Workbook

Sheet Raw Data
A1: Sampling_Cycle | B1: Site_Name | C1: Location | D1: Site_Code | E1: Region | F1: Zone | G1: Latitude | H1: Longitude | I1: Depth | J1: Month | K1: Day | L1: Year | M1: Date | N1: Captain | O1: Crew_1 | P1: Crew_2 | Q1: Crew_3 | R1: Time_In | S1: Time_Out | T1: Surface_Temp_C | U1: Surface_Temp_Depth_m | V1: Surface_Sal_psu | W1: Surface_Sal_Depth_m | X1: LAB_SAL_Surf | Y1: Surface_DO_mg_L | Z1: Surface_DO_Depth_m | AA1: Surface_pH | AB1: Surface_pH_Depth_m | AC1: Bottom_Temp_C | AD1: Bottom_Temp_Depth_m | AE1: Bottom_Sal_psu | AF1: Bottom_Sal_Depth_m | AG1: LAB_SAL_Bttm | AH1: Bottom_DO_mg_L | AI1: Bottom_DO_Depth_m | AJ1: Bottom_pH | AK1: Bottom_pH_Depth_m | AL1: Secchi_Depth_1_m | AM1: Secchi_Depth_2_m | AN1: Secchi_Depth_3_m | AO1: Secchi_Avg_Depth | AP1: Surface_Van_Dorn_Depth_m | AQ1: Bottom_Van_Dorn_Depth_m | AR1: Surface_TA_DIC | AS1: Bottom_TA_DIC | AT1: Surface_BOD | AU1: Bottom_BOD | AV1: Chl_a | AW1: Turbidity_NTU | AX1: Settleable_Solids | AY1: Total_Suspended_Solids | AZ1: POx_NOx | BA1: TKN | BB1: Enterococcus | BC1: Note
A2: 2 | B2: =LOOKUP($D2,Site_Meta!$C$2:$C$43,Site_Meta!A$2:A$43) -> Cayo Aurora 5m | C2: =LOOKUP($D2,Site_Meta!$C$2:$C$43,Site_Meta!B$2:B$43) -> Guanica | D2: AURO05 | E2: =LOOKUP($D2,Site_Meta!$C$2:$C$43,Site_Meta!D$2:D$43) -> Southwest | F2: =LOOKUP($D2,Site_Meta!$C$2:$C$43,Site_Meta!E$2:E$43) -> SW | G2: =LOOKUP($D2,Site_Meta!$C$2:$C$43,Site_Meta!F$2:F$43) -> 17.9369 | H2: =LOOKUP($D2,Site_Meta!$C$2:$C$43,Site_Meta!G$2:G$43) -> -66.8738 | I2: =LOOKUP($D2,Site_Meta!$C$2:$C$43,Site_Meta!H$2:H$43) -> 5 | J2: 10 | K2: 4 | L2: 2023 | M2: =CONCATENATE(J2,"/",K2,"/",L2) -> 10/4/2023 | N2: Anibal | O2: Leira | P2: Manuel | R2: 0.41666667 | S2: 0.42986111 | T2: 30.87 | U2: 0.54 | V2: 36.66 | W2: 0.52 | X2: NA | Y2: 4.73 | Z2: 0.53 | AA2: 7.84 | AB2: 0.53 | AC2: 31.15 | AD2: 3.03 | AE2: 36.49 | AF2: 3.03 | AG2: 34.4 | AH2: 4.87 | AI2: 3.03 | AJ2: 7.99 | AK2: 3.03 | AL2: >3 | AM2: >3 | AN2: >3 | AO2: =AVERAGE(AL2:AN2) -> #DIV/0! | AP2: 0.5 | AQ2: 3 | AR2: 290 | AS2: 291 | AT2: 292 | AU2: 293 | AV2: 294 | AW2: 295 | AX2: 296 | AY2: 297 | AZ2: 298 | BA2: 299 | BB2: 256 | BC2: HydroLab
A3: 2 | B3: =LOOKUP($D3,Site_Meta!$C$2:$C$43,Site_Meta!A$2:A$43) -> Puerto Botes 15m | C3: =LOOKUP($D3,Site_Meta!$C$2:$C$43,Site_Meta!B$2:B$43) -> Isla Desecheo | D3: BOTE15 | E3: =LOOKUP($D3,Site_Meta!$C$2:$C$43,Site_Meta!D$2:D$43) -> Mona/Desecheo | F3: =LOOKUP($D3,Site_Meta!$C$2:$C$43,Site_Meta!E$2:E$43) -> W | G3: =LOOKUP($D3,Site_Meta!$C$2:$C$43,Site_Meta!F$2:F$43) -> 18.382 | H3: =LOOKUP($D3,Site_Meta!$C$2:$C$43,Site_Meta!G$2:G$43) -> -67.4883 | I3: =LOOKUP($D3,Site_Meta!$C$2:$C$43,Site_Meta!H$2:H$43) -> 15 | J3: 10 | K3: 23 | L3: 2023 | M3: =CONCATENATE(J3,"/",K3,"/",L3) -> 10/23/2023 | N3: Anibal | O3: Adiana | P3: Leira | R3: 0.42916667 | S3: 0.45 | T3: 30.21 | U3: 0.52 | V3: 35.94 | W3: 0.52 | X3: 34.8 | Y3: 6.38 | Z3: 0.52 | AA3: 8.17 | AB3: 0.52 | AC3: 30.12 | AD3: 16.46 | AE3: 36.04 | AF3: 16.46 | AG3: 35.1 | AH3: 6.2 | AI3: 16.46 | AJ3: 8.21 | AK3: 16.46 | AL3: >15 | AM3: >15 | AN3: >15 | AO3: =AVERAGE(AL3:AN3) -> #DIV/0! | AP3: 0.5 | AQ3: 15 | AR3: 532 | AS3: 533 | AT3: 534 | AU3: 535 | AV3: 536 | AW3: 537 | AX3: 538 | AY3: 539 | AZ3: 540 | BA3: 541 | BB3: 433 | BC3: Eureka_Log_Oct_5,20,23-25_2023.xlsx; Correct depth offset ~0.35 m
A4: 2 | B4: =LOOKUP($D4,Site_Meta!$C$2:$C$43,Site_Meta!A$2:A$43) -> Puerto Botes 20m | C4: =LOOKUP($D4,Site_Meta!$C$2:$C$43,Site_Meta!B$2:B$43) -> Isla Desecheo | D4: BOTE20 | E4: =LOOKUP($D4,Site_Meta!$C$2:$C$43,Site_Meta!D$2:D$43) -> Mona/Desecheo | F4: =LOOKUP($D4,Site_Meta!$C$2:$C$43,Site_Meta!E$2:E$43) -> W | G4: =LOOKUP($D4,Site_Meta!$C$2:$C$43,Site_Meta!F$2:F$43) -> 18.38158 | H4: =LOOKUP($D4,Site_Meta!$C$2:$C$43,Site_Meta!G$2:G$43) -> -67.4886 | I4: =LOOKUP($D4,Site_Meta!$C$2:$C$43,Site_Meta!H$2:H$43) -> 20 | J4: 10 | K4: 23 | L4: 2023 | M4: =CONCATENATE(J4,"/",K4,"/",L4) -> 10/23/2023 | N4: Anibal | O4: Adiana | P4: Leira | R4: 0.39930556 | S4: 0.42638889 | T4: 30.2 | U4: 0.65 | V4: 35.81 | W4: 0.65 | X4: 34.8 | Y4: 6.2 | Z4: 0.65 | AA4: 8.18 | AB4: 0.65 | AC4: 30.9 | AD4: 18.89 | AE4: 36.08 | AF4: 18.89 | AG4: 35.1 | AH4: 6.19 | AI4: 18.89 | AJ4: 8.22 | AK4: 18.89 | AL4: >18 | AM4: >18 | AN4: >18 | AO4: =AVERAGE(AL4:AN4) -> #DIV/0! | AP4: 0.5 | AQ4: 18.5 | AR4: 466 | AS4: 467 | AT4: 468 | AU4: 469 | AV4: 470 | AW4: 471 | AX4: 472 | AY4: 473 | AZ4: 474 | BA4: 475 | BB4: 374 | BC4: Eureka_Log_Oct_5,20,23-25_2023.xlsx; Correct depth offset ~0.35 m
A5: 2 | B5: =LOOKUP($D5,Site_Meta!$C$2:$C$43,Site_Meta!A$2:A$43) -> Boya Vieja 20m | C5: =LOOKUP($D5,Site_Meta!$C$2:$C$43,Site_Meta!B$2:B$43) -> La Parguera | D5: BOYA20 | E5: =LOOKUP($D5,Site_Meta!$C$2:$C$43,Site_Meta!D$2:D$43) -> Southwest | F5: =LOOKUP($D5,Site_Meta!$C$2:$C$43,Site_Meta!E$2:E$43) -> SW | G5: =LOOKUP($D5,Site_Meta!$C$2:$C$43,Site_Meta!F$2:F$43) -> 17.88827 | H5: =LOOKUP($D5,Site_Meta!$C$2:$C$43,Site_Meta!G$2:G$43) -> -66.9978 | I5: =LOOKUP($D5,Site_Meta!$C$2:$C$43,Site_Meta!H$2:H$43) -> 20 | J5: 9 | K5: 19 | L5: 2023 | M5: =CONCATENATE(J5,"/",K5,"/",L5) -> 9/19/2023 | N5: Anibal | O5: Adiana | P5: Leira | Q5: Manuel | R5: 0.375 | S5: 0.39583333 | T5: 30.4 | U5: 0.63 | V5: 34.49 | W5: 0.59 | X5: 33.4 | Y5: 6.22 | Z5: 0.61 | AA5: 7.93 | AB5: 0.65 | AC5: 29.71 | AD5: 19.3 | AE5: 34.8 | AF5: 19.19 | AG5: 34.6 | AH5: 6.18 | AI5: 19.1 | AJ5: 8.08 | AK5: 19.08 | AL5: 12 | AM5: 12 | AN5: 12 | AO5: =AVERAGE(AL5:AN5) -> 12 | AP5: 0.5 | AQ5: 19 | AR5: 179 | AS5: 178 | AT5: 110 | AU5: 109 | AV5: 53 | AW5: 55 | AX5: 56 | AY5: 53 | AZ5: 70 | BA5: 76 | BB5: 47 | BC5: HydroLab
A6: 2 | B6: =LOOKUP($D6,Site_Meta!$C$2:$C$43,Site_Meta!A$2:A$43) -> Cabezas de San Juan 5m | C6: =LOOKUP($D6,Site_Meta!$C$2:$C$43,Site_Meta!B$2:B$43) -> Fajardo | D6: CABE05 | E6: =LOOKUP($D6,Site_Meta!$C$2:$C$43,Site_Meta!D$2:D$43) -> North/Northeast | F6: =LOOKUP($D6,Site_Meta!$C$2:$C$43,Site_Meta!E$2:E$43) -> E | G6: =LOOKUP($D6,Site_Meta!$C$2:$C$43,Site_Meta!F$2:F$43) -> 18.38544 | H6: =LOOKUP($D6,Site_Meta!$C$2:$C$43,Site_Meta!G$2:G$43) -> -65.6297 | I6: =LOOKUP($D6,Site_Meta!$C$2:$C$43,Site_Meta!H$2:H$43) -> 5 | J6: 10 | K6: 15 | L6: 2023 | M6: =CONCATENATE(J6,"/",K6,"/",L6) -> 10/15/2023 | N6: Tyrone | O6: Adiana | P6: Manuel | R6: 0.28541667 | S6: 0.30208333 | T6: 29.88 | U6: 0.47 | V6: 36.32 | W6: 0.51 | X6: 35.4 | Y6: 5.76 | Z6: 0.52 | AA6: 7.09 | AB6: 0.52 | AC6: 30.05 | AD6: 7.43 | AE6: 35.96 | AF6: 7.44 | AG6: 35 | AH6: 5.74 | AI6: 7.44 | AJ6: 7.14 | AK6: 7.4 | AL6: >7.5 | AM6: >7.5 | AN6: >7.5 | AO6: =AVERAGE(AL6:AN6) -> #DIV/0! | AP6: 0.5 | AQ6: 7.5 | AR6: 400 | AS6: 401 | AT6: 402 | AU6: 403 | AV6: 404 | AW6: 405 | AX6: 406 | AY6: 407 | AZ6: 408 | BA6: 409 | BB6: 531 | BC6: HydroLab
A7: 2 | B7: =LOOKUP($D7,Site_Meta!$C$2:$C$43,Site_Meta!A$2:A$43) -> Cabezas de San Juan 5m | C7: =LOOKUP($D7,Site_Meta!$C$2:$C$43,Site_Meta!B$2:B$43) -> Fajardo | D7: CABE05 | E7: =LOOKUP($D7,Site_Meta!$C$2:$C$43,Site_Meta!D$2:D$43) -> North/Northeast | F7: =LOOKUP($D7,Site_Meta!$C$2:$C$43,Site_Meta!E$2:E$43) -> E | G7: =LOOKUP($D7,Site_Meta!$C$2:$C$43,Site_Meta!F$2:F$43) -> 18.38544 | H7: =LOOKUP($D7,Site_Meta!$C$2:$C$43,Site_Meta!G$2:G$43) -> -65.6297 | I7: =LOOKUP($D7,Site_Meta!$C$2:$C$43,Site_Meta!H$2:H$43) -> 5 | J7: 10 | K7: 15 | L7: 2023 | M7: =CONCATENATE(J7,"/",K7,"/",L7) -> 10/15/2023 | N7: Tyrone | O7: Adiana | P7: Manuel | R7: 0.28125 | S7: 0.28472222 | T7: 30.64 | U7: 0.68 | V7: 36.59 | W7: 0.7 | X7: 35.4 | Y7: 4.61 | Z7: 0.7 | AA7: 7.65 | AB7: 0.7 | AC7: 31.78 | AD7: 6.5 | AE7: 36.06 | AF7: 6.7 | AG7: NA | AH7: 4.51 | AI7: 6.9 | AJ7: 7.72 | AK7: 7 | AL7: NA | AM7: NA | AN7: NA | AO7: =AVERAGE(AL7:AN7) -> #DIV/0! | AP7: NA | AQ7: NA | AR7: NA | AS7: NA | AT7: NA | AU7: NA | AV7: NA | AW7: NA | AX7: NA | AY7: NA | AZ7: NA | BA7: NA | BB7: NA | BC7: YSI
A8: 2 | B8: =LOOKUP($D8,Site_Meta!$C$2:$C$43,Site_Meta!A$2:A$43) -> Canjilones 15m | C8: =LOOKUP($D8,Site_Meta!$C$2:$C$43,Site_Meta!B$2:B$43) -> Isla Vieques | D8: CANJ15 | E8: =LOOKUP($D8,Site_Meta!$C$2:$C$43,Site_Meta!D$2:D$43) -> Vieques/Culebra | F8: =LOOKUP($D8,Site_Meta!$C$2:$C$43,Site_Meta!E$2:E$43) -> E | G8: =LOOKUP($D8,Site_Meta!$C$2:$C$43,Site_Meta!F$2:F$43) -> 18.08964 | H8: =LOOKUP($D8,Site_Meta!$C$2:$C$43,Site_Meta!G$2:G$43) -> -65.5901 | I8: =LOOKUP($D8,Site_Meta!$C$2:$C$43,Site_Meta!H$2:H$43) -> 15 | J8: 10 | K8: 14 | L8: 2023 | M8: =CONCATENATE(J8,"/",K8,"/",L8) -> 10/14/2023 | N8: Tyrone | O8: Irais | P8: Manuel | R8: 0.425 | S8: 0.44236111 | T8: 30.13 | U8: 0.51 | V8: 34.83 | W8: 0.51 | X8: 34.1 | Y8: 6.35 | Z8: 0.5 | AA8: 7.05 | AB8: 0.51 | AC8: 30.02 | AD8: 14.97 | AE8: 35.61 | AF8: 15 | AG8: 34 | AH8: 5.48 | AI8: 15 | AJ8: 6.9 | AK8: 15.01 | AL8: >15 | AM8: >15 | AN8: >15 | AO8: =AVERAGE(AL8:AN8) -> #DIV/0! | AP8: 0.5 | AQ8: 15 | AR8: 444 | AS8: 445 | AT8: 446 | AU8: 447 | AV8: 448 | AW8: 449 | AX8: 450 | AY8: 451 | AZ8: 452 | BA8: 453 | BB8: 520 | BC8: HydroLab
A9: 2 | B9: =LOOKUP($D9,Site_Meta!$C$2:$C$43,Site_Meta!A$2:A$43) -> Puerto Canoas 30m | C9: =LOOKUP($D9,Site_Meta!$C$2:$C$43,Site_Meta!B$2:B$43) -> Isla Desecheo | D9: CANO30 | E9: =LOOKUP($D9,Site_Meta!$C$2:$C$43,Site_Meta!D$2:D$43) -> Mona/Desecheo | F9: =LOOKUP($D9,Site_Meta!$C$2:$C$43,Site_Meta!E$2:E$43) -> W | G9: =LOOKUP($D9,Site_Meta!$C$2:$C$43,Site_Meta!F$2:F$43) -> 18.37747 | H9: =LOOKUP($D9,Site_Meta!$C$2:$C$43,Site_Meta!G$2:G$43) -> -67.484 | I9: =LOOKUP($D9,Site_Meta!$C$2:$C$43,Site_Meta!H$2:H$43) -> 30 | J9: 10 | K9: 23 | L9: 2023 | M9: =CONCATENATE(J9,"/",K9,"/",L9) -> 10/23/2023 | N9: Anibal | O9: Adiana | P9: Leira | R9: 0.45763889 | S9: 0.48333333 | T9: 30.25 | U9: 0.51 | V9: 36.05 | W9: 0.53 | X9: 35 | Y9: 6.33 | Z9: 0.56 | AA9: 8.2 | AB9: 0.52 | AC9: 30.19 | AD9: 26.61 | AE9: 36.05 | AF9: 26.65 | AG9: 35.3 | AH9: 6.22 | AI9: 26.52 | AJ9: 8.22 | AK9: 26.67 | AL9: >26.5 | AM9: >26.5 | AN9: >26.5 | AO9: =AVERAGE(AL9:AN9) -> #DIV/0! | AP9: 0.5 | AQ9: 26.5 | AR9: 521 | AS9: 522 | AT9: 523 | AU9: 524 | AV9: 525 | AW9: 526 | AX9: 527 | AY9: 528 | AZ9: 529 | BA9: 530 | BB9: 542 | BC9: Eureka; Correct depth offset ~0.35 m
A10: 2 | B10: =LOOKUP($D10,Site_Meta!$C$2:$C$43,Site_Meta!A$2:A$43) -> Puerto Canoas 30m | C10: =LOOKUP($D10,Site_Meta!$C$2:$C$43,Site_Meta!B$2:B$43) -> Isla Desecheo | D10: CANO30-R | E10: =LOOKUP($D10,Site_Meta!$C$2:$C$43,Site_Meta!D$2:D$43) -> Mona/Desecheo | F10: =LOOKUP($D10,Site_Meta!$C$2:$C$43,Site_Meta!E$2:E$43) -> W | G10: =LOOKUP($D10,Site_Meta!$C$2:$C$43,Site_Meta!F$2:F$43) -> 18.37747 | H10: =LOOKUP($D10,Site_Meta!$C$2:$C$43,Site_Meta!G$2:G$43) -> -67.484 | I10: =LOOKUP($D10,Site_Meta!$C$2:$C$43,Site_Meta!H$2:H$43) -> 30 | J10: 10 | K10: 23 | L10: 2023 | M10: =CONCATENATE(J10,"/",K10,"/",L10) -> 10/23/2023 | N10: Anibal | O10: Adiana | P10: Leira | R10: 0.48611111 | S10: 0.50625 | T10: 30.27 | U10: 0.57 | V10: 35.85 | W10: 0.57 | X10: 34.8 | Y10: 6.27 | Z10: 0.57 | AA10: 8.22 | AB10: 0.57 | AC10: 30.19 | AD10: 29.12 | AE10: 34.37 | AF10: 29.12 | AG10: 34.6 | AH10: 6.3 | AI10: 29.12 | AJ10: 8.22 | AK10: 29.12 | AL10: >29 | AM10: >29 | AN10: >29 | AO10: =AVERAGE(AL10:AN10) -> #DIV/0! | AP10: 0.5 | AQ10: 29 | AR10: 510 | AS10: 511 | AT10: 512 | AU10: 513 | AV10: 514 | AW10: 515 | AX10: 516 | AY10: 517 | AZ10: 518 | BA10: 519 | BB10: 399 | BC10: Eureka_Log_Oct_5,20,23-25_2023.xlsx; Correct depth offset ~0.35 m
A11: 2 | B11: =LOOKUP($D11,Site_Meta!$C$2:$C$43,Site_Meta!A$2:A$43) -> Cayo Caribes 10m | C11: =LOOKUP($D11,Site_Meta!$C$2:$C$43,Site_Meta!B$2:B$43) -> Salinas | D11: CARI10 | E11: =LOOKUP($D11,Site_Meta!$C$2:$C$43,Site_Meta!D$2:D$43) -> Southeast | F11: =LOOKUP($D11,Site_Meta!$C$2:$C$43,Site_Meta!E$2:E$43) -> S | G11: =LOOKUP($D11,Site_Meta!$C$2:$C$43,Site_Meta!F$2:F$43) -> 17.91533 | H11: =LOOKUP($D11,Site_Meta!$C$2:$C$43,Site_Meta!G$2:G$43) -> -66.2141 | I11: =LOOKUP($D11,Site_Meta!$C$2:$C$43,Site_Meta!H$2:H$43) -> 10 | J11: 9 | K11: 21 | L11: 2023 | M11: =CONCATENATE(J11,"/",K11,"/",L11) -> 9/21/2023 | N11: Anibal | O11: Adiana | P11: Juanita | Q11: Manuel | R11: 0.36805556 | S11: 0.39583333 | T11: 30.62 | U11: 0.54 | V11: 35.85 | W11: 0.55 | X11: 34.8 | Y11: 6.1 | Z11: 0.56 | AA11: 7.94 | AB11: 0.56 | AC11: 30.84 | AD11: 9.51 | AE11: 35.55 | AF11: 9.5 | AG11: 35.2 | AH11: 6.05 | AI11: 9.62 | AJ11: 8.08 | AK11: 9.62 | AL11: >10 | AM11: >10 | AN11: >10 | AO11: =AVERAGE(AL11:AN11) -> #DIV/0! | AP11: 0.5 | AQ11: 9.5 | AR11: 184 | AS11: 185 | AT11: 115 | AU11: 116 | AV11: 56 | AW11: 58 | AX11: 59 | AY11: 56 | AZ11: 73 | BA11: 79 | BB11: 65 | BC11: HydroLab
A12: 2 | B12: =LOOKUP($D12,Site_Meta!$C$2:$C$43,Site_Meta!A$2:A$43) -> West Reef 10m | C12: =LOOKUP($D12,Site_Meta!$C$2:$C$43,Site_Meta!B$2:B$43) -> Ponce | D12: CDMU10 | E12: =LOOKUP($D12,Site_Meta!$C$2:$C$43,Site_Meta!D$2:D$43) -> South | F12: =LOOKUP($D12,Site_Meta!$C$2:$C$43,Site_Meta!E$2:E$43) -> S | G12: =LOOKUP($D12,Site_Meta!$C$2:$C$43,Site_Meta!F$2:F$43) -> 17.89502 | H12: =LOOKUP($D12,Site_Meta!$C$2:$C$43,Site_Meta!G$2:G$43) -> -66.5284 | I12: =LOOKUP($D12,Site_Meta!$C$2:$C$43,Site_Meta!H$2:H$43) -> 10 | J12: 9 | K12: 21 | L12: 2023 | M12: =CONCATENATE(J12,"/",K12,"/",L12) -> 9/21/2023 | N12: Anibal | O12: Adiana | P12: Juanita | Q12: Manuel | R12: 0.44722222 | S12: 0.46111111 | T12: 30.86 | U12: 0.59 | V12: 34.73 | W12: 0.59 | X12: 33.9 | Y12: 6.52 | Z12: 0.62 | AA12: 8.03 | AB12: 0.68 | AC12: 30.62 | AD12: 8.03 | AE12: 34.72 | AF12: 7.9 | AG12: 34.3 | AH12: 6.64 | AI12: 7.77 | AJ12: 8.09 | AK12: 7.57 | AL12: >8 | AM12: >8 | AN12: >8 | AO12: =AVERAGE(AL12:AN12) -> #DIV/0! | AP12: 0.5 | AQ12: 7.5 | AR12: 200 | AS12: 201 | AT12: 131 | AU12: 132 | AV12: 64 | AW12: 66 | AX12: 67 | AY12: 64 | AZ12: 81 | BA12: 87 | BB12: 56 | BC12: HydroLab
A13: 2 | B13: =LOOKUP($D13,Site_Meta!$C$2:$C$43,Site_Meta!A$2:A$43) -> Cibuco 05m | C13: =LOOKUP($D13,Site_Meta!$C$2:$C$43,Site_Meta!B$2:B$43) -> Vega Baja | D13: CIBU05 | E13: =LOOKUP($D13,Site_Meta!$C$2:$C$43,Site_Meta!D$2:D$43) -> North/Northeast | F13: =LOOKUP($D13,Site_Meta!$C$2:$C$43,Site_Meta!E$2:E$43) -> N | G13: =LOOKUP($D13,Site_Meta!$C$2:$C$43,Site_Meta!F$2:F$43) -> 18.48955 | H13: =LOOKUP($D13,Site_Meta!$C$2:$C$43,Site_Meta!G$2:G$43) -> -66.3736 | I13: =LOOKUP($D13,Site_Meta!$C$2:$C$43,Site_Meta!H$2:H$43) -> 10 | J13: 10 | K13: 6 | L13: 2023 | M13: =CONCATENATE(J13,"/",K13,"/",L13) -> 10/6/2023 | N13: Rodolfo | O13: Leira | P13: Manuel | R13: 0.27847222 | S13: 0.29236111 | T13: 29.65 | U13: 0.42 | V13: 34.71 | W13: 0.42 | X13: 34.8 | Y13: 5.79 | Z13: 0.45 | AA13: 7.69 | AB13: 0.49 | AC13: 29.85 | AD13: 1.92 | AE13: 34.45 | AF13: 1.97 | AG13: 34.9 | AH13: 5.73 | AI13: 2.01 | AJ13: 7.95 | AK13: 2.03 | AL13: >2.5 | AM13: >2.5 | AN13: >2.5 | AO13: =AVERAGE(AL13:AN13) -> #DIV/0! | AP13: 0.5 | AQ13: 2 | AR13: 323 | AS13: 324 | AT13: 325 | AU13: 326 | AV13: 327 | AW13: 328 | AX13: 329 | AY13: 330 | AZ13: 331 | BA13: 332 | BB13: 311 | BC13: Check salinity & pH
A14: 2 | B14: =LOOKUP($D14,Site_Meta!$C$2:$C$43,Site_Meta!A$2:A$43) -> Cibuco 05m | C14: =LOOKUP($D14,Site_Meta!$C$2:$C$43,Site_Meta!B$2:B$43) -> Vega Baja | D14: CIBU05-R | E14: =LOOKUP($D14,Site_Meta!$C$2:$C$43,Site_Meta!D$2:D$43) -> North/Northeast | F14: =LOOKUP($D14,Site_Meta!$C$2:$C$43,Site_Meta!E$2:E$43) -> N | G14: =LOOKUP($D14,Site_Meta!$C$2:$C$43,Site_Meta!F$2:F$43) -> 18.48955 | H14: =LOOKUP($D14,Site_Meta!$C$2:$C$43,Site_Meta!G$2:G$43) -> -66.3736 | I14: =LOOKUP($D14,Site_Meta!$C$2:$C$43,Site_Meta!H$2:H$43) -> 10 | J14: 10 | K14: 6 | L14: 2023 | M14: =CONCATENATE(J14,"/",K14,"/",L14) -> 10/6/2023 | N14: Rodolfo | O14: Leira | P14: Manuel | R14: 0.29722222 | S14: 0.30555556 | T14: 29.85 | U14: 0.49 | V14: 31.76 | W14: 0.52 | X14: 34.7 | Y14: 5.88 | Z14: 0.51 | AA14: 7.74 | AB14: 0.52 | AC14: 29.9 | AD14: 2.45 | AE14: 8.64 | AF14: 2.5 | AG14: 34.6 | AH14: 6.72 | AI14: 2.5 | AJ14: 8.01 | AK14: 2.48 | AL14: >2.5 | AM14: >2.5 | AN14: >2.5 | AO14: =AVERAGE(AL14:AN14) -> #DIV/0! | AP14: 0.5 | AQ14: 2.5 | AR14: 334 | AS14: 335 | AT14: 336 | AU14: 337 | AV14: 338 | AW14: 339 | AX14: 340 | AY14: 341 | AZ14: 342 | BA14: 343 | BB14: 322 | BC14: Check salinity & pH
A15: 2 | B15: =LOOKUP($D15,Site_Meta!$C$2:$C$43,Site_Meta!A$2:A$43) -> Cayo Coral 10m | C15: =LOOKUP($D15,Site_Meta!$C$2:$C$43,Site_Meta!B$2:B$43) -> Guanica | D15: CORA10 | E15: =LOOKUP($D15,Site_Meta!$C$2:$C$43,Site_Meta!D$2:D$43) -> Southwest | F15: =LOOKUP($D15,Site_Meta!$C$2:$C$43,Site_Meta!E$2:E$43) -> SW | G15: =LOOKUP($D15,Site_Meta!$C$2:$C$43,Site_Meta!F$2:F$43) -> 17.9362 | H15: =LOOKUP($D15,Site_Meta!$C$2:$C$43,Site_Meta!G$2:G$43) -> -66.8884 | I15: =LOOKUP($D15,Site_Meta!$C$2:$C$43,Site_Meta!H$2:H$43) -> 10 | J15: 10 | K15: 4 | L15: 2023 | M15: =CONCATENATE(J15,"/",K15,"/",L15) -> 10/4/2023 | N15: Anibal | O15: Leira | P15: Manuel | R15: 0.43472222 | S15: 0.44930556 | T15: 31.21 | U15: 0.49 | V15: 36.03 | W15: 0.49 | X15: 34.1 | Y15: 5.77 | Z15: 0.49 | AA15: 7.94 | AB15: 0.49 | AC15: 30.99 | AD15: 8.9 | AE15: 36.45 | AF15: 8.96 | AG15: 34.3 | AH15: 3.87 | AI15: 8.99 | AJ15: 7.95 | AK15: 9 | AL15: >9 | AM15: >9 | AN15: >9 | AO15: =AVERAGE(AL15:AN15) -> #DIV/0! | AP15: 0.5 | AQ15: 9 | AR15: 279 | AS15: 280 | AT15: 281 | AU15: 282 | AV15: 283 | AW15: 284 | AX15: 285 | AY15: 286 | AZ15: 287 | BA15: 288 | BB15: 267 | BC15: HydroLab
A16: 2 | B16: =LOOKUP($D16,Site_Meta!$C$2:$C$43,Site_Meta!A$2:A$43) -> Carlos Rosario 10m | C16: =LOOKUP($D16,Site_Meta!$C$2:$C$43,Site_Meta!B$2:B$43) -> Isla Culebra | D16: CROS10 | E16: =LOOKUP($D16,Site_Meta!$C$2:$C$43,Site_Meta!D$2:D$43) -> Vieques/Culebra | F16: =LOOKUP($D16,Site_Meta!$C$2:$C$43,Site_Meta!E$2:E$43) -> E | G16: =LOOKUP($D16,Site_Meta!$C$2:$C$43,Site_Meta!F$2:F$43) -> 18.32779 | H16: =LOOKUP($D16,Site_Meta!$C$2:$C$43,Site_Meta!G$2:G$43) -> -65.332 | I16: =LOOKUP($D16,Site_Meta!$C$2:$C$43,Site_Meta!H$2:H$43) -> 10 | J16: 10 | K16: 13 | L16: 2023 | M16: =CONCATENATE(J16,"/",K16,"/",L16) -> 10/13/2023 | N16: Tyrone | O16: Adiana | P16: Manuel | R16: 0.39166667 | S16: 0.40833333 | T16: 29.89 | U16: 0.44 | V16: 36.07 | W16: 0.49 | X16: 34.3 | Y16: 6.11 | Z16: 0.5 | AA16: 7.92 | AB16: 0.5 | AC16: 29.9 | AD16: 10.01 | AE16: 35.89 | AF16: 9.95 | AG16: 34.4 | AH16: 6.06 | AI16: 9.97 | AJ16: 8.1 | AK16: 9.98 | AL16: >10 | AM16: >10 | AN16: >10 | AO16: =AVERAGE(AL16:AN16) -> #DIV/0! | AP16: 0.5 | AQ16: 10 | AR16: 356 | AS16: 357 | AT16: 358 | AU16: 359 | AV16: 360 | AW16: 361 | AX16: 362 | AY16: 363 | AZ16: 364 | BA16: 365 | BB16: 487 | BC16: HydroLab
A17: 2 | B17: =LOOKUP($D17,Site_Meta!$C$2:$C$43,Site_Meta!A$2:A$43) -> Dakiti 20m | C17: =LOOKUP($D17,Site_Meta!$C$2:$C$43,Site_Meta!B$2:B$43) -> Isla Culebra | D17: DAKI20 | E17: =LOOKUP($D17,Site_Meta!$C$2:$C$43,Site_Meta!D$2:D$43) -> Vieques/Culebra | F17: =LOOKUP($D17,Site_Meta!$C$2:$C$43,Site_Meta!E$2:E$43) -> E | G17: =LOOKUP($D17,Site_Meta!$C$2:$C$43,Site_Meta!F$2:F$43) -> 18.27587 | H17: =LOOKUP($D17,Site_Meta!$C$2:$C$43,Site_Meta!G$2:G$43) -> -65.2773 | I17: =LOOKUP($D17,Site_Meta!$C$2:$C$43,Site_Meta!H$2:H$43) -> 20 | J17: 10 | K17: 13 | L17: 2023 | M17: =CONCATENATE(J17,"/",K17,"/",L17) -> 10/13/2023 | N17: Tyrone | O17: Adiana | P17: Manuel | R17: 0.3 | S17: 0.32083333 | T17: 29.56 | U17: 0.52 | V17: 36.04 | W17: 0.55 | X17: 34 | Y17: 6.26 | Z17: 0.55 | AA17: 7.78 | AB17: 0.52 | AC17: 29.92 | AD17: 20.07 | AE17: 36.23 | AF17: 20.07 | AG17: 34.3 | AH17: 5.52 | AI17: 20.06 | AJ17: 8.05 | AK17: 20.06 | AL17: >20 | AM17: >20 | AN17: >20 | AO17: =AVERAGE(AL17:AN17) -> #DIV/0! | AP17: 0.5 | AQ17: 20 | AR17: 389 | AS17: 390 | AT17: 391 | AU17: 392 | AV17: 393 | AW17: 394 | AX17: 395 | AY17: 396 | AZ17: 397 | BA17: 398 | BB17: 454 | BC17: HydroLab
A18: 2 | B18: =LOOKUP($D18,Site_Meta!$C$2:$C$43,Site_Meta!A$2:A$43) -> Dakiti 20m | C18: =LOOKUP($D18,Site_Meta!$C$2:$C$43,Site_Meta!B$2:B$43) -> Isla Culebra | D18: DAKI20-R | E18: =LOOKUP($D18,Site_Meta!$C$2:$C$43,Site_Meta!D$2:D$43) -> Vieques/Culebra | F18: =LOOKUP($D18,Site_Meta!$C$2:$C$43,Site_Meta!E$2:E$43) -> E | G18: =LOOKUP($D18,Site_Meta!$C$2:$C$43,Site_Meta!F$2:F$43) -> 18.27587 | H18: =LOOKUP($D18,Site_Meta!$C$2:$C$43,Site_Meta!G$2:G$43) -> -65.2773 | I18: =LOOKUP($D18,Site_Meta!$C$2:$C$43,Site_Meta!H$2:H$43) -> 20 | J18: 10 | K18: 13 | L18: 2023 | M18: =CONCATENATE(J18,"/",K18,"/",L18) -> 10/13/2023 | N18: Tyrone | O18: Adiana | P18: Manuel | R18: 0.32638889 | S18: 0.34166667 | T18: 29.7 | U18: 0.5 | V18: 35.99 | W18: 0.5 | X18: 33 | Y18: 6.13 | Z18: 0.49 | AA18: 7.94 | AB18: 0.48 | AC18: 29.92 | AD18: 19.93 | AE18: 36.2 | AF18: 19.97 | AG18: 34.2 | AH18: 5.72 | AI18: 19.98 | AJ18: 8.08 | AK18: 19.97 | AL18: >20 | AM18: >20 | AN18: >20 | AO18: =AVERAGE(AL18:AN18) -> #DIV/0! | AP18: 0.5 | AQ18: 20 | AR18: 312 | AS18: 313 | AT18: 314 | AU18: 315 | AV18: 316 | AW18: 317 | AX18: 318 | AY18: 319 | AZ18: 320 | BA18: 321 | BB18: 465 | BC18: HydroLab
A19: 2 | B19: =LOOKUP($D19,Site_Meta!$C$2:$C$43,Site_Meta!A$2:A$43) -> Derrumbadero 20m | C19: =LOOKUP($D19,Site_Meta!$C$2:$C$43,Site_Meta!B$2:B$43) -> Ponce | D19: DERR20 | E19: =LOOKUP($D19,Site_Meta!$C$2:$C$43,Site_Meta!D$2:D$43) -> South | F19: =LOOKUP($D19,Site_Meta!$C$2:$C$43,Site_Meta!E$2:E$43) -> S | G19: =LOOKUP($D19,Site_Meta!$C$2:$C$43,Site_Meta!F$2:F$43) -> 17.904 | H19: =LOOKUP($D19,Site_Meta!$C$2:$C$43,Site_Meta!G$2:G$43) -> -66.6086 | I19: =LOOKUP($D19,Site_Meta!$C$2:$C$43,Site_Meta!H$2:H$43) -> 20 | J19: 9 | K19: 21 | L19: 2023 | M19: =CONCATENATE(J19,"/",K19,"/",L19) -> 9/21/2023 | N19: Anibal | O19: Adiana | P19: Juanita | Q19: Manuel | R19: 0.47569444 | S19: 0.49722222 | T19: 30.9 | U19: 0.63 | V19: 34.36 | W19: 0.67 | X19: 34.1 | Y19: 6.32 | Z19: 0.7 | AA19: 8.08 | AB19: 0.7 | AC19: 30.12 | AD19: 16.5 | AE19: 35 | AF19: 17 | AG19: 34.6 | AH19: 6.2 | AI19: 17.3 | AJ19: 8.06 | AK19: 17.33 | AL19: 12.25 | AM19: 12.5 | AN19: 12.75 | AO19: =AVERAGE(AL19:AN19) -> 12.5 | AP19: 0.5 | AQ19: 17 | AR19: 190 | AS19: 191 | AT19: 121 | AU19: 122 | AV19: 59 | AW19: 61 | AX19: 62 | AY19: 59 | AZ19: 76 | BA19: 82 | BB19: 57 | BC19: HydroLab
A20: 2 | B20: =LOOKUP($D20,Site_Meta!$C$2:$C$43,Site_Meta!A$2:A$43) -> Cayo Diablo 5m | C20: =LOOKUP($D20,Site_Meta!$C$2:$C$43,Site_Meta!B$2:B$43) -> Fajardo | D20: DIAB05 | E20: =LOOKUP($D20,Site_Meta!$C$2:$C$43,Site_Meta!D$2:D$43) -> North/Northeast | F20: =LOOKUP($D20,Site_Meta!$C$2:$C$43,Site_Meta!E$2:E$43) -> E | G20: =LOOKUP($D20,Site_Meta!$C$2:$C$43,Site_Meta!F$2:F$43) -> 18.36033 | H20: =LOOKUP($D20,Site_Meta!$C$2:$C$43,Site_Meta!G$2:G$43) -> -65.5309 | I20: =LOOKUP($D20,Site_Meta!$C$2:$C$43,Site_Meta!H$2:H$43) -> 5 | J20: 10 | K20: 15 | L20: 2023 | M20: =CONCATENATE(J20,"/",K20,"/",L20) -> 10/15/2023 | N20: Tyrone | O20: Adiana | P20: Manuel | R20: 0.32291667 | S20: 0.33611111 | T20: 30.24 | U20: 0.44 | V20: 35.88 | W20: 0.43 | X20: 34.5 | Y20: 6.01 | Z20: 0.43 | AA20: 7.83 | AB20: 0.43 | AC20: 30.28 | AD20: 3.5 | AE20: 35.86 | AF20: 3.4 | AG20: 34.1 | AH20: 5.79 | AI20: 3.3 | AJ20: 8 | AK20: 3.3 | AL20: >3.5 | AM20: >3.5 | AN20: >3.5 | AO20: =AVERAGE(AL20:AN20) -> #DIV/0! | AP20: 0.5 | AQ20: 3.5 | AR20: 411 | AS20: 412 | AT20: 413 | AU20: 414 | AV20: 415 | AW20: 416 | AX20: 417 | AY20: 418 | AZ20: 419 | BA20: 420 | BB20: 410 | BC20: HydroLab
A21: 2 | B21: =LOOKUP($D21,Site_Meta!$C$2:$C$43,Site_Meta!A$2:A$43) -> Cayo Diablo 5m | C21: =LOOKUP($D21,Site_Meta!$C$2:$C$43,Site_Meta!B$2:B$43) -> Fajardo | D21: DIAB05 | E21: =LOOKUP($D21,Site_Meta!$C$2:$C$43,Site_Meta!D$2:D$43) -> North/Northeast | F21: =LOOKUP($D21,Site_Meta!$C$2:$C$43,Site_Meta!E$2:E$43) -> E | G21: =LOOKUP($D21,Site_Meta!$C$2:$C$43,Site_Meta!F$2:F$43) -> 18.36033 | H21: =LOOKUP($D21,Site_Meta!$C$2:$C$43,Site_Meta!G$2:G$43) -> -65.5309 | I21: =LOOKUP($D21,Site_Meta!$C$2:$C$43,Site_Meta!H$2:H$43) -> 5 | J21: 10 | K21: 15 | L21: 2023 | M21: =CONCATENATE(J21,"/",K21,"/",L21) -> 10/15/2023 | N21: Tyrone | O21: Adiana | P21: Manuel | R21: 0.35069444 | S21: 0.35763889 | T21: 30.4 | U21: 0.51 | V21: 36.75 | W21: 0.51 | X21: 34.5 | Y21: 5.16 | Z21: 0.51 | AA21: 6.19 | AB21: 0.51 | AC21: 31.97 | AD21: 3.55 | AE21: 35.76 | AF21: 3.55 | AG21: 34.1 | AH21: 4.52 | AI21: 3.55 | AJ21: 7.16 | AK21: 3.55 | AL21: NA | AM21: NA | AN21: NA | AO21: =AVERAGE(AL21:AN21) -> #DIV/0! | AP21: NA | AQ21: NA | AR21: NA | AS21: NA | AT21: NA | AU21: NA | AV21: NA | AW21: NA | AX21: NA | AY21: NA | AZ21: NA | BA21: NA | BB21: NA | BC21: YSI
A22: 2 | B22: =LOOKUP($D22,Site_Meta!$C$2:$C$43,Site_Meta!A$2:A$43) -> Dominos 5m | C22: =LOOKUP($D22,Site_Meta!$C$2:$C$43,Site_Meta!B$2:B$43) -> San Juan | D22: DOMI05 | E22: =LOOKUP($D22,Site_Meta!$C$2:$C$43,Site_Meta!D$2:D$43) -> North/Northeast | F22: =LOOKUP($D22,Site_Meta!$C$2:$C$43,Site_Meta!E$2:E$43) -> N | G22: =LOOKUP($D22,Site_Meta!$C$2:$C$43,Site_Meta!F$2:F$43) -> 18.46222 | H22: =LOOKUP($D22,Site_Meta!$C$2:$C$43,Site_Meta!G$2:G$43) -> -66.0517 | I22: =LOOKUP($D22,Site_Meta!$C$2:$C$43,Site_Meta!H$2:H$43) -> 5 | J22: 10 | K22: 6 | L22: 2023 | M22: =CONCATENATE(J22,"/",K22,"/",L22) -> 10/6/2023 | N22: Rodolfo | O22: Leira | P22: Manuel | R22: 0.39722222 | S22: 0.41111111 | T22: 29.85 | U22: 0.63 | V22: 14.79 | W22: 0.53 | X22: 34.8 | Y22: 6.67 | Z22: 0.44 | AA22: 7.96 | AB22: 0.45 | AC22: 29.81 | AD22: 4 | AE22: 7.09 | AF22: 4.03 | AG22: 35 | AH22: 7.02 | AI22: 4.04 | AJ22: 8.05 | AK22: 4.02 | AL22: >4.5 | AM22: >4.5 | AN22: >4.5 | AO22: =AVERAGE(AL22:AN22) -> #DIV/0! | AP22: 0.5 | AQ22: 4 | AR22: 301 | AS22: 302 | AT22: 303 | AU22: 304 | AV22: 305 | AW22: 306 | AX22: 307 | AY22: 308 | AZ22: 309 | BA22: 310 | BB22: 333 | BC22: Check salinity & pH
A23: 2 | B23: =LOOKUP($D23,Site_Meta!$C$2:$C$43,Site_Meta!A$2:A$43) -> Esperanza 10m | C23: =LOOKUP($D23,Site_Meta!$C$2:$C$43,Site_Meta!B$2:B$43) -> Isla Vieques | D23: ESPE10 | E23: =LOOKUP($D23,Site_Meta!$C$2:$C$43,Site_Meta!D$2:D$43) -> Vieques/Culebra | F23: =LOOKUP($D23,Site_Meta!$C$2:$C$43,Site_Meta!E$2:E$43) -> E | G23: =LOOKUP($D23,Site_Meta!$C$2:$C$43,Site_Meta!F$2:F$43) -> 18.08057 | H23: =LOOKUP($D23,Site_Meta!$C$2:$C$43,Site_Meta!G$2:G$43) -> -65.4879 | I23: =LOOKUP($D23,Site_Meta!$C$2:$C$43,Site_Meta!H$2:H$43) -> 10 | J23: 10 | K23: 14 | L23: 2023 | M23: =CONCATENATE(J23,"/",K23,"/",L23) -> 10/14/2023 | N23: Tyrone | O23: Irais | P23: Manuel | R23: 0.38541667 | S23: 0.40555556 | T23: 30.3 | U23: 0.55 | V23: 35.32 | W23: 0.55 | X23: 34.2 | Y23: 6.36 | Z23: 0.54 | AA23: 7.69 | AB23: 0.54 | AC23: 30.13 | AD23: 12.03 | AE23: 35.49 | AF23: 12.02 | AG23: 34.1 | AH23: 6.2 | AI23: 12.03 | AJ23: 6.58 | AK23: 12 | AL23: >12 | AM23: >12 | AN23: >12 | AO23: =AVERAGE(AL23:AN23) -> #DIV/0! | AP23: 0.5 | AQ23: 12 | AR23: 345 | AS23: 346 | AT23: 347 | AU23: 348 | AV23: 349 | AW23: 350 | AX23: 351 | AY23: 352 | AZ23: 353 | BA23: 354 | BB23: 509 | BC23: HydroLab
A24: 2 | B24: =LOOKUP($D24,Site_Meta!$C$2:$C$43,Site_Meta!A$2:A$43) -> Efras Wall 20m | C24: =LOOKUP($D24,Site_Meta!$C$2:$C$43,Site_Meta!B$2:B$43) -> La Parguera | D24: EWAL20 | E24: =LOOKUP($D24,Site_Meta!$C$2:$C$43,Site_Meta!D$2:D$43) -> Southwest | F24: =LOOKUP($D24,Site_Meta!$C$2:$C$43,Site_Meta!E$2:E$43) -> SW | G24: =LOOKUP($D24,Site_Meta!$C$2:$C$43,Site_Meta!F$2:F$43) -> 17.8976 | H24: =LOOKUP($D24,Site_Meta!$C$2:$C$43,Site_Meta!G$2:G$43) -> -66.9599 | I24: =LOOKUP($D24,Site_Meta!$C$2:$C$43,Site_Meta!H$2:H$43) -> 20 | J24: 9 | K24: 19 | L24: 2023 | M24: =CONCATENATE(J24,"/",K24,"/",L24) -> 9/19/2023 | N24: Anibal | O24: Adiana | P24: Leira | Q24: Manuel | R24: 0.33333333 | S24: 0.36041667 | T24: 30.05 | U24: 0.6 | V24: 34.87 | W24: 0.61 | X24: 33.6 | Y24: 6.35 | Z24: 0.62 | AA24: 7.7 | AB24: 0.61 | AC24: 30.16 | AD24: 17.28 | AE24: 34.76 | AF24: 17.4 | AG24: 34.1 | AH24: 5.73 | AI24: 17.51 | AJ24: 8.06 | AK24: 17.5 | AL24: 10.25 | AM24: 10 | AN24: 10.5 | AO24: =AVERAGE(AL24:AN24) -> 10.25 | AP24: 0.5 | AQ24: 17.5 | AR24: 182 | AS24: 183 | AT24: 113 | AU24: 114 | AV24: 55 | AW24: 57 | AX24: 58 | AY24: 55 | AZ24: 72 | BA24: 78 | BB24: 48 | BC24: HydroLab
A25: 2 | B25: =LOOKUP($D25,Site_Meta!$C$2:$C$43,Site_Meta!A$2:A$43) -> Gallardo 5m | C25: =LOOKUP($D25,Site_Meta!$C$2:$C$43,Site_Meta!B$2:B$43) -> Cabo Rojo | D25: GALL05 | E25: =LOOKUP($D25,Site_Meta!$C$2:$C$43,Site_Meta!D$2:D$43) -> West | F25: =LOOKUP($D25,Site_Meta!$C$2:$C$43,Site_Meta!E$2:E$43) -> W | G25: =LOOKUP($D25,Site_Meta!$C$2:$C$43,Site_Meta!F$2:F$43) -> 18.0017 | H25: =LOOKUP($D25,Site_Meta!$C$2:$C$43,Site_Meta!G$2:G$43) -> -67.3299 | I25: =LOOKUP($D25,Site_Meta!$C$2:$C$43,Site_Meta!H$2:H$43) -> 5 | J25: 9 | K25: 20 | L25: 2023 | M25: =CONCATENATE(J25,"/",K25,"/",L25) -> 9/20/2023 | N25: Anibal | O25: Adiana | P25: Manuel | R25: 0.37152778 | S25: 0.38888889 | T25: 30.51 | U25: 0.6 | V25: 33.89 | W25: 0.61 | X25: NA | Y25: 5.77 | Z25: 0.62 | AA25: 7.83 | AB25: 0.58 | AC25: 30.58 | AD25: 6.6 | AE25: 33.94 | AF25: 6.55 | AG25: 33.6 | AH25: 5.75 | AI25: 6.58 | AJ25: 8.02 | AK25: 6.63 | AL25: >6.5 | AM25: >6.5 | AN25: >6.5 | AO25: =AVERAGE(AL25:AN25) -> #DIV/0! | AP25: 0.5 | AQ25: 6.5 | AR25: 187 | AS25: 186 | AT25: 117 | AU25: 118 | AV25: 57 | AW25: 59 | AX25: 60 | AY25: 57 | AZ25: 74 | BA25: 80 | BB25: 50 | BC25: HydroLab; No HOBO
A26: 2 | B26: =LOOKUP($D26,Site_Meta!$C$2:$C$43,Site_Meta!A$2:A$43) -> Guanajibo 20m | C26: =LOOKUP($D26,Site_Meta!$C$2:$C$43,Site_Meta!B$2:B$43) -> Mayaguez | D26: GUAN20 | E26: =LOOKUP($D26,Site_Meta!$C$2:$C$43,Site_Meta!D$2:D$43) -> West | F26: =LOOKUP($D26,Site_Meta!$C$2:$C$43,Site_Meta!E$2:E$43) -> W | G26: =LOOKUP($D26,Site_Meta!$C$2:$C$43,Site_Meta!F$2:F$43) -> 18.17202 | H26: =LOOKUP($D26,Site_Meta!$C$2:$C$43,Site_Meta!G$2:G$43) -> -67.253 | I26: =LOOKUP($D26,Site_Meta!$C$2:$C$43,Site_Meta!H$2:H$43) -> 20 | J26: 10 | K26: 25 | L26: 2023 | M26: =CONCATENATE(J26,"/",K26,"/",L26) -> 10/25/2023 | N26: Orlando | O26: Adiana | P26: Manuel | R26: 0.37916667 | S26: 0.39444444 | T26: 30.34 | U26: 0.34 | V26: 35.44 | W26: 0.34 | X26: 34 | Y26: 6.12 | Z26: 0.34 | AA26: 8.2 | AB26: 0.34 | AC26: 30.02 | AD26: 11.18 | AE26: 35.77 | AF26: 11.18 | AG26: 34.6 | AH26: 6.09 | AI26: 11.18 | AJ26: 8.21 | AK26: 11.18 | AL26: >16 | AM26: >16 | AN26: >16 | AO26: =AVERAGE(AL26:AN26) -> #DIV/0! | AP26: 0.5 | AQ26: 18 | AR26: 587 | AS26: 588 | AT26: 589 | AU26: 590 | AV26: 591 | AW26: 592 | AX26: 593 | AY26: 594 | AZ26: 595 | BA26: 596 | BB26: 586 | BC26: Eureka_Log_Oct_5,20,23-25_2023.xlsx
A27: 2 | B27: =LOOKUP($D27,Site_Meta!$C$2:$C$43,Site_Meta!A$2:A$43) -> Canal Luis Pena 5m | C27: =LOOKUP($D27,Site_Meta!$C$2:$C$43,Site_Meta!B$2:B$43) -> Isla Culebra | D27: LPEN05 | E27: =LOOKUP($D27,Site_Meta!$C$2:$C$43,Site_Meta!D$2:D$43) -> Vieques/Culebra | F27: =LOOKUP($D27,Site_Meta!$C$2:$C$43,Site_Meta!E$2:E$43) -> E | G27: =LOOKUP($D27,Site_Meta!$C$2:$C$43,Site_Meta!F$2:F$43) -> 18.30493 | H27: =LOOKUP($D27,Site_Meta!$C$2:$C$43,Site_Meta!G$2:G$43) -> -65.3277 | I27: =LOOKUP($D27,Site_Meta!$C$2:$C$43,Site_Meta!H$2:H$43) -> 5 | J27: 10 | K27: 13 | L27: 2023 | M27: =CONCATENATE(J27,"/",K27,"/",L27) -> 10/13/2023 | N27: Tyrone | O27: Adiana | P27: Manuel | R27: 0.35625 | S27: 0.37083333 | T27: 29.67 | U27: 0.51 | V27: 35.88 | W27: 0.51 | X27: 34 | Y27: 5.84 | Z27: 0.52 | AA27: 7.73 | AB27: 0.52 | AC27: 29.81 | AD27: 4.58 | AE27: 35.82 | AF27: 4.53 | AG27: 34.2 | AH27: 5.82 | AI27: 4.53 | AJ27: 8.03 | AK27: 4.53 | AL27: >5 | AM27: >5 | AN27: >5 | AO27: =AVERAGE(AL27:AN27) -> #DIV/0! | AP27: 0.5 | AQ27: 5 | AR27: 378 | AS27: 379 | AT27: 380 | AU27: 381 | AV27: 382 | AW27: 383 | AX27: 384 | AY27: 385 | AZ27: 387 | BA27: 386 | BB27: 476 | BC27: HydroLab
A28: 2 | B28: =LOOKUP($D28,Site_Meta!$C$2:$C$43,Site_Meta!A$2:A$43) -> Manchas Exteriores 10m | C28: =LOOKUP($D28,Site_Meta!$C$2:$C$43,Site_Meta!B$2:B$43) -> Mayaguez | D28: MEXT10 | E28: =LOOKUP($D28,Site_Meta!$C$2:$C$43,Site_Meta!D$2:D$43) -> West | F28: =LOOKUP($D28,Site_Meta!$C$2:$C$43,Site_Meta!E$2:E$43) -> W | G28: =LOOKUP($D28,Site_Meta!$C$2:$C$43,Site_Meta!F$2:F$43) -> 18.23353 | H28: =LOOKUP($D28,Site_Meta!$C$2:$C$43,Site_Meta!G$2:G$43) -> -67.2006 | I28: =LOOKUP($D28,Site_Meta!$C$2:$C$43,Site_Meta!H$2:H$43) -> 10 | J28: 10 | K28: 23 | L28: 2023 | M28: =CONCATENATE(J28,"/",K28,"/",L28) -> 10/23/2023 | N28: Anibal | O28: Adiana | P28: Leira | R28: 0.57638889 | S28: 0.60208333 | T28: 30.71 | U28: 0.51 | V28: 35.33 | W28: 0.51 | X28: 33.9 | Y28: 6.21 | Z28: 0.51 | AA28: 8.12 | AB28: 0.51 | AC28: 30.66 | AD28: 10.96 | AE28: 35.43 | AF28: 10.96 | AG28: 33.9 | AH28: 6.22 | AI28: 10.96 | AJ28: 8.19 | AK28: 10.96 | AL28: >10 | AM28: >10 | AN28: >10 | AO28: =AVERAGE(AL28:AN28) -> #DIV/0! | AP28: 0.5 | AQ28: 10 | AR28: 499 | AS28: 500 | AT28: 501 | AU28: 502 | AV28: 503 | AW28: 504 | AX28: 505 | AY28: 506 | AZ28: 507 | BA28: 508 | BB28: 355 | BC28: Eureka_Log_Oct_5,20,23-25_2023.xlsx
A29: 2 | B29: =LOOKUP($D29,Site_Meta!$C$2:$C$43,Site_Meta!A$2:A$43) -> Manchas Exteriores 20m | C29: =LOOKUP($D29,Site_Meta!$C$2:$C$43,Site_Meta!B$2:B$43) -> Mayaguez | D29: MEXT20 | E29: =LOOKUP($D29,Site_Meta!$C$2:$C$43,Site_Meta!D$2:D$43) -> West | F29: =LOOKUP($D29,Site_Meta!$C$2:$C$43,Site_Meta!E$2:E$43) -> W | G29: =LOOKUP($D29,Site_Meta!$C$2:$C$43,Site_Meta!F$2:F$43) -> 18.2335 | H29: =LOOKUP($D29,Site_Meta!$C$2:$C$43,Site_Meta!G$2:G$43) -> -67.2009 | I29: =LOOKUP($D29,Site_Meta!$C$2:$C$43,Site_Meta!H$2:H$43) -> 20 | J29: 10 | K29: 24 | L29: 2023 | M29: =CONCATENATE(J29,"/",K29,"/",L29) -> 10/24/2023 | N29: Anibal | O29: Adiana | P29: Erica | Q29: Manuel | R29: 0.48263889 | S29: 0.50138889 | T29: 30.75 | U29: 0.74 | V29: 35.28 | W29: 0.74 | X29: NA | Y29: 6.22 | Z29: 0.74 | AA29: 8.19 | AB29: 0.74 | AC29: 29.77 | AD29: 18.66 | AE29: 35.83 | AF29: 18.66 | AG29: 34.6 | AH29: 6.07 | AI29: 18.66 | AJ29: 8.2 | AK29: 18.66 | AL29: 11.25 | AM29: 11.25 | AN29: 10.75 | AO29: =AVERAGE(AL29:AN29) -> 11.083333 | AP29: 0.5 | AQ29: 18 | AR29: 576 | AS29: 577 | AT29: 578 | AU29: 579 | AV29: 580 | AW29: 581 | AX29: 582 | AY29: 583 | AZ29: 584 | BA29: 585 | BB29: 388 | BC29: Eureka_Log_Oct_5,20,23-25_2023.xlsx; Correct depth offset ~0.35 m
A30: 2 | B30: =LOOKUP($D30,Site_Meta!$C$2:$C$43,Site_Meta!A$2:A$43) -> Maria Langa 5m | C30: =LOOKUP($D30,Site_Meta!$C$2:$C$43,Site_Meta!B$2:B$43) -> Guayanilla | D30: MLAN05 | E30: =LOOKUP($D30,Site_Meta!$C$2:$C$43,Site_Meta!D$2:D$43) -> South | F30: =LOOKUP($D30,Site_Meta!$C$2:$C$43,Site_Meta!E$2:E$43) -> S | G30: =LOOKUP($D30,Site_Meta!$C$2:$C$43,Site_Meta!F$2:F$43) -> 17.96488 | H30: =LOOKUP($D30,Site_Meta!$C$2:$C$43,Site_Meta!G$2:G$43) -> -66.7565 | I30: =LOOKUP($D30,Site_Meta!$C$2:$C$43,Site_Meta!H$2:H$43) -> 5 | J30: 10 | K30: 4 | L30: 2023 | M30: =CONCATENATE(J30,"/",K30,"/",L30) -> 10/4/2023 | N30: Anibal | O30: Leira | P30: Manuel | R30: 0.36736111 | S30: 0.38402778 | T30: 31.17 | U30: 0.53 | V30: 36.24 | W30: 0.55 | X30: 34.2 | Y30: 5.11 | Z30: 0.54 | AA30: 7.9 | AB30: 0.54 | AC30: 30.96 | AD30: 4.1 | AE30: 36.48 | AF30: 4.07 | AG30: 34 | AH30: 5.05 | AI30: 4.02 | AJ30: 8.02 | AK30: 4.02 | AL30: >4 | AM30: >4 | AN30: >4 | AO30: =AVERAGE(AL30:AN30) -> #DIV/0! | AP30: 0.5 | AQ30: 4 | AR30: 257 | AS30: 258 | AT30: 259 | AU30: 260 | AV30: 261 | AW30: 262 | AX30: 263 | AY30: 264 | AZ30: 265 | BA30: 266 | BB30: 234 | BC30: HydroLab
A31: 2 | B31: =LOOKUP($D31,Site_Meta!$C$2:$C$43,Site_Meta!A$2:A$43) -> Maria Langa 5m | C31: =LOOKUP($D31,Site_Meta!$C$2:$C$43,Site_Meta!B$2:B$43) -> Guayanilla | D31: MLAN05-R | E31: =LOOKUP($D31,Site_Meta!$C$2:$C$43,Site_Meta!D$2:D$43) -> South | F31: =LOOKUP($D31,Site_Meta!$C$2:$C$43,Site_Meta!E$2:E$43) -> S | G31: =LOOKUP($D31,Site_Meta!$C$2:$C$43,Site_Meta!F$2:F$43) -> 17.96488 | H31: =LOOKUP($D31,Site_Meta!$C$2:$C$43,Site_Meta!G$2:G$43) -> -66.7565 | I31: =LOOKUP($D31,Site_Meta!$C$2:$C$43,Site_Meta!H$2:H$43) -> 5 | J31: 10 | K31: 4 | L31: 2023 | M31: =CONCATENATE(J31,"/",K31,"/",L31) -> 10/4/2023 | N31: Anibal | O31: Leira | P31: Manuel | R31: 0.38402778 | S31: 0.39722222 | T31: 31.04 | U31: 0.58 | V31: 36.3 | W31: 0.6 | X31: 33.8 | Y31: 4.37 | Z31: 0.6 | AA31: 7.83 | AB31: 0.6 | AC31: 31.02 | AD31: 2.94 | AE31: 36.25 | AF31: 3.18 | AG31: 33.4 | AH31: 5.01 | AI31: 3.14 | AJ31: 7.99 | AK31: 3.02 | AL31: >3 | AM31: >3 | AN31: >3 | AO31: =AVERAGE(AL31:AN31) -> #DIV/0! | AP31: 0.5 | AQ31: 3 | AR31: 268 | AS31: 269 | AT31: 270 | AU31: 271 | AV31: 272 | AW31: 273 | AX31: 274 | AY31: 275 | AZ31: 276 | BA31: 277 | BB31: 245 | BC31: HydroLab
A32: 2 | B32: =LOOKUP($D32,Site_Meta!$C$2:$C$43,Site_Meta!A$2:A$43) -> Maria Langa 10m | C32: =LOOKUP($D32,Site_Meta!$C$2:$C$43,Site_Meta!B$2:B$43) -> Guayanilla | D32: MLAN10 | E32: =LOOKUP($D32,Site_Meta!$C$2:$C$43,Site_Meta!D$2:D$43) -> South | F32: =LOOKUP($D32,Site_Meta!$C$2:$C$43,Site_Meta!E$2:E$43) -> S | G32: =LOOKUP($D32,Site_Meta!$C$2:$C$43,Site_Meta!F$2:F$43) -> 17.96093 | H32: =LOOKUP($D32,Site_Meta!$C$2:$C$43,Site_Meta!G$2:G$43) -> -66.7529 | I32: =LOOKUP($D32,Site_Meta!$C$2:$C$43,Site_Meta!H$2:H$43) -> 10 | J32: 10 | K32: 4 | L32: 2023 | M32: =CONCATENATE(J32,"/",K32,"/",L32) -> 10/4/2023 | N32: Anibal | O32: Leira | P32: Manuel | R32: 0.34236111 | S32: 0.36041667 | T32: 30.8 | U32: 0.53 | V32: 36.49 | W32: 0.58 | X32: 34.3 | Y32: 5.51 | Z32: 0.57 | AA32: 7.92 | AB32: 0.56 | AC32: 30.72 | AD32: 8.76 | AE32: 36.5 | AF32: 8.82 | AG32: 34.2 | AH32: 5.41 | AI32: 8.86 | AJ32: 8.04 | AK32: 8.92 | AL32: >8.75 | AM32: >8.75 | AN32: >8.75 | AO32: =AVERAGE(AL32:AN32) -> #DIV/0! | AP32: 0.5 | AQ32: 8 | AR32: 246 | AS32: 247 | AT32: 248 | AU32: 249 | AV32: 250 | AW32: 251 | AX32: 252 | AY32: 253 | AZ32: 254 | BA32: 255 | BB32: 223 | BC32: HydroLab
A33: 2 | B33: =LOOKUP($D33,Site_Meta!$C$2:$C$43,Site_Meta!A$2:A$43) -> Maria Langa 20m | C33: =LOOKUP($D33,Site_Meta!$C$2:$C$43,Site_Meta!B$2:B$43) -> Guayanilla | D33: MLAN20 | E33: =LOOKUP($D33,Site_Meta!$C$2:$C$43,Site_Meta!D$2:D$43) -> South | F33: =LOOKUP($D33,Site_Meta!$C$2:$C$43,Site_Meta!E$2:E$43) -> S | G33: =LOOKUP($D33,Site_Meta!$C$2:$C$43,Site_Meta!F$2:F$43) -> 17.95953 | H33: =LOOKUP($D33,Site_Meta!$C$2:$C$43,Site_Meta!G$2:G$43) -> -66.747 | I33: =LOOKUP($D33,Site_Meta!$C$2:$C$43,Site_Meta!H$2:H$43) -> 20 | J33: 10 | K33: 4 | L33: 2023 | M33: =CONCATENATE(J33,"/",K33,"/",L33) -> 10/4/2023 | N33: Anibal | O33: Leira | P33: Manuel | R33: 0.30555556 | S33: 0.33680556 | T33: 31 | U33: 0.58 | V33: 36.36 | W33: 0.59 | X33: 34.2 | Y33: 5.05 | Z33: 0.58 | AA33: 7.4 | AB33: 0.59 | AC33: 30.37 | AD33: 18.5 | AE33: 36.95 | AF33: 18.5 | AG33: 34.6 | AH33: 6.04 | AI33: 18.05 | AJ33: 8.08 | AK33: 17.87 | AL33: 11.25 | AM33: 11.25 | AN33: 11.25 | AO33: =AVERAGE(AL33:AN33) -> 11.25 | AP33: 0.5 | AQ33: 18 | AR33: 235 | AS33: 236 | AT33: 237 | AU33: 238 | AV33: 239 | AW33: 240 | AX33: 241 | AY33: 242 | AZ33: 243 | BA33: 244 | BB33: 212 | BC33: HydroLab
A34: 2 | B34: =LOOKUP($D34,Site_Meta!$C$2:$C$43,Site_Meta!A$2:A$43) -> Media Luna 5m | C34: =LOOKUP($D34,Site_Meta!$C$2:$C$43,Site_Meta!B$2:B$43) -> La Parguera | D34: MLUN05 | E34: =LOOKUP($D34,Site_Meta!$C$2:$C$43,Site_Meta!D$2:D$43) -> Southwest | F34: =LOOKUP($D34,Site_Meta!$C$2:$C$43,Site_Meta!E$2:E$43) -> SW | G34: =LOOKUP($D34,Site_Meta!$C$2:$C$43,Site_Meta!F$2:F$43) -> 17.93937 | H34: =LOOKUP($D34,Site_Meta!$C$2:$C$43,Site_Meta!G$2:G$43) -> -67.0507 | I34: =LOOKUP($D34,Site_Meta!$C$2:$C$43,Site_Meta!H$2:H$43) -> 5 | J34: 9 | K34: 19 | L34: 2023 | M34: =CONCATENATE(J34,"/",K34,"/",L34) -> 9/19/2023 | N34: Anibal | O34: Adiana | P34: Leira | Q34: Manuel | R34: 0.42986111 | S34: 0.44722222 | T34: 31.25 | U34: 0.6 | V34: 34 | W34: 0.56 | X34: 33.6 | Y34: 5.89 | Z34: 0.57 | AA34: 7.99 | AB34: 0.6 | AC34: 31.01 | AD34: 3.2 | AE34: 34.26 | AF34: 3.08 | AG34: 33.9 | AH34: 5.89 | AI34: 3.09 | AJ34: 8.03 | AK34: 3.07 | AL34: >3.5 | AM34: >3.5 | AN34: >3.5 | AO34: =AVERAGE(AL34:AN34) -> #DIV/0! | AP34: 0.5 | AQ34: 3 | AR34: 176 | AS34: 177 | AT34: 107 | AU34: 108 | AV34: 52 | AW34: 54 | AX34: 55 | AY34: 52 | AZ34: 69 | BA34: 75 | BB34: 55 | BC34: HydroLab
A35: 2 | B35: =LOOKUP($D35,Site_Meta!$C$2:$C$43,Site_Meta!A$2:A$43) -> Media Luna 10m | C35: =LOOKUP($D35,Site_Meta!$C$2:$C$43,Site_Meta!B$2:B$43) -> La Parguera | D35: MLUN10 | E35: =LOOKUP($D35,Site_Meta!$C$2:$C$43,Site_Meta!D$2:D$43) -> Southwest | F35: =LOOKUP($D35,Site_Meta!$C$2:$C$43,Site_Meta!E$2:E$43) -> SW | G35: =LOOKUP($D35,Site_Meta!$C$2:$C$43,Site_Meta!F$2:F$43) -> 17.93472 | H35: =LOOKUP($D35,Site_Meta!$C$2:$C$43,Site_Meta!G$2:G$43) -> -67.0485 | I35: =LOOKUP($D35,Site_Meta!$C$2:$C$43,Site_Meta!H$2:H$43) -> 10 | J35: 9 | K35: 19 | L35: 2023 | M35: =CONCATENATE(J35,"/",K35,"/",L35) -> 9/19/2023 | N35: Anibal | O35: Adiana | P35: Leira | Q35: Manuel | R35: 0.40763889 | S35: 0.425 | T35: 30.92 | U35: 0.55 | V35: 34.16 | W35: 0.56 | X35: 34.4 | Y35: 6.11 | Z35: 0.56 | AA35: 7.97 | AB35: 0.5 | AC35: 30.8 | AD35: 5.6 | AE35: 34.2 | AF35: 5.65 | AG35: 33.9 | AH35: 6.12 | AI35: 5.64 | AJ35: 8.06 | AK35: 5.65 | AL35: >5.5 | AM35: >5.5 | AN35: >5.5 | AO35: =AVERAGE(AL35:AN35) -> #DIV/0! | AP35: 0.5 | AQ35: 5 | AR35: 181 | AS35: 180 | AT35: 111 | AU35: 112 | AV35: 54 | AW35: 56 | AX35: 57 | AY35: 54 | AZ35: 71 | BA35: 77 | BB35: 49 | BC35: HydroLab; p.d. Martha and Enterococcus # --> # on field log vs Martha's notes
A36: 2 | B36: =LOOKUP($D36,Site_Meta!$C$2:$C$43,Site_Meta!A$2:A$43) -> El Negro 5m | C36: =LOOKUP($D36,Site_Meta!$C$2:$C$43,Site_Meta!B$2:B$43) -> Cabo Rojo | D36: NEGR05 | E36: =LOOKUP($D36,Site_Meta!$C$2:$C$43,Site_Meta!D$2:D$43) -> West | F36: =LOOKUP($D36,Site_Meta!$C$2:$C$43,Site_Meta!E$2:E$43) -> W | G36: =LOOKUP($D36,Site_Meta!$C$2:$C$43,Site_Meta!F$2:F$43) -> 18.14658 | H36: =LOOKUP($D36,Site_Meta!$C$2:$C$43,Site_Meta!G$2:G$43) -> -67.2476 | I36: =LOOKUP($D36,Site_Meta!$C$2:$C$43,Site_Meta!H$2:H$43) -> 5 | J36: 10 | K36: 25 | L36: 2023 | M36: =CONCATENATE(J36,"/",K36,"/",L36) -> 10/25/2023 | N36: Orlando | O36: Adiana | P36: Manuel | R36: 0.32777778 | S36: 0.34166667 | T36: 30.35 | U36: 0.55 | V36: 35.11 | W36: 0.55 | X36: 34.2 | Y36: 6.03 | Z36: 0.55 | AA36: 8.17 | AB36: 0.55 | AC36: 30.04 | AD36: 8.76 | AE36: 35.71 | AF36: 8.76 | AG36: 34.6 | AH36: 5.88 | AI36: 8.76 | AJ36: 8.19 | AK36: 8.76 | AL36: >7.5 | AM36: >7.5 | AN36: >7.5 | AO36: =AVERAGE(AL36:AN36) -> #DIV/0! | AP36: 0.5 | AQ36: 7.5 | AR36: 477 | AS36: 478 | AT36: 479 | AU36: 480 | AV36: 481 | AW36: 482 | AX36: 483 | AY36: 484 | AZ36: 485 | BA36: 486 | BB36: 575 | BC36: Eureka_Log_Oct_5,20,23-25_2023.xlsx
A37: 2 | B37: =LOOKUP($D37,Site_Meta!$C$2:$C$43,Site_Meta!A$2:A$43) -> El Negro 10m | C37: =LOOKUP($D37,Site_Meta!$C$2:$C$43,Site_Meta!B$2:B$43) -> Cabo Rojo | D37: NEGR10 | E37: =LOOKUP($D37,Site_Meta!$C$2:$C$43,Site_Meta!D$2:D$43) -> West | F37: =LOOKUP($D37,Site_Meta!$C$2:$C$43,Site_Meta!E$2:E$43) -> W | G37: =LOOKUP($D37,Site_Meta!$C$2:$C$43,Site_Meta!F$2:F$43) -> 18.14653 | H37: =LOOKUP($D37,Site_Meta!$C$2:$C$43,Site_Meta!G$2:G$43) -> -67.248 | I37: =LOOKUP($D37,Site_Meta!$C$2:$C$43,Site_Meta!H$2:H$43) -> 10 | J37: 10 | K37: 25 | L37: 2023 | M37: =CONCATENATE(J37,"/",K37,"/",L37) -> 10/25/2023 | N37: Orlando | O37: Adiana | P37: Manuel | R37: 0.34722222 | S37: 0.36319444 | T37: 30.31 | U37: 0.47 | V37: 35.38 | W37: 0.47 | X37: 34.3 | Y37: 6.29 | Z37: 0.47 | AA37: 8.15 | AB37: 0.47 | AC37: 29.89 | AD37: 19.01 | AE37: 35.87 | AF37: 19.01 | AG37: 34.8 | AH37: 5.99 | AI37: 19.01 | AJ37: 8.2 | AK37: 19.01 | AL37: 10 | AM37: 10 | AN37: 10 | AO37: =AVERAGE(AL37:AN37) -> 10 | AP37: 0.5 | AQ37: 18 | AR37: 609 | AS37: 610 | AT37: 611 | AU37: 612 | AV37: 613 | AW37: 614 | AX37: 615 | AY37: 616 | AZ37: 617 | BA37: 618 | BB37: 564 | BC37: Eureka_Log_Oct_5,20,23-25_2023.xlsx
A38: 2 | B38: =LOOKUP($D38,Site_Meta!$C$2:$C$43,Site_Meta!A$2:A$43) -> Palominos 20m | C38: =LOOKUP($D38,Site_Meta!$C$2:$C$43,Site_Meta!B$2:B$43) -> Fajardo | D38: PALN20 | E38: =LOOKUP($D38,Site_Meta!$C$2:$C$43,Site_Meta!D$2:D$43) -> North/Northeast | F38: =LOOKUP($D38,Site_Meta!$C$2:$C$43,Site_Meta!E$2:E$43) -> E | G38: =LOOKUP($D38,Site_Meta!$C$2:$C$43,Site_Meta!F$2:F$43) -> 18.35466 | H38: =LOOKUP($D38,Site_Meta!$C$2:$C$43,Site_Meta!G$2:G$43) -> -65.5671 | I38: =LOOKUP($D38,Site_Meta!$C$2:$C$43,Site_Meta!H$2:H$43) -> 20 | J38: 10 | K38: 15 | L38: 2023 | M38: =CONCATENATE(J38,"/",K38,"/",L38) -> 10/15/2023 | N38: Tyrone | O38: Adiana | P38: Manuel | R38: 0.40694444 | S38: 0.42152778 | T38: NA | U38: NA | V38: NA | W38: NA | X38: 35.1 | Y38: NA | Z38: NA | AA38: NA | AB38: NA | AC38: NA | AD38: NA | AE38: NA | AF38: NA | AG38: 35.2 | AH38: NA | AI38: NA | AJ38: NA | AK38: NA | AL38: 12.25 | AM38: 12.5 | AN38: 12.5 | AO38: =AVERAGE(AL38:AN38) -> 12.416667 | AP38: 0.5 | AQ38: 17.5 | AR38: 433 | AS38: 434 | AT38: 435 | AU38: 436 | AV38: 437 | AW38: 438 | AX38: 439 | AY38: 440 | AZ38: 441 | BA38: 442 | BB38: 432 | BC38: HydroLab; Handheld Surveyor turned off
A39: 2 | B39: =LOOKUP($D39,Site_Meta!$C$2:$C$43,Site_Meta!A$2:A$43) -> Palominos 20m | C39: =LOOKUP($D39,Site_Meta!$C$2:$C$43,Site_Meta!B$2:B$43) -> Fajardo | D39: PALN20 | E39: =LOOKUP($D39,Site_Meta!$C$2:$C$43,Site_Meta!D$2:D$43) -> North/Northeast | F39: =LOOKUP($D39,Site_Meta!$C$2:$C$43,Site_Meta!E$2:E$43) -> E | G39: =LOOKUP($D39,Site_Meta!$C$2:$C$43,Site_Meta!F$2:F$43) -> 18.35466 | H39: =LOOKUP($D39,Site_Meta!$C$2:$C$43,Site_Meta!G$2:G$43) -> -65.5671 | I39: =LOOKUP($D39,Site_Meta!$C$2:$C$43,Site_Meta!H$2:H$43) -> 20 | J39: 10 | K39: 15 | L39: 2023 | M39: =CONCATENATE(J39,"/",K39,"/",L39) -> 10/15/2023 | N39: Tyrone | O39: Adiana | P39: Manuel | R39: 0.41041667 | S39: 0.42083333 | T39: 30.76 | U39: 0.63 | V39: 36.68 | W39: 0.63 | X39: 35.1 | Y39: 5.17 | Z39: 0.63 | AA39: 6.49 | AB39: 0.63 | AC39: 32.04 | AD39: 18.15 | AE39: 35.77 | AF39: 18.15 | AG39: 35.2 | AH39: 4.91 | AI39: 18.15 | AJ39: 6.99 | AK39: 18.15 | AL39: NA | AM39: NA | AN39: NA | AO39: =AVERAGE(AL39:AN39) -> #DIV/0! | AP39: NA | AQ39: NA | AR39: NA | AS39: NA | AT39: NA | AU39: NA | AV39: NA | AW39: NA | AX39: NA | AY39: NA | AZ39: NA | BA39: NA | BB39: NA | BC39: YSI
A40: 2 | B40: =LOOKUP($D40,Site_Meta!$C$2:$C$43,Site_Meta!A$2:A$43) -> Palominitos 10m | C40: =LOOKUP($D40,Site_Meta!$C$2:$C$43,Site_Meta!B$2:B$43) -> Fajardo | D40: PALT10 | E40: =LOOKUP($D40,Site_Meta!$C$2:$C$43,Site_Meta!D$2:D$43) -> North/Northeast | F40: =LOOKUP($D40,Site_Meta!$C$2:$C$43,Site_Meta!E$2:E$43) -> E | G40: =LOOKUP($D40,Site_Meta!$C$2:$C$43,Site_Meta!F$2:F$43) -> 18.33537 | H40: =LOOKUP($D40,Site_Meta!$C$2:$C$43,Site_Meta!G$2:G$43) -> -65.5656 | I40: =LOOKUP($D40,Site_Meta!$C$2:$C$43,Site_Meta!H$2:H$43) -> 10 | J40: 10 | K40: 15 | L40: 2023 | M40: =CONCATENATE(J40,"/",K40,"/",L40) -> 10/15/2023 | N40: Tyrone | O40: Adiana | P40: Manuel | R40: 0.35277778 | S40: 0.37430556 | T40: 30.35 | U40: 0.53 | V40: 35.61 | W40: 0.55 | X40: 34.8 | Y40: 6.3 | Z40: 0.54 | AA40: 7.81 | AB40: 0.54 | AC40: 30.36 | AD40: 8.5 | AE40: 34.23 | AF40: 8.2 | AG40: 33.8 | AH40: 6.12 | AI40: 8.1 | AJ40: 8.11 | AK40: 7.96 | AL40: >8.5 | AM40: >8.5 | AN40: >8.5 | AO40: =AVERAGE(AL40:AN40) -> #DIV/0! | AP40: 0.5 | AQ40: 8.5 | AR40: 422 | AS40: 423 | AT40: 424 | AU40: 425 | AV40: 426 | AW40: 427 | AX40: 428 | AY40: 429 | AZ40: 430 | BA40: 431 | BB40: 421 | BC40: HydroLab
...

Sheet data_tac
A1: Sampling_Cycle | B1: Site_Name | C1: Location | D1: Site_Code | E1: Region | F1: Zone | G1: Latitude | H1: Longitude | I1: Depth | J1: Month | K1: Day | L1: Year | M1: Date | N1: Captain | O1: Crew_1 | P1: Crew_2 | Q1: Crew_3 | R1: Time_In | S1: Time_Out | T1: Surface_Temp_C | U1: Surface_Temp_Depth_m | V1: Surface_Sal_psu | W1: Surface_Sal_Depth_m | X1: Surface_DO_mg_L | Y1: Surface_DO_Depth_m | Z1: Surface_pH | AA1: Surface_pH_Depth_m | AB1: Bottom_Temp_C | AC1: Bottom_Temp_Depth_m | AD1: Bottom_Sal_psu | AE1: Bottom_Sal_Depth_m | AF1: Bottom_DO_mg_L | AG1: Bottom_DO_Depth_m | AH1: Bottom_pH | AI1: Bottom_pH_Depth_m | AJ1: Secchi_Depth_1_m | AK1: Secchi_Depth_2_m | AL1: Secchi_Depth_3_m | AM1: Secchi_Avg_Depth | AN1: Surface_Van_Dorn_Depth_m | AO1: Bottom_Van_Dorn_Depth_m | AP1: Surface_TA_DIC | AQ1: Bottom_TA_DIC | AR1: Surface_BOD | AS1: Bottom_BOD | AT1: Chl_a | AU1: Turbidity_NTU | AV1: Settleable_Solids | AW1: Total_Suspended_Solids | AX1: POx_NOx | AY1: TKN | AZ1: Enterococcus | BA1: Note
A2: 2 | B2: Cayo Aurora 5m | C2: Guanica | D2: AURO05 | E2: Southwest | F2: SW | G2: 17.9369 | H2: -66.8738 | I2: 5 | J2: 10 | K2: 4 | L2: 2023 | M2: 10/4/2023 | N2: Anibal | O2: Leira | P2: Manuel | Q2: NA | R2: 0.41666667 | S2: 0.42986111 | T2: 30.87 | U2: 0.54 | V2: 36.66 | W2: 0.52 | X2: 4.73 | Y2: 0.53 | Z2: 7.84 | AA2: 0.53 | AB2: 31.15 | AC2: 3.03 | AD2: 36.49 | AE2: 3.03 | AF2: 4.87 | AG2: 3.03 | AH2: 7.99 | AI2: 3.03 | AJ2: >3 | AK2: >3 | AL2: >3 | AM2: >3 | AN2: 0.5 | AO2: 3 | AP2: 290 | AQ2: 291 | AR2: 292 | AS2: 293 | AT2: 294 | AU2: 295 | AV2: 296 | AW2: 297 | AX2: 298 | AY2: 299 | AZ2: 256 | BA2: HydroLab
A3: 2 | B3: Puerto Botes 15m | C3: Isla Desecheo | D3: BOTE15 | E3: Mona/Desecheo | F3: W | G3: 18.382 | H3: -67.4883 | I3: 15 | J3: 10 | K3: 23 | L3: 2023 | M3: 10/23/2023 | N3: Anibal | O3: Adiana | P3: Leira | Q3: NA | R3: 0.42916667 | S3: 0.45 | T3: 30.21 | U3: 0.52 | V3: 35.94 | W3: 0.52 | X3: 6.38 | Y3: 0.52 | Z3: 8.17 | AA3: 0.52 | AB3: 30.12 | AC3: 16.46 | AD3: 36.04 | AE3: 16.46 | AF3: 6.2 | AG3: 16.46 | AH3: 8.21 | AI3: 16.46 | AJ3: >15 | AK3: >15 | AL3: >15 | AM3: >15 | AN3: 0.5 | AO3: 15 | AP3: 532 | AQ3: 533 | AR3: 534 | AS3: 535 | AT3: 536 | AU3: 537 | AV3: 538 | AW3: 539 | AX3: 540 | AY3: 541 | AZ3: 433 | BA3: Eureka_Log_Oct_5,20,23-25_2023.xlsx; Correct depth offset ~0.35 m
A4: 2 | B4: Puerto Botes 20m | C4: Isla Desecheo | D4: BOTE20 | E4: Mona/Desecheo | F4: W | G4: 18.38158 | H4: -67.4886 | I4: 20 | J4: 10 | K4: 23 | L4: 2023 | M4: 10/23/2023 | N4: Anibal | O4: Adiana | P4: Leira | Q4: NA | R4: 0.39930556 | S4: 0.42638889 | T4: 30.2 | U4: 0.65 | V4: 35.81 | W4: 0.65 | X4: 6.2 | Y4: 0.65 | Z4: 8.18 | AA4: 0.65 | AB4: 30.9 | AC4: 18.89 | AD4: 36.08 | AE4: 18.89 | AF4: 6.19 | AG4: 18.89 | AH4: 8.22 | AI4: 18.89 | AJ4: >18 | AK4: >18 | AL4: >18 | AM4: >18 | AN4: 0.5 | AO4: 18.5 | AP4: 466 | AQ4: 467 | AR4: 468 | AS4: 469 | AT4: 470 | AU4: 471 | AV4: 472 | AW4: 473 | AX4: 474 | AY4: 475 | AZ4: 374 | BA4: Eureka_Log_Oct_5,20,23-25_2023.xlsx; Correct depth offset ~0.35 m
A5: 2 | B5: Boya Vieja 20m | C5: La Parguera | D5: BOYA20 | E5: Southwest | F5: SW | G5: 17.88827 | H5: -66.9978 | I5: 20 | J5: 9 | K5: 19 | L5: 2023 | M5: 9/19/2023 | N5: Anibal | O5: Adiana | P5: Leira | Q5: Manuel | R5: 0.375 | S5: 0.39583333 | T5: 30.4 | U5: 0.63 | V5: 34.49 | W5: 0.59 | X5: 6.22 | Y5: 0.61 | Z5: 7.93 | AA5: 0.65 | AB5: 29.71 | AC5: 19.3 | AD5: 34.8 | AE5: 19.19 | AF5: 6.18 | AG5: 19.1 | AH5: 8.08 | AI5: 19.08 | AJ5: 12 | AK5: 12 | AL5: 12 | AM5: 12 | AN5: 0.5 | AO5: 19 | AP5: 179 | AQ5: 178 | AR5: 110 | AS5: 109 | AT5: 53 | AU5: 55 | AV5: 56 | AW5: 53 | AX5: 70 | AY5: 76 | AZ5: 47 | BA5: HydroLab
A6: 2 | B6: Cabezas de San Juan 5m | C6: Fajardo | D6: CABE05 | E6: North/Northeast | F6: E | G6: 18.38544 | H6: -65.6297 | I6: 5 | J6: 10 | K6: 15 | L6: 2023 | M6: 10/15/2023 | N6: Tyrone | O6: Adiana | P6: Manuel | Q6: NA | R6: 0.28541667 | S6: 0.30208333 | T6: 29.88 | U6: 0.47 | V6: 36.32 | W6: 0.51 | X6: 5.76 | Y6: 0.52 | Z6: 7.09 | AA6: 0.52 | AB6: 30.05 | AC6: 7.43 | AD6: 35.96 | AE6: 7.44 | AF6: 5.74 | AG6: 7.44 | AH6: 7.14 | AI6: 7.4 | AJ6: >7.5 | AK6: >7.5 | AL6: >7.5 | AM6: >7.5 | AN6: 0.5 | AO6: 7.5 | AP6: 400 | AQ6: 401 | AR6: 402 | AS6: 403 | AT6: 404 | AU6: 405 | AV6: 406 | AW6: 407 | AX6: 408 | AY6: 409 | AZ6: 531 | BA6: HydroLab
A7: 2 | B7: Canjilones 15m | C7: Isla Vieques | D7: CANJ15 | E7: Vieques/Culebra | F7: E | G7: 18.08964 | H7: -65.5901 | I7: 15 | J7: 10 | K7: 14 | L7: 2023 | M7: 10/14/2023 | N7: Tyrone | O7: Irais | P7: Manuel | Q7: NA | R7: 0.425 | S7: 0.44236111 | T7: 30.13 | U7: 0.51 | V7: 34.83 | W7: 0.51 | X7: 6.35 | Y7: 0.5 | Z7: 7.05 | AA7: 0.51 | AB7: 30.02 | AC7: 14.97 | AD7: 35.61 | AE7: 15 | AF7: 5.48 | AG7: 15 | AH7: 6.9 | AI7: 15.01 | AJ7: >15 | AK7: >15 | AL7: >15 | AM7: >15 | AN7: 0.5 | AO7: 15 | AP7: 444 | AQ7: 445 | AR7: 446 | AS7: 447 | AT7: 448 | AU7: 449 | AV7: 450 | AW7: 451 | AX7: 452 | AY7: 453 | AZ7: 520 | BA7: Hydrolab; Check salinity & pH
A8: 2 | B8: Puerto Canoas 30m | C8: Isla Desecheo | D8: CANO30 | E8: Mona/Desecheo | F8: W | G8: 18.37747 | H8: -67.484 | I8: 30 | J8: 10 | K8: 23 | L8: 2023 | M8: 10/23/2023 | N8: Anibal | O8: Adiana | P8: Leira | Q8: NA | R8: 0.45763889 | S8: 0.48333333 | T8: 30.25 | U8: 0.51 | V8: 36.05 | W8: 0.53 | X8: 6.33 | Y8: 0.56 | Z8: 8.2 | AA8: 0.52 | AB8: 30.19 | AC8: 26.61 | AD8: 36.05 | AE8: 26.65 | AF8: 6.22 | AG8: 26.52 | AH8: 8.22 | AI8: 26.67 | AJ8: >26.5 | AK8: >26.5 | AL8: >26.5 | AM8: >26.5 | AN8: 0.5 | AO8: 26.5 | AP8: 521 | AQ8: 522 | AR8: 523 | AS8: 524 | AT8: 525 | AU8: 526 | AV8: 527 | AW8: 528 | AX8: 529 | AY8: 530 | AZ8: 542 | BA8: Eureka; Correct depth offset ~0.35 m
A9: 2 | B9: Puerto Canoas 30m | C9: Isla Desecheo | D9: CANO30-R | E9: Mona/Desecheo | F9: W | G9: 18.37747 | H9: -67.484 | I9: 30 | J9: 10 | K9: 23 | L9: 2023 | M9: 10/23/2023 | N9: Anibal | O9: Adiana | P9: Leira | Q9: NA | R9: 0.48611111 | S9: 0.50625 | T9: 30.27 | U9: 0.57 | V9: 35.85 | W9: 0.57 | X9: 6.27 | Y9: 0.57 | Z9: 8.22 | AA9: 0.57 | AB9: 30.19 | AC9: 29.12 | AD9: 34.37 | AE9: 29.12 | AF9: 6.3 | AG9: 29.12 | AH9: 8.22 | AI9: 29.12 | AJ9: >29 | AK9: >29 | AL9: >29 | AM9: >29 | AN9: 0.5 | AO9: 29 | AP9: 510 | AQ9: 511 | AR9: 512 | AS9: 513 | AT9: 514 | AU9: 515 | AV9: 516 | AW9: 517 | AX9: 518 | AY9: 519 | AZ9: 399 | BA9: Eureka_Log_Oct_5,20,23-25_2023.xlsx; Correct depth offset ~0.35 m
A10: 2 | B10: Cayo Caribes 10m | C10: Salinas | D10: CARI10 | E10: Southeast | F10: S | G10: 17.91533 | H10: -66.2141 | I10: 10 | J10: 9 | K10: 21 | L10: 2023 | M10: 9/21/2023 | N10: Anibal | O10: Adiana | P10: Juanita | Q10: Manuel | R10: 0.36805556 | S10: 0.39583333 | T10: 30.62 | U10: 0.54 | V10: 35.85 | W10: 0.55 | X10: 6.1 | Y10: 0.56 | Z10: 7.94 | AA10: 0.56 | AB10: 30.84 | AC10: 9.51 | AD10: 35.55 | AE10: 9.5 | AF10: 6.05 | AG10: 9.62 | AH10: 8.08 | AI10: 9.62 | AJ10: >10 | AK10: >10 | AL10: >10 | AM10: >10 | AN10: 0.5 | AO10: 9.5 | AP10: 184 | AQ10: 185 | AR10: 115 | AS10: 116 | AT10: 56 | AU10: 58 | AV10: 59 | AW10: 56 | AX10: 73 | AY10: 79 | AZ10: 65 | BA10: HydroLab
A11: 2 | B11: West Reef 10m | C11: Ponce | D11: CDMU10 | E11: South | F11: S | G11: 17.89502 | H11: -66.5284 | I11: 10 | J11: 9 | K11: 21 | L11: 2023 | M11: 9/21/2023 | N11: Anibal | O11: Adiana | P11: Juanita | Q11: Manuel | R11: 0.44722222 | S11: 0.46111111 | T11: 30.86 | U11: 0.59 | V11: 34.73 | W11: 0.59 | X11: 6.52 | Y11: 0.62 | Z11: 8.03 | AA11: 0.68 | AB11: 30.62 | AC11: 8.03 | AD11: 34.72 | AE11: 7.9 | AF11: 6.64 | AG11: 7.77 | AH11: 8.09 | AI11: 7.57 | AJ11: >8 | AK11: >8 | AL11: >8 | AM11: >8 | AN11: 0.5 | AO11: 7.5 | AP11: 200 | AQ11: 201 | AR11: 131 | AS11: 132 | AT11: 64 | AU11: 66 | AV11: 67 | AW11: 64 | AX11: 81 | AY11: 87 | AZ11: 56 | BA11: HydroLab
A12: 2 | B12: Cibuco 05m | C12: Vega Baja | D12: CIBU05 | E12: North/Northeast | F12: N | G12: 18.48955 | H12: -66.3736 | I12: 10 | J12: 10 | K12: 6 | L12: 2023 | M12: 10/6/2023 | N12: Rodolfo | O12: Leira | P12: Manuel | Q12: NA | R12: 0.27847222 | S12: 0.29236111 | T12: 29.65 | U12: 0.42 | V12: 34.71 | W12: 0.42 | X12: 5.79 | Y12: 0.45 | Z12: 7.69 | AA12: 0.49 | AB12: 29.85 | AC12: 1.92 | AD12: 34.45 | AE12: 1.97 | AF12: 5.73 | AG12: 2.01 | AH12: 7.95 | AI12: 2.03 | AJ12: >2.5 | AK12: >2.5 | AL12: >2.5 | AM12: >2.5 | AN12: 0.5 | AO12: 2 | AP12: 323 | AQ12: 324 | AR12: 325 | AS12: 326 | AT12: 327 | AU12: 328 | AV12: 329 | AW12: 330 | AX12: 331 | AY12: 332 | AZ12: 311 | BA12: Check salinity & pH
A13: 2 | B13: Cibuco 05m | C13: Vega Baja | D13: CIBU05-R | E13: North/Northeast | F13: N | G13: 18.48955 | H13: -66.3736 | I13: 10 | J13: 10 | K13: 6 | L13: 2023 | M13: 10/6/2023 | N13: Rodolfo | O13: Leira | P13: Manuel | Q13: NA | R13: 0.29722222 | S13: 0.30555556 | T13: 29.85 | U13: 0.49 | V13: 31.76 | W13: 0.52 | X13: 5.88 | Y13: 0.51 | Z13: 7.74 | AA13: 0.52 | AB13: 29.9 | AC13: 2.45 | AD13: NA | AE13: 2.5 | AF13: 6.72 | AG13: 2.5 | AH13: 8.01 | AI13: 2.48 | AJ13: >2.5 | AK13: >2.5 | AL13: >2.5 | AM13: >2.5 | AN13: 0.5 | AO13: 2.5 | AP13: 334 | AQ13: 335 | AR13: 336 | AS13: 337 | AT13: 338 | AU13: 339 | AV13: 340 | AW13: 341 | AX13: 342 | AY13: 343 | AZ13: 322 | BA13: Check salinity & pH
A14: 2 | B14: Cayo Coral 10m | C14: Guanica | D14: CORA10 | E14: Southwest | F14: SW | G14: 17.9362 | H14: -66.8884 | I14: 10 | J14: 10 | K14: 4 | L14: 2023 | M14: 10/4/2023 | N14: Anibal | O14: Leira | P14: Manuel | Q14: NA | R14: 0.43472222 | S14: 0.44930556 | T14: 31.21 | U14: 0.49 | V14: 36.03 | W14: 0.49 | X14: 5.77 | Y14: 0.49 | Z14: 7.94 | AA14: 0.49 | AB14: 30.99 | AC14: 8.9 | AD14: 36.45 | AE14: 8.96 | AF14: 3.87 | AG14: 8.99 | AH14: 7.95 | AI14: 9 | AJ14: >9 | AK14: >9 | AL14: >9 | AM14: >9 | AN14: 0.5 | AO14: 9 | AP14: 279 | AQ14: 280 | AR14: 281 | AS14: 282 | AT14: 283 | AU14: 284 | AV14: 285 | AW14: 286 | AX14: 287 | AY14: 288 | AZ14: 267 | BA14: HydroLab
A15: 2 | B15: Carlos Rosario 10m | C15: Isla Culebra | D15: CROS10 | E15: Vieques/Culebra | F15: E | G15: 18.32779 | H15: -65.332 | I15: 10 | J15: 10 | K15: 13 | L15: 2023 | M15: 10/13/2023 | N15: Tyrone | O15: Adiana | P15: Manuel | Q15: NA | R15: 0.39166667 | S15: 0.40833333 | T15: 29.89 | U15: 0.44 | V15: 36.07 | W15: 0.49 | X15: 6.11 | Y15: 0.5 | Z15: 7.92 | AA15: 0.5 | AB15: 29.9 | AC15: 10.01 | AD15: 35.89 | AE15: 9.95 | AF15: 6.06 | AG15: 9.97 | AH15: 8.1 | AI15: 9.98 | AJ15: >10 | AK15: >10 | AL15: >10 | AM15: >10 | AN15: 0.5 | AO15: 10 | AP15: 356 | AQ15: 357 | AR15: 358 | AS15: 359 | AT15: 360 | AU15: 361 | AV15: 362 | AW15: 363 | AX15: 364 | AY15: 365 | AZ15: 487 | BA15: Hydrolab; Check salinity & pH
A16: 2 | B16: Dakiti 20m | C16: Isla Culebra | D16: DAKI20 | E16: Vieques/Culebra | F16: E | G16: 18.27587 | H16: -65.2773 | I16: 20 | J16: 10 | K16: 13 | L16: 2023 | M16: 10/13/2023 | N16: Tyrone | O16: Adiana | P16: Manuel | Q16: NA | R16: 0.3 | S16: 0.32083333 | T16: 29.56 | U16: 0.52 | V16: 36.04 | W16: 0.55 | X16: 6.26 | Y16: 0.55 | Z16: 7.78 | AA16: 0.52 | AB16: 29.92 | AC16: 20.07 | AD16: 36.23 | AE16: 20.07 | AF16: 5.52 | AG16: 20.06 | AH16: 8.05 | AI16: 20.06 | AJ16: >20 | AK16: >20 | AL16: >20 | AM16: >20 | AN16: 0.5 | AO16: 20 | AP16: 389 | AQ16: 390 | AR16: 391 | AS16: 392 | AT16: 393 | AU16: 394 | AV16: 395 | AW16: 396 | AX16: 397 | AY16: 398 | AZ16: 454 | BA16: Hydrolab; Check salinity & pH
A17: 2 | B17: Dakiti 20m | C17: Isla Culebra | D17: DAKI20-R | E17: Vieques/Culebra | F17: E | G17: 18.27587 | H17: -65.2773 | I17: 20 | J17: 10 | K17: 13 | L17: 2023 | M17: 10/13/2023 | N17: Tyrone | O17: Adiana | P17: Manuel | Q17: NA | R17: 0.32638889 | S17: 0.34166667 | T17: 29.7 | U17: 0.5 | V17: 35.99 | W17: 0.5 | X17: 6.13 | Y17: 0.49 | Z17: 7.94 | AA17: 0.48 | AB17: 29.92 | AC17: 19.93 | AD17: 36.2 | AE17: 19.97 | AF17: 5.72 | AG17: 19.98 | AH17: 8.08 | AI17: 19.97 | AJ17: >20 | AK17: >20 | AL17: >20 | AM17: >20 | AN17: 0.5 | AO17: 20 | AP17: 312 | AQ17: 313 | AR17: 314 | AS17: 315 | AT17: 316 | AU17: 317 | AV17: 318 | AW17: 319 | AX17: 320 | AY17: 321 | AZ17: 465 | BA17: Hydrolab; Check salinity & pH
A18: 2 | B18: Derrumbadero 20m | C18: Ponce | D18: DERR20 | E18: South | F18: S | G18: 17.904 | H18: -66.6086 | I18: 20 | J18: 9 | K18: 21 | L18: 2023 | M18: 9/21/2023 | N18: Anibal | O18: Adiana | P18: Juanita | Q18: Manuel | R18: 0.47569444 | S18: 0.49722222 | T18: 30.9 | U18: 0.63 | V18: 34.36 | W18: 0.67 | X18: 6.32 | Y18: 0.7 | Z18: 8.08 | AA18: 0.7 | AB18: 30.12 | AC18: 16.5 | AD18: 35 | AE18: 17 | AF18: 6.2 | AG18: 17.3 | AH18: 8.06 | AI18: 17.33 | AJ18: 12.25 | AK18: 12.5 | AL18: 12.75 | AM18: 12.5 | AN18: 0.5 | AO18: 17 | AP18: 190 | AQ18: 191 | AR18: 121 | AS18: 122 | AT18: 59 | AU18: 61 | AV18: 62 | AW18: 59 | AX18: 76 | AY18: 82 | AZ18: 57 | BA18: HydroLab
A19: 2 | B19: Cayo Diablo 5m | C19: Fajardo | D19: DIAB05 | E19: North/Northeast | F19: E | G19: 18.36033 | H19: -65.5309 | I19: 5 | J19: 10 | K19: 15 | L19: 2023 | M19: 10/15/2023 | N19: Tyrone | O19: Adiana | P19: Manuel | Q19: NA | R19: 0.32291667 | S19: 0.33611111 | T19: 30.24 | U19: 0.44 | V19: 35.88 | W19: 0.43 | X19: 6.01 | Y19: 0.43 | Z19: 7.83 | AA19: 0.43 | AB19: 30.28 | AC19: 3.5 | AD19: 35.86 | AE19: 3.4 | AF19: 5.79 | AG19: 3.3 | AH19: 8 | AI19: 3.3 | AJ19: >3.5 | AK19: >3.5 | AL19: >3.5 | AM19: >3.5 | AN19: 0.5 | AO19: 3.5 | AP19: 411 | AQ19: 412 | AR19: 413 | AS19: 414 | AT19: 415 | AU19: 416 | AV19: 417 | AW19: 418 | AX19: 419 | AY19: 420 | AZ19: 410 | BA19: HydroLab
