Workbook

Sheet Raw Data
A1: Sampling_Cycle | B1: Site_Name | C1: Location | D1: Site_Code | E1: Region | F1: Zone | G1: Latitude | H1: Longitude | I1: Depth | J1: Month | K1: Day | L1: Year | M1: Date | N1: Captain | O1: Crew_1 | P1: Crew_2 | Q1: Crew_3 | R1: Time_In | S1: Time_Out | T1: Surface_Temp_C | U1: Surface_Temp_Depth_m | V1: Surface_Sal_psu | W1: Surface_Sal_Depth_m | X1: Surface_DO_mg_L | Y1: Surface_DO_Depth_m | Z1: Surface_pH | AA1: Surface_pH_Depth_m | AB1: Bottom_Temp_C | AC1: Bottom_Temp_Depth_m | AD1: Bottom_Sal_psu | AE1: Bottom_Sal_Depth_m | AF1: Bottom_DO_mg_L | AG1: Bottom_DO_Depth_m | AH1: Bottom_pH | AI1: Bottom_pH_Depth_m | AJ1: Secchi_Depth_1_m | AK1: Secchi_Depth_2_m | AL1: Secchi_Depth_3_m | AM1: Secchi_Avg_Depth | AN1: Surface_Van_Dorn_Depth_m | AO1: Bottom_Van_Dorn_Depth_m | AP1: Surface_TA_DIC | AQ1: Bottom_TA_DIC | AR1: Surface_BOD | AS1: Bottom_BOD | AT1: Chl_a | AU1: Turbidity_NTU | AV1: Settleable_Solids | AW1: Total_Suspended_Solids | AX1: POx_NOx | AY1: TKN | AZ1: Enterococcus | BA1: Note
A2: 7 | B2: =LOOKUP($D2,Site_Meta!$C$2:$C$43,Site_Meta!A$2:A$43) -> Media Luna 5m | C2: =LOOKUP($D2,Site_Meta!$C$2:$C$43,Site_Meta!B$2:B$43) -> La Parguera | D2: MLUN05 | E2: =LOOKUP($D2,Site_Meta!$C$2:$C$43,Site_Meta!D$2:D$43) -> Southwest | F2: =LOOKUP($D2,Site_Meta!$C$2:$C$43,Site_Meta!E$2:E$43) -> SW | G2: =LOOKUP($D2,Site_Meta!$C$2:$C$43,Site_Meta!F$2:F$43) -> 17.93937 | H2: =LOOKUP($D2,Site_Meta!$C$2:$C$43,Site_Meta!G$2:G$43) -> -67.0507 | I2: =LOOKUP($D2,Site_Meta!$C$2:$C$43,Site_Meta!H$2:H$43) -> 5 | J2: 11 | K2: 14 | L2: 24 | M2: =CONCATENATE(J2,"/",K2,"/",L2) -> 11/14/24 | N2: Anibal | O2: Manuel O | P2: Victoria | Q2: NA | R2: 0.48680556 | S2: 0.50277778 | T2: 29.58 | U2: 0.54 | V2: 33.86 | W2: 0.48 | X2: 6.34 | Y2: 0.5 | Z2: 8.13 | AA2: 0.52 | AB2: 29.37 | AC2: 3 | AD2: 33.8 | AE2: 3.01 | AF2: 6.13 | AG2: 3.71 | AH2: 8.11 | AI2: 3.71 | AJ2: 5 | AK2: 5 | AL2: 5 | AM2: 5 | AN2: 0.5 | AP2: 53 | AQ2: 54 | AR2: 55 | AS2: 56 | AT2: 57 | AU2: 58 | AV2: 59 | AW2: 60 | AX2: 61 | AY2: 62 | AZ2: 63
A3: 7 | B3: =LOOKUP($D3,Site_Meta!$C$2:$C$43,Site_Meta!A$2:A$43) -> Media Luna 10m | C3: =LOOKUP($D3,Site_Meta!$C$2:$C$43,Site_Meta!B$2:B$43) -> La Parguera | D3: MLUN20 | E3: =LOOKUP($D3,Site_Meta!$C$2:$C$43,Site_Meta!D$2:D$43) -> Southwest | F3: =LOOKUP($D3,Site_Meta!$C$2:$C$43,Site_Meta!E$2:E$43) -> SW | G3: =LOOKUP($D3,Site_Meta!$C$2:$C$43,Site_Meta!F$2:F$43) -> 17.93472 | H3: =LOOKUP($D3,Site_Meta!$C$2:$C$43,Site_Meta!G$2:G$43) -> -67.0485 | I3: =LOOKUP($D3,Site_Meta!$C$2:$C$43,Site_Meta!H$2:H$43) -> 10 | J3: 11 | K3: 14 | L3: 24 | M3: =CONCATENATE(J3,"/",K3,"/",L3) -> 11/14/24 | N3: Anibal | O3: Manuel O | P3: Victoria | Q3: NA | R3: 0.30763889 | S3: 0.33125 | T3: 29.07 | U3: 0.55 | V3: 33.39 | W3: 0.56 | X3: 6.49 | Y3: 0.56 | Z3: 8.07 | AA3: 0.54 | AB3: 29.55 | AC3: 9.56 | AD3: 34.1 | AE3: 9.44 | AF3: 6.21 | AG3: 9.22 | AH3: 8.13 | AI3: 9.11 | AJ3: 10 | AK3: 10 | AL3: 10 | AM3: 10 | AN3: 0.5 | AO3: 10 | AP3: 79 | AQ3: 80 | AR3: 81 | AS3: 82 | AT3: 83 | AU3: 84 | AV3: 85 | AW3: 86 | AX3: 87 | AY3: 88 | AZ3: 89
A4: 7 | B4: =LOOKUP($D4,Site_Meta!$C$2:$C$43,Site_Meta!A$2:A$43) -> Maria Langa 10m | C4: =LOOKUP($D4,Site_Meta!$C$2:$C$43,Site_Meta!B$2:B$43) -> Guayanilla | D4: MLAN10 | E4: =LOOKUP($D4,Site_Meta!$C$2:$C$43,Site_Meta!D$2:D$43) -> South | F4: =LOOKUP($D4,Site_Meta!$C$2:$C$43,Site_Meta!E$2:E$43) -> S | G4: =LOOKUP($D4,Site_Meta!$C$2:$C$43,Site_Meta!F$2:F$43) -> 17.96093 | H4: =LOOKUP($D4,Site_Meta!$C$2:$C$43,Site_Meta!G$2:G$43) -> -66.7529 | I4: =LOOKUP($D4,Site_Meta!$C$2:$C$43,Site_Meta!H$2:H$43) -> 10 | J4: 11 | K4: 14 | L4: 24 | M4: =CONCATENATE(J4,"/",K4,"/",L4) -> 11/14/24 | N4: Anibal | O4: Manuel O | P4: Victoria | Q4: NA | R4: 0.33819444 | S4: 0.34861111 | T4: 29.35 | U4: 0.47 | V4: 33.87 | W4: 0.53 | X4: 6.33 | Y4: 0.51 | Z4: 8.13 | AA4: 0.51 | AB4: 29.56 | AC4: 8.51 | AD4: 34.1 | AE4: 8.63 | AF4: 6.16 | AG4: 8.56 | AH4: 8.13 | AI4: 8.68 | AJ4: 10 | AK4: 10 | AL4: 10 | AM4: 10 | AN4: 0.5 | AO4: 8 | AP4: 105 | AQ4: 106 | AR4: 107 | AS4: 108 | AT4: 109 | AU4: 110 | AV4: 111 | AW4: 112 | AX4: 113 | AY4: 114 | AZ4: 115
A5: 7 | B5: =LOOKUP($D5,Site_Meta!$C$2:$C$43,Site_Meta!A$2:A$43) -> Maria Langa 5m | C5: =LOOKUP($D5,Site_Meta!$C$2:$C$43,Site_Meta!B$2:B$43) -> Guayanilla | D5: MLAN05 | E5: =LOOKUP($D5,Site_Meta!$C$2:$C$43,Site_Meta!D$2:D$43) -> South | F5: =LOOKUP($D5,Site_Meta!$C$2:$C$43,Site_Meta!E$2:E$43) -> S | G5: =LOOKUP($D5,Site_Meta!$C$2:$C$43,Site_Meta!F$2:F$43) -> 17.96488 | H5: =LOOKUP($D5,Site_Meta!$C$2:$C$43,Site_Meta!G$2:G$43) -> -66.7565 | I5: =LOOKUP($D5,Site_Meta!$C$2:$C$43,Site_Meta!H$2:H$43) -> 5 | J5: 11 | K5: 14 | L5: 24 | M5: =CONCATENATE(J5,"/",K5,"/",L5) -> 11/14/24 | N5: Anibal | O5: Manuel O | P5: Victoria | Q5: NA | R5: 0.35555556 | S5: 0.36111111 | T5: 29.14 | U5: 0.48 | V5: 33.54 | W5: 0.49 | X5: 5.41 | Y5: 0.49 | Z5: 8.04 | AA5: 0.5 | AB5: 29.54 | AC5: 3.78 | AD5: 34.13 | AE5: 3.59 | AF5: 5.27 | AG5: 3.81 | AH5: 8.1 | AI5: 3.9 | AJ5: 10 | AK5: 10 | AL5: 10 | AM5: 10 | AN5: 0.5 | AO5: 3 | AP5: 92 | AQ5: 93 | AR5: 94 | AS5: 95 | AT5: 96 | AU5: 97 | AV5: 98 | AW5: 99 | AX5: 100 | AY5: 101 | AZ5: 102
A6: 7 | B6: =LOOKUP($D6,Site_Meta!$C$2:$C$43,Site_Meta!A$2:A$43) -> Cayo Aurora 5m | C6: =LOOKUP($D6,Site_Meta!$C$2:$C$43,Site_Meta!B$2:B$43) -> Guanica | D6: AURO05 | E6: =LOOKUP($D6,Site_Meta!$C$2:$C$43,Site_Meta!D$2:D$43) -> Southwest | F6: =LOOKUP($D6,Site_Meta!$C$2:$C$43,Site_Meta!E$2:E$43) -> SW | G6: =LOOKUP($D6,Site_Meta!$C$2:$C$43,Site_Meta!F$2:F$43) -> 17.9369 | H6: =LOOKUP($D6,Site_Meta!$C$2:$C$43,Site_Meta!G$2:G$43) -> -66.8738 | I6: =LOOKUP($D6,Site_Meta!$C$2:$C$43,Site_Meta!H$2:H$43) -> 5 | J6: 11 | K6: 14 | L6: 24 | M6: =CONCATENATE(J6,"/",K6,"/",L6) -> 11/14/24 | N6: Anibal | O6: Manuel O | P6: Victoria | Q6: NA | R6: 0.38194444 | S6: 0.39097222 | T6: 29.65 | U6: 0.56 | V6: 33.94 | W6: 0.46 | X6: 5.41 | Y6: 0.5 | Z6: 8.1 | AA6: 0.49 | AB6: 29.63 | AC6: 3.49 | AD6: 34.05 | AE6: 3.47 | AF6: 5.33 | AG6: 3.49 | AH6: 8.1 | AI6: 3.44 | AJ6: 10 | AK6: 10 | AL6: 10 | AM6: 10 | AN6: 0.5 | AO6: 3 | AP6: 1 | AQ6: 2 | AR6: 3 | AS6: 4 | AT6: 5 | AU6: 6 | AV6: 7 | AW6: 8 | AX6: 9 | AY6: 10 | AZ6: 11
A7: 7 | B7: =LOOKUP($D7,Site_Meta!$C$2:$C$43,Site_Meta!A$2:A$43) -> Cayo Coral 10m | C7: =LOOKUP($D7,Site_Meta!$C$2:$C$43,Site_Meta!B$2:B$43) -> Guanica | D7: CORA10 | E7: =LOOKUP($D7,Site_Meta!$C$2:$C$43,Site_Meta!D$2:D$43) -> Southwest | F7: =LOOKUP($D7,Site_Meta!$C$2:$C$43,Site_Meta!E$2:E$43) -> SW | G7: =LOOKUP($D7,Site_Meta!$C$2:$C$43,Site_Meta!F$2:F$43) -> 17.9362 | H7: =LOOKUP($D7,Site_Meta!$C$2:$C$43,Site_Meta!G$2:G$43) -> -66.8884 | I7: =LOOKUP($D7,Site_Meta!$C$2:$C$43,Site_Meta!H$2:H$43) -> 10 | J7: 11 | K7: 14 | L7: 24 | M7: =CONCATENATE(J7,"/",K7,"/",L7) -> 11/14/24 | N7: Anibal | O7: Manuel O | P7: Victoria | Q7: NA | R7: 0.39861111 | S7: 0.41041667 | T7: 29.67 | U7: 0.64 | V7: 33.78 | W7: 0.46 | X7: 6.11 | Y7: 0.47 | Z7: 8.1 | AA7: 0.48 | AB7: 29.59 | AC7: 8 | AD7: 33.92 | AE7: 8.03 | AF7: 5.94 | AG7: 8.09 | AH7: 8.12 | AI7: 8.06 | AJ7: 10 | AK7: 10 | AL7: 10 | AM7: 10 | AN7: 0.5 | AO7: 8 | AP7: 14 | AQ7: 15 | AR7: 16 | AS7: 17 | AT7: 18 | AU7: 19 | AV7: 20 | AW7: 21 | AX7: 22 | AY7: 23 | AZ7: 24
A8: 7 | B8: =LOOKUP($D8,Site_Meta!$C$2:$C$43,Site_Meta!A$2:A$43) -> Efras Wall 20m | C8: =LOOKUP($D8,Site_Meta!$C$2:$C$43,Site_Meta!B$2:B$43) -> La Parguera | D8: EWAL20 | E8: =LOOKUP($D8,Site_Meta!$C$2:$C$43,Site_Meta!D$2:D$43) -> Southwest | F8: =LOOKUP($D8,Site_Meta!$C$2:$C$43,Site_Meta!E$2:E$43) -> SW | G8: =LOOKUP($D8,Site_Meta!$C$2:$C$43,Site_Meta!F$2:F$43) -> 17.8976 | H8: =LOOKUP($D8,Site_Meta!$C$2:$C$43,Site_Meta!G$2:G$43) -> -66.9599 | I8: =LOOKUP($D8,Site_Meta!$C$2:$C$43,Site_Meta!H$2:H$43) -> 20 | J8: 11 | K8: 14 | L8: 24 | M8: =CONCATENATE(J8,"/",K8,"/",L8) -> 11/14/24 | N8: Anibal | O8: Manuel O | P8: Victoria | Q8: NA | R8: 0.425 | S8: 0.4375 | T8: 29.53 | U8: 0.63 | V8: 33.75 | W8: 0.62 | X8: 6.49 | Y8: 0.59 | Z8: 8.15 | AA8: 0.64 | AB8: 29.6 | AC8: 18.55 | AD8: 34.14 | AE8: 18.48 | AF8: 5.86 | AG8: 18.48 | AH8: 8.13 | AI8: 18.38 | AJ8: 12 | AK8: 12 | AL8: 12 | AM8: 12 | AN8: 0.5 | AO8: 18 | AP8: 40 | AQ8: 41 | AR8: 42 | AS8: 43 | AT8: 44 | AU8: 45 | AV8: 46 | AW8: 47 | AX8: 48 | AY8: 49 | AZ8: 50
A9: 7 | B9: =LOOKUP($D9,Site_Meta!$C$2:$C$43,Site_Meta!A$2:A$43) -> Boya Vieja 20m | C9: =LOOKUP($D9,Site_Meta!$C$2:$C$43,Site_Meta!B$2:B$43) -> La Parguera | D9: BOYA20 | E9: =LOOKUP($D9,Site_Meta!$C$2:$C$43,Site_Meta!D$2:D$43) -> Southwest | F9: =LOOKUP($D9,Site_Meta!$C$2:$C$43,Site_Meta!E$2:E$43) -> SW | G9: =LOOKUP($D9,Site_Meta!$C$2:$C$43,Site_Meta!F$2:F$43) -> 17.88827 | H9: =LOOKUP($D9,Site_Meta!$C$2:$C$43,Site_Meta!G$2:G$43) -> -66.9978 | I9: =LOOKUP($D9,Site_Meta!$C$2:$C$43,Site_Meta!H$2:H$43) -> 20 | J9: 11 | K9: 14 | L9: 24 | M9: =CONCATENATE(J9,"/",K9,"/",L9) -> 11/14/24 | N9: Anibal | O9: Manuel O | P9: Victoria | Q9: NA | R9: 0.44791667 | S9: 0.45833333 | T9: 29.69 | U9: 0.6 | V9: 34.04 | W9: 0.61 | X9: 5.78 | Y9: 0.59 | Z9: 8.13 | AA9: 0.57 | AB9: 29.62 | AC9: 17.97 | AD9: 34.11 | AE9: 18.24 | AF9: 5.87 | AG9: 18.12 | AH9: 8.14 | AI9: 18.02 | AJ9: 20 | AK9: 20 | AL9: 20 | AM9: 20 | AN9: 0.5 | AO9: 18 | AP9: 66 | AQ9: 67 | AR9: 68 | AS9: 69 | AT9: 70 | AU9: 71 | AV9: 72 | AW9: 73 | AX9: 74 | AY9: 75 | AZ9: 76
A10: 7 | B10: =LOOKUP($D10,Site_Meta!$C$2:$C$43,Site_Meta!A$2:A$43) -> Media Luna 10m | C10: =LOOKUP($D10,Site_Meta!$C$2:$C$43,Site_Meta!B$2:B$43) -> La Parguera | D10: MLUN10 | E10: =LOOKUP($D10,Site_Meta!$C$2:$C$43,Site_Meta!D$2:D$43) -> Southwest | F10: =LOOKUP($D10,Site_Meta!$C$2:$C$43,Site_Meta!E$2:E$43) -> SW | G10: =LOOKUP($D10,Site_Meta!$C$2:$C$43,Site_Meta!F$2:F$43) -> 17.93472 | H10: =LOOKUP($D10,Site_Meta!$C$2:$C$43,Site_Meta!G$2:G$43) -> -67.0485 | I10: =LOOKUP($D10,Site_Meta!$C$2:$C$43,Site_Meta!H$2:H$43) -> 10 | J10: 11 | K10: 14 | L10: 24 | M10: =CONCATENATE(J10,"/",K10,"/",L10) -> 11/14/24 | N10: Anibal | O10: Manuel O | P10: Victoria | Q10: NA | R10: 0.47361111 | S10: 0.47916667 | T10: 29.58 | U10: 0.55 | V10: 33.93 | W10: 0.57 | X10: 5.79 | Y10: 0.56 | Z10: 8.1 | AA10: 0.58 | AB10: 29.35 | AC10: 8.87 | AD10: 34.05 | AE10: 4.38 | AF10: 5.71 | AG10: 9.43 | AH10: 8.1 | AI10: 9.32 | AJ10: 10 | AK10: 10 | AL10: 10 | AM10: 10 | AN10: 0.5 | AO10: 18 | AP10: 27 | AQ10: 28 | AR10: 29 | AS10: 30 | AT10: 31 | AU10: 32 | AV10: 33 | AW10: 34 | AX10: 35 | AY10: 36 | AZ10: 37
A11: 7 | B11: =LOOKUP($D11,Site_Meta!$C$2:$C$43,Site_Meta!A$2:A$43) -> Dakiti 20m | C11: =LOOKUP($D11,Site_Meta!$C$2:$C$43,Site_Meta!B$2:B$43) -> Isla Culebra | D11: DAKI20 | E11: =LOOKUP($D11,Site_Meta!$C$2:$C$43,Site_Meta!D$2:D$43) -> Vieques/Culebra | F11: =LOOKUP($D11,Site_Meta!$C$2:$C$43,Site_Meta!E$2:E$43) -> E | G11: =LOOKUP($D11,Site_Meta!$C$2:$C$43,Site_Meta!F$2:F$43) -> 18.27587 | H11: =LOOKUP($D11,Site_Meta!$C$2:$C$43,Site_Meta!G$2:G$43) -> -65.2773 | I11: =LOOKUP($D11,Site_Meta!$C$2:$C$43,Site_Meta!H$2:H$43) -> 20 | J11: 11 | K11: 20 | L11: 24 | M11: =CONCATENATE(J11,"/",K11,"/",L11) -> 11/20/24 | N11: Julio | O11: Manuel O | P11: Johan C | Q11: NA | R11: 0.30347222 | S11: 0.31944444 | T11: 29.19 | U11: 0.62 | V11: 35.74 | W11: 0.63 | X11: 6.01 | Y11: 0.59 | Z11: 8.07 | AA11: 0.58 | AB11: 29.19 | AC11: 18.09 | AD11: 35.76 | AE11: 17.6 | AF11: 5.82 | AG11: 18.21 | AH11: 8.1 | AI11: 18.14 | AJ11: 8.5 | AK11: 9 | AL11: 9 | AM11: =AVERAGE(AJ11,AK11,AL11) -> 8.8333333 | AN11: 0.5 | AO11: 18 | AP11: 209 | AQ11: 210 | AR11: 211 | AS11: 212 | AT11: 213 | AU11: 214 | AV11: 215 | AW11: 216 | AX11: 217 | AY11: 218 | AZ11: 219
A12: 7 | B12: =LOOKUP($D12,Site_Meta!$C$2:$C$43,Site_Meta!A$2:A$43) -> Canal Luis Pena 5m | C12: =LOOKUP($D12,Site_Meta!$C$2:$C$43,Site_Meta!B$2:B$43) -> Isla Culebra | D12: LPEN05 | E12: =LOOKUP($D12,Site_Meta!$C$2:$C$43,Site_Meta!D$2:D$43) -> Vieques/Culebra | F12: =LOOKUP($D12,Site_Meta!$C$2:$C$43,Site_Meta!E$2:E$43) -> E | G12: =LOOKUP($D12,Site_Meta!$C$2:$C$43,Site_Meta!F$2:F$43) -> 18.30493 | H12: =LOOKUP($D12,Site_Meta!$C$2:$C$43,Site_Meta!G$2:G$43) -> -65.3277 | I12: =LOOKUP($D12,Site_Meta!$C$2:$C$43,Site_Meta!H$2:H$43) -> 5 | J12: 11 | K12: 20 | L12: 24 | M12: =CONCATENATE(J12,"/",K12,"/",L12) -> 11/20/24 | N12: Julio | O12: Manuel O | P12: Johan C | Q12: NA | R12: 0.34027778 | S12: 0.35208333 | T12: 28.99 | U12: 0.61 | V12: 35.64 | W12: 0.62 | X12: 6.33 | Y12: 0.63 | Z12: 8.11 | AA12: 0.63 | AB12: 28.97 | AC12: 4.27 | AD12: 35.66 | AE12: 4.22 | AF12: 5.99 | AG12: 4.31 | AH12: 8.11 | AI12: 4.32 | AJ12: 10 | AK12: 10 | AL12: 10 | AM12: 10 | AN12: 0.5 | AO12: 9 | AP12: 144 | AQ12: 145 | AR12: 146 | AS12: 147 | AT12: 148 | AU12: 149 | AV12: 150 | AW12: 151 | AX12: 152 | AY12: 153 | AZ12: 154
A13: 7 | B13: =LOOKUP($D13,Site_Meta!$C$2:$C$43,Site_Meta!A$2:A$43) -> Carlos Rosario 10m | C13: =LOOKUP($D13,Site_Meta!$C$2:$C$43,Site_Meta!B$2:B$43) -> Isla Culebra | D13: CROS10 | E13: =LOOKUP($D13,Site_Meta!$C$2:$C$43,Site_Meta!D$2:D$43) -> Vieques/Culebra | F13: =LOOKUP($D13,Site_Meta!$C$2:$C$43,Site_Meta!E$2:E$43) -> E | G13: =LOOKUP($D13,Site_Meta!$C$2:$C$43,Site_Meta!F$2:F$43) -> 18.32779 | H13: =LOOKUP($D13,Site_Meta!$C$2:$C$43,Site_Meta!G$2:G$43) -> -65.332 | I13: =LOOKUP($D13,Site_Meta!$C$2:$C$43,Site_Meta!H$2:H$43) -> 10 | J13: 11 | K13: 20 | L13: 24 | M13: =CONCATENATE(J13,"/",K13,"/",L13) -> 11/20/24 | N13: Julio | O13: Manuel O | P13: Johan C | Q13: NA | R13: 0.36319444 | S13: 0.37569444 | T13: 29 | U13: 0.73 | V13: 35.58 | W13: 0.52 | X13: 6.42 | Y13: 0.56 | Z13: 8.12 | AA13: 0.83 | AB13: 29.01 | AC13: 8.61 | AD13: 35.66 | AE13: 8.6 | AF13: 6.06 | AG13: 8.67 | AH13: 8.11 | AI13: 8.44 | AJ13: 9 | AK13: 8.5 | AL13: 8.5 | AM13: =AVERAGE(AJ13,AK13,AL13) -> 8.6666667 | AN13: 0.5 | AO13: 9 | AP13: 248 | AQ13: 249 | AR13: 250 | AS13: 251 | AT13: 252 | AU13: 253 | AV13: 254 | AW13: 255 | AX13: 256 | AY13: 257 | AZ13: 258
A14: 7 | B14: =LOOKUP($D14,Site_Meta!$C$2:$C$43,Site_Meta!A$2:A$43) -> Cayo Diablo 5m | C14: =LOOKUP($D14,Site_Meta!$C$2:$C$43,Site_Meta!B$2:B$43) -> Fajardo | D14: DIAB05 | E14: =LOOKUP($D14,Site_Meta!$C$2:$C$43,Site_Meta!D$2:D$43) -> North/Northeast | F14: =LOOKUP($D14,Site_Meta!$C$2:$C$43,Site_Meta!E$2:E$43) -> E | G14: =LOOKUP($D14,Site_Meta!$C$2:$C$43,Site_Meta!F$2:F$43) -> 18.36033 | H14: =LOOKUP($D14,Site_Meta!$C$2:$C$43,Site_Meta!G$2:G$43) -> -65.5309 | I14: =LOOKUP($D14,Site_Meta!$C$2:$C$43,Site_Meta!H$2:H$43) -> 5 | J14: 11 | K14: 20 | L14: 24 | M14: =CONCATENATE(J14,"/",K14,"/",L14) -> 11/20/24 | N14: Julio | O14: Manuel O | P14: Johan C | Q14: NA | R14: 0.41319444 | S14: 0.42291667 | T14: 28.99 | U14: 0.52 | V14: 35.28 | W14: 0.59 | X14: 6.67 | Y14: 0.57 | Z14: 8.14 | AA14: 0.65 | AB14: 28.97 | AC14: 5.07 | AD14: 35.34 | AE14: 4.9 | AF14: 6.67 | AG14: 5.03 | AH14: 8.14 | AI14: 4.92 | AJ14: 5 | AK14: 5 | AL14: 5 | AM14: 5 | AN14: 0.5 | AO14: 5 | AP14: 196 | AQ14: 197 | AR14: 198 | AS14: 199 | AT14: 200 | AU14: 201 | AV14: 202 | AW14: 203 | AX14: 204 | AY14: 205 | AZ14: 206
A15: 7 | B15: =LOOKUP($D15,Site_Meta!$C$2:$C$43,Site_Meta!A$2:A$43) -> Palominos 20m | C15: =LOOKUP($D15,Site_Meta!$C$2:$C$43,Site_Meta!B$2:B$43) -> Fajardo | D15: PALN20 | E15: =LOOKUP($D15,Site_Meta!$C$2:$C$43,Site_Meta!D$2:D$43) -> North/Northeast | F15: =LOOKUP($D15,Site_Meta!$C$2:$C$43,Site_Meta!E$2:E$43) -> E | G15: =LOOKUP($D15,Site_Meta!$C$2:$C$43,Site_Meta!F$2:F$43) -> 18.35466 | H15: =LOOKUP($D15,Site_Meta!$C$2:$C$43,Site_Meta!G$2:G$43) -> -65.5671 | I15: =LOOKUP($D15,Site_Meta!$C$2:$C$43,Site_Meta!H$2:H$43) -> 20 | J15: 11 | K15: 20 | L15: 24 | M15: =CONCATENATE(J15,"/",K15,"/",L15) -> 11/20/24 | N15: Julio | O15: Manuel O | P15: Johan C | Q15: NA | R15: 0.43680556 | S15: 0.44930556 | T15: 28.98 | U15: 0.49 | V15: 35.3 | W15: 0.53 | X15: 6.35 | Y15: 0.51 | Z15: 8.14 | AA15: 0.53 | AB15: 28.88 | AC15: 17.33 | AD15: 35.31 | AE15: 17.48 | AF15: 6.05 | AG15: 17.17 | AH15: 8.13 | AI15: 17.58 | AJ15: 5.25 | AK15: 5.25 | AL15: 5.5 | AM15: =AVERAGE(AJ15,AK15,AL15) -> 5.3333333 | AN15: 0.5 | AO15: 16 | AP15: 261 | AQ15: 262 | AR15: 263 | AS15: 264 | AT15: 265 | AU15: 266 | AV15: 267 | AW15: 268 | AX15: 269 | AY15: 270 | AZ15: 271
A16: 7 | B16: =LOOKUP($D16,Site_Meta!$C$2:$C$43,Site_Meta!A$2:A$43) -> Cabezas de San Juan 5m | C16: =LOOKUP($D16,Site_Meta!$C$2:$C$43,Site_Meta!B$2:B$43) -> Fajardo | D16: CABE05 | E16: =LOOKUP($D16,Site_Meta!$C$2:$C$43,Site_Meta!D$2:D$43) -> North/Northeast | F16: =LOOKUP($D16,Site_Meta!$C$2:$C$43,Site_Meta!E$2:E$43) -> E | G16: =LOOKUP($D16,Site_Meta!$C$2:$C$43,Site_Meta!F$2:F$43) -> 18.38544 | H16: =LOOKUP($D16,Site_Meta!$C$2:$C$43,Site_Meta!G$2:G$43) -> -65.6297 | I16: =LOOKUP($D16,Site_Meta!$C$2:$C$43,Site_Meta!H$2:H$43) -> 5 | J16: 11 | K16: 20 | L16: 24 | M16: =CONCATENATE(J16,"/",K16,"/",L16) -> 11/20/24 | N16: Julio | O16: Manuel O | P16: Johan C | Q16: NA | R16: 0.47222222 | S16: 0.48263889 | T16: 29.12 | U16: 0.55 | V16: 35.32 | W16: 0.46 | X16: 6.21 | Y16: 0.47 | Z16: 8.12 | AA16: 0.44 | AB16: 28.89 | AC16: 4.23 | AD16: 35.32 | AE16: 4.34 | AF16: 6.12 | AG16: 4.14 | AH16: 8.12 | AI16: 4.37 | AJ16: 3.25 | AK16: 3.25 | AL16: 3.25 | AM16: 3.25 | AN16: 0.5 | AO16: 4 | AP16: 183 | AQ16: 184 | AR16: 185 | AS16: 186 | AT16: 187 | AU16: 188 | AV16: 189 | AW16: 190 | AX16: 191 | AY16: 192 | AZ16: 193
A17: 7 | B17: =LOOKUP($D17,Site_Meta!$C$2:$C$43,Site_Meta!A$2:A$43) -> El Seco 30m | C17: =LOOKUP($D17,Site_Meta!$C$2:$C$43,Site_Meta!B$2:B$43) -> Isla Vieques | D17: SECO30 | E17: =LOOKUP($D17,Site_Meta!$C$2:$C$43,Site_Meta!D$2:D$43) -> Vieques/Culebra | F17: =LOOKUP($D17,Site_Meta!$C$2:$C$43,Site_Meta!E$2:E$43) -> E | G17: =LOOKUP($D17,Site_Meta!$C$2:$C$43,Site_Meta!F$2:F$43) -> 18.13869 | H17: =LOOKUP($D17,Site_Meta!$C$2:$C$43,Site_Meta!G$2:G$43) -> -65.1971 | I17: =LOOKUP($D17,Site_Meta!$C$2:$C$43,Site_Meta!H$2:H$43) -> 30 | J17: 11 | K17: 19 | L17: 24 | M17: =CONCATENATE(J17,"/",K17,"/",L17) -> 11/19/24 | N17: Julio | O17: Manuel O | P17: Johan C | Q17: NA | R17: 0.38888889 | S17: 0.40625 | T17: 29.06 | U17: 0.44 | V17: 35.56 | W17: 0.5 | X17: 6.23 | Y17: 0.76 | Z17: 8.1 | AA17: 0.54 | AB17: 29.2 | AC17: 25.54 | AD17: 35.87 | AE17: 25.54 | AF17: 5.68 | AG17: 27.04 | AH17: 8.1 | AI17: 27.04 | AJ17: 10.5 | AK17: 13 | AL17: 13 | AM17: =AVERAGE(AJ17,AK17,AL17) -> 12.166667 | AN17: 0.5 | AO17: 10 | AP17: 157 | AQ17: 158 | AR17: 159 | AS17: 160 | AT17: 161 | AU17: 162 | AV17: 163 | AW17: 164 | AX17: 165 | AY17: 166 | AZ17: 167
A18: 7 | B18: =LOOKUP($D18,Site_Meta!$C$2:$C$43,Site_Meta!A$2:A$43) -> Esperanza 10m | C18: =LOOKUP($D18,Site_Meta!$C$2:$C$43,Site_Meta!B$2:B$43) -> Isla Vieques | D18: ESPE10 | E18: =LOOKUP($D18,Site_Meta!$C$2:$C$43,Site_Meta!D$2:D$43) -> Vieques/Culebra | F18: =LOOKUP($D18,Site_Meta!$C$2:$C$43,Site_Meta!E$2:E$43) -> E | G18: =LOOKUP($D18,Site_Meta!$C$2:$C$43,Site_Meta!F$2:F$43) -> 18.08057 | H18: =LOOKUP($D18,Site_Meta!$C$2:$C$43,Site_Meta!G$2:G$43) -> -65.4879 | I18: =LOOKUP($D18,Site_Meta!$C$2:$C$43,Site_Meta!H$2:H$43) -> 10 | J18: 11 | K18: 19 | L18: 24 | M18: =CONCATENATE(J18,"/",K18,"/",L18) -> 11/19/24 | N18: Julio | O18: Manuel O | P18: Johan C | Q18: NA | R18: 0.45694444 | S18: 0.47222222 | T18: 29.23 | U18: 0.84 | V18: 35.56 | W18: 0.72 | X18: 6.14 | Y18: 0.58 | Z18: 8.13 | AA18: 0.69 | AB18: 29.1 | AC18: 9.41 | AD18: 35.55 | AE18: 9.37 | AF18: 6.05 | AG18: 9.23 | AH18: 8.13 | AI18: 9.23 | AJ18: 10 | AK18: 10 | AL18: 10 | AM18: 10 | AN18: 0.5 | AO18: 9 | AP18: 170 | AQ18: 171 | AR18: 172 | AS18: 173 | AT18: 174 | AU18: 175 | AV18: 176 | AW18: 177 | AX18: 178 | AY18: 179 | AZ18: 180
A19: 7 | B19: =LOOKUP($D19,Site_Meta!$C$2:$C$43,Site_Meta!A$2:A$43) -> Canjilones 15m | C19: =LOOKUP($D19,Site_Meta!$C$2:$C$43,Site_Meta!B$2:B$43) -> Isla Vieques | D19: CANJ15 | E19: =LOOKUP($D19,Site_Meta!$C$2:$C$43,Site_Meta!D$2:D$43) -> Vieques/Culebra | F19: =LOOKUP($D19,Site_Meta!$C$2:$C$43,Site_Meta!E$2:E$43) -> E | G19: =LOOKUP($D19,Site_Meta!$C$2:$C$43,Site_Meta!F$2:F$43) -> 18.08964 | H19: =LOOKUP($D19,Site_Meta!$C$2:$C$43,Site_Meta!G$2:G$43) -> -65.5901 | I19: =LOOKUP($D19,Site_Meta!$C$2:$C$43,Site_Meta!H$2:H$43) -> 15 | J19: 11 | K19: 19 | L19: 24 | M19: =CONCATENATE(J19,"/",K19,"/",L19) -> 11/19/24 | N19: Julio | O19: Manuel O | P19: Johan C | Q19: NA | R19: 0.49305556 | S19: 0.50763889 | T19: 29.29 | U19: 0.81 | V19: 35.42 | W19: 0.9 | X19: 6.15 | Y19: 0.89 | Z19: 8.14 | AA19: 0.71 | AB19: 29.24 | AC19: 13.49 | AD19: 35.55 | AE19: 13.52 | AF19: 6.16 | AG19: 13.5 | AH19: 8.14 | AI19: 13.22 | AJ19: 15 | AK19: 15 | AL19: 15 | AM19: 15 | AN19: 0.5 | AO19: 13 | AP19: 118 | AQ19: 119 | AR19: 120 | AS19: 121 | AT19: 122 | AU19: 123 | AV19: 124 | AW19: 125 | AX19: 126 | AY19: 127 | AZ19: 128
A20: 7 | B20: =LOOKUP($D20,Site_Meta!$C$2:$C$43,Site_Meta!A$2:A$43) -> Palominitos 10m | C20: =LOOKUP($D20,Site_Meta!$C$2:$C$43,Site_Meta!B$2:B$43) -> Fajardo | D20: PALT10 | E20: =LOOKUP($D20,Site_Meta!$C$2:$C$43,Site_Meta!D$2:D$43) -> North/Northeast | F20: =LOOKUP($D20,Site_Meta!$C$2:$C$43,Site_Meta!E$2:E$43) -> E | G20: =LOOKUP($D20,Site_Meta!$C$2:$C$43,Site_Meta!F$2:F$43) -> 18.33537 | H20: =LOOKUP($D20,Site_Meta!$C$2:$C$43,Site_Meta!G$2:G$43) -> -65.5656 | I20: =LOOKUP($D20,Site_Meta!$C$2:$C$43,Site_Meta!H$2:H$43) -> 10 | J20: 11 | K20: 19 | L20: 24 | M20: =CONCATENATE(J20,"/",K20,"/",L20) -> 11/19/24 | N20: Julio | O20: Manuel O | P20: Johan C | Q20: NA | R20: 0.55138889 | S20: 0.56736111 | T20: 29.16 | U20: 0.54 | V20: 35.26 | W20: 0.52 | X20: 6.35 | Y20: 0.5 | Z20: 8.15 | AA20: 0.56 | AB20: 29.04 | AC20: 8.78 | AD20: 35.39 | AE20: 8.92 | AF20: 6.45 | AG20: 7.81 | AH20: 8.15 | AI20: 7.84 | AJ20: 5.25 | AK20: 5.25 | AL20: 5.25 | AM20: 5.25 | AN20: 0.5 | AO20: 8 | AP20: 131 | AQ20: 132 | AR20: 133 | AS20: 134 | AT20: 135 | AU20: 136 | AV20: 137 | AW20: 138 | AX20: 139 | AY20: 140 | AZ20: 141
A21: 7 | B21: =LOOKUP($D21,Site_Meta!$C$2:$C$43,Site_Meta!A$2:A$43) -> Cayo Rodriguez 5m | C21: =LOOKUP($D21,Site_Meta!$C$2:$C$43,Site_Meta!B$2:B$43) -> Mayaguez | D21: RODR05 | E21: =LOOKUP($D21,Site_Meta!$C$2:$C$43,Site_Meta!D$2:D$43) -> West | F21: =LOOKUP($D21,Site_Meta!$C$2:$C$43,Site_Meta!E$2:E$43) -> W | G21: =LOOKUP($D21,Site_Meta!$C$2:$C$43,Site_Meta!F$2:F$43) -> 18.1893 | H21: =LOOKUP($D21,Site_Meta!$C$2:$C$43,Site_Meta!G$2:G$43) -> -67.1919 | I21: =LOOKUP($D21,Site_Meta!$C$2:$C$43,Site_Meta!H$2:H$43) -> 5 | J21: 12 | K21: 3 | L21: 24 | M21: =CONCATENATE(J21,"/",K21,"/",L21) -> 12/3/24 | N21: Espinoza | O21: Manuel O | P21: Victoria | Q21: NA | R21: 0.375 | S21: 0.38055556 | T21: 29.19 | U21: 0.65 | V21: 34.76 | W21: 0.61 | X21: 6.08 | Y21: 0.61 | Z21: 8.09 | AA21: 0.62 | AB21: 29.33 | AC21: 4.7 | AD21: 34.87 | AE21: 4.73 | AF21: 6.06 | AG21: 4.95 | AH21: 8.11 | AI21: 5.59 | AJ21: 5 | AK21: 5 | AL21: 6 | AM21: =AVERAGE(AJ21:AL21) -> 5.3333333 | AN21: 0.5 | AO21: 5 | AP21: 326 | AQ21: 327 | AR21: 328 | AS21: 329 | AT21: 330 | AU21: 331 | AV21: 332 | AW21: 333 | AX21: 334 | AY21: 335 | AZ21: 336
A22: 7 | B22: =LOOKUP($D22,Site_Meta!$C$2:$C$43,Site_Meta!A$2:A$43) -> Guanajibo 20m | C22: =LOOKUP($D22,Site_Meta!$C$2:$C$43,Site_Meta!B$2:B$43) -> Mayaguez | D22: GUAN20 | E22: =LOOKUP($D22,Site_Meta!$C$2:$C$43,Site_Meta!D$2:D$43) -> West | F22: =LOOKUP($D22,Site_Meta!$C$2:$C$43,Site_Meta!E$2:E$43) -> W | G22: =LOOKUP($D22,Site_Meta!$C$2:$C$43,Site_Meta!F$2:F$43) -> 18.17202 | H22: =LOOKUP($D22,Site_Meta!$C$2:$C$43,Site_Meta!G$2:G$43) -> -67.253 | I22: =LOOKUP($D22,Site_Meta!$C$2:$C$43,Site_Meta!H$2:H$43) -> 20 | J22: 12 | K22: 3 | L22: 24 | M22: =CONCATENATE(J22,"/",K22,"/",L22) -> 12/3/24 | N22: Espinoza | O22: Manuel O | P22: Victoria | Q22: NA | R22: 0.40486111 | S22: 0.41666667 | T22: 29.45 | U22: 0.59 | V22: 35.03 | W22: 0.62 | X22: 6.52 | Y22: 0.65 | Z22: 8.17 | AA22: 0.64 | AB22: 29.36 | AC22: 9.85 | AD22: 35.21 | AE22: 9.89 | AF22: 6.01 | AG22: 9.96 | AH22: 8.15 | AI22: 9.96 | AJ22: >20 | AK22: >20 | AL22: >20 | AM22: >20 | AN22: 0.5 | AO22: 14 | AP22: 469 | AQ22: 470 | AR22: 471 | AS22: 472 | AT22: 473 | AU22: 474 | AV22: 475 | AW22: 476 | AX22: 477 | AY22: 478 | AZ22: 479
A23: 7 | B23: =LOOKUP($D23,Site_Meta!$C$2:$C$43,Site_Meta!A$2:A$43) -> Tourmaline 30m | C23: =LOOKUP($D23,Site_Meta!$C$2:$C$43,Site_Meta!B$2:B$43) -> Cabo Rojo | D23: TOUR30 | E23: =LOOKUP($D23,Site_Meta!$C$2:$C$43,Site_Meta!D$2:D$43) -> West | F23: =LOOKUP($D23,Site_Meta!$C$2:$C$43,Site_Meta!E$2:E$43) -> W | G23: =LOOKUP($D23,Site_Meta!$C$2:$C$43,Site_Meta!F$2:F$43) -> 18.16637 | H23: =LOOKUP($D23,Site_Meta!$C$2:$C$43,Site_Meta!G$2:G$43) -> -67.2763 | I23: =LOOKUP($D23,Site_Meta!$C$2:$C$43,Site_Meta!H$2:H$43) -> 30 | J23: 12 | K23: 3 | L23: 24 | M23: =CONCATENATE(J23,"/",K23,"/",L23) -> 12/3/24 | N23: Espinoza | O23: Manuel O | P23: Victoria | Q23: NA | R23: 0.43125 | S23: 0.44722222 | T23: 29.48 | U23: 0.53 | V23: 35.05 | W23: 0.73 | X23: 6.35 | Y23: 0.71 | Z23: 8.16 | AA23: 0.68 | AB23: 29.37 | AC23: 24.03 | AD23: 35.31 | AE23: 24.09 | AF23: 6.22 | AG23: 24.08 | AH23: 8.16 | AI23: 24.08 | AJ23: 22 | AK23: 23.5 | AL23: 23 | AM23: =AVERAGE(AJ23:AL23) -> 22.833333 | AN23: 0.5 | AO23: 25 | AP23: 378 | AQ23: 379 | AR23: 380 | AS23: 381 | AT23: 382 | AU23: 383 | AV23: 384 | AW23: 385 | AX23: 386 | AY23: 387 | AZ23: 388
A24: 7 | B24: =LOOKUP($D24,Site_Meta!$C$2:$C$43,Site_Meta!A$2:A$43) -> Tourmaline 20m | C24: =LOOKUP($D24,Site_Meta!$C$2:$C$43,Site_Meta!B$2:B$43) -> Cabo Rojo | D24: TOUR20 | E24: =LOOKUP($D24,Site_Meta!$C$2:$C$43,Site_Meta!D$2:D$43) -> West | F24: =LOOKUP($D24,Site_Meta!$C$2:$C$43,Site_Meta!E$2:E$43) -> W | G24: =LOOKUP($D24,Site_Meta!$C$2:$C$43,Site_Meta!F$2:F$43) -> 18.16517 | H24: =LOOKUP($D24,Site_Meta!$C$2:$C$43,Site_Meta!G$2:G$43) -> -67.2752 | I24: =LOOKUP($D24,Site_Meta!$C$2:$C$43,Site_Meta!H$2:H$43) -> 20 | J24: 12 | K24: 3 | L24: 24 | M24: =CONCATENATE(J24,"/",K24,"/",L24) -> 12/3/24 | N24: Espinoza | O24: Manuel O | P24: Victoria | Q24: NA | R24: 0.45277778 | S24: 0.4625 | T24: 29.53 | U24: 0.66 | V24: 35.14 | W24: 0.7 | X24: 6.31 | Y24: 0.66 | Z24: 8.16 | AA24: 0.67 | AB24: 29.4 | AC24: 8.72 | AD24: 35.16 | AE24: 8.92 | AF24: 6.29 | AG24: 8.92 | AH24: 8.16 | AI24: 9.6 | AJ24: >20 | AK24: >11 | AL24: >11 | AM24: >20 | AN24: 0.5 | AO24: 11 | AP24: 287 | AQ24: 288 | AR24: 289 | AS24: 290 | AT24: 291 | AU24: 292 | AV24: 293 | AW24: 294 | AX24: 295 | AY24: 296 | AZ24: 297
A25: 7 | B25: =LOOKUP($D25,Site_Meta!$C$2:$C$43,Site_Meta!A$2:A$43) -> Tourmaline 10m | C25: =LOOKUP($D25,Site_Meta!$C$2:$C$43,Site_Meta!B$2:B$43) -> Cabo Rojo | D25: TOUR10 | E25: =LOOKUP($D25,Site_Meta!$C$2:$C$43,Site_Meta!D$2:D$43) -> West | F25: =LOOKUP($D25,Site_Meta!$C$2:$C$43,Site_Meta!E$2:E$43) -> W | G25: =LOOKUP($D25,Site_Meta!$C$2:$C$43,Site_Meta!F$2:F$43) -> 18.16304 | H25: =LOOKUP($D25,Site_Meta!$C$2:$C$43,Site_Meta!G$2:G$43) -> -67.2737 | I25: =LOOKUP($D25,Site_Meta!$C$2:$C$43,Site_Meta!H$2:H$43) -> 10 | J25: 12 | K25: 3 | L25: 24 | M25: =CONCATENATE(J25,"/",K25,"/",L25) -> 12/3/24 | N25: Espinoza | O25: Manuel O | P25: Victoria | Q25: NA | R25: 0.46944444 | S25: 0.47777778 | T25: 29.46 | U25: 0.66 | V25: 35.07 | W25: 0.65 | X25: 6.31 | Y25: 0.65 | Z25: 8.16 | AA25: 0.64 | AB25: 29.39 | AC25: 7.88 | AD25: 35.24 | AE25: 7.87 | AF25: 6.28 | AG25: 7.79 | AH25: 8.16 | AI25: 7.59 | AJ25: >10 | AK25: >10 | AL25: >10 | AM25: >10 | AN25: 0.5 | AO25: 8 | AP25: 313 | AQ25: 314 | AR25: 315 | AS25: 316 | AT25: 317 | AU25: 318 | AV25: 319 | AW25: 320 | AX25: 321 | AY25: 322 | AZ25: 323
A26: 7 | B26: =LOOKUP($D26,Site_Meta!$C$2:$C$43,Site_Meta!A$2:A$43) -> El Negro 10m | C26: =LOOKUP($D26,Site_Meta!$C$2:$C$43,Site_Meta!B$2:B$43) -> Cabo Rojo | D26: NEGR10 | E26: =LOOKUP($D26,Site_Meta!$C$2:$C$43,Site_Meta!D$2:D$43) -> West | F26: =LOOKUP($D26,Site_Meta!$C$2:$C$43,Site_Meta!E$2:E$43) -> W | G26: =LOOKUP($D26,Site_Meta!$C$2:$C$43,Site_Meta!F$2:F$43) -> 18.14653 | H26: =LOOKUP($D26,Site_Meta!$C$2:$C$43,Site_Meta!G$2:G$43) -> -67.248 | I26: =LOOKUP($D26,Site_Meta!$C$2:$C$43,Site_Meta!H$2:H$43) -> 10 | J26: 12 | K26: 3 | L26: 24 | M26: =CONCATENATE(J26,"/",K26,"/",L26) -> 12/3/24 | N26: Espinoza | O26: Manuel O | P26: Victoria | Q26: NA | R26: 0.49652778 | S26: 0.51041667 | T26: 29.56 | U26: 0.78 | V26: 35.02 | W26: 0.77 | X26: 6.11 | Y26: 0.77 | Z26: 8.15 | AA26: 0.77 | AB26: 29.5 | AC26: 7.74 | AD26: 35.1 | AE26: 7.74 | AF26: 6.2 | AG26: 7.74 | AH26: 8.16 | AI26: 8.08 | AJ26: >10 | AK26: >10 | AL26: >10 | AM26: >10 | AN26: 0.5 | AO26: 8 | AP26: 300 | AQ26: 301 | AR26: 302 | AS26: 303 | AT26: 304 | AU26: 305 | AV26: 306 | AW26: 307 | AX26: 308 | AY26: 309 | AZ26: 310
A27: 7 | B27: =LOOKUP($D27,Site_Meta!$C$2:$C$43,Site_Meta!A$2:A$43) -> El Negro 5m | C27: =LOOKUP($D27,Site_Meta!$C$2:$C$43,Site_Meta!B$2:B$43) -> Cabo Rojo | D27: NEGR05 | E27: =LOOKUP($D27,Site_Meta!$C$2:$C$43,Site_Meta!D$2:D$43) -> West | F27: =LOOKUP($D27,Site_Meta!$C$2:$C$43,Site_Meta!E$2:E$43) -> W | G27: =LOOKUP($D27,Site_Meta!$C$2:$C$43,Site_Meta!F$2:F$43) -> 18.14658 | H27: =LOOKUP($D27,Site_Meta!$C$2:$C$43,Site_Meta!G$2:G$43) -> -67.2476 | I27: =LOOKUP($D27,Site_Meta!$C$2:$C$43,Site_Meta!H$2:H$43) -> 5 | J27: 12 | K27: 3 | L27: 24 | M27: =CONCATENATE(J27,"/",K27,"/",L27) -> 12/3/24 | N27: Espinoza | O27: Manuel O | P27: Victoria | Q27: NA | R27: 0.51805556 | S27: 0.52986111 | T27: 29.57 | U27: 0.57 | V27: 35.08 | W27: 0.62 | X27: 6.16 | Y27: 0.62 | Z27: 8.16 | AA27: 0.68 | AB27: 29.51 | AC27: 4.41 | AD27: 35.13 | AE27: 4.41 | AF27: 6.29 | AG27: 4.39 | AH27: 8.16 | AI27: 4.39 | AJ27: >5 | AK27: >5 | AL27: >5 | AM27: >5 | AN27: 0.5 | AO27: 3 | AP27: 274 | AQ27: 274 | AR27: 276 | AS27: 277 | AT27: 278 | AU27: 279 | AV27: 280 | AW27: 281 | AX27: 282 | AY27: 283 | AZ27: 284
A28: 7 | B28: =LOOKUP($D28,Site_Meta!$C$2:$C$43,Site_Meta!A$2:A$43) -> Gallardo 5m | C28: =LOOKUP($D28,Site_Meta!$C$2:$C$43,Site_Meta!B$2:B$43) -> Cabo Rojo | D28: GALL05 | E28: =LOOKUP($D28,Site_Meta!$C$2:$C$43,Site_Meta!D$2:D$43) -> West | F28: =LOOKUP($D28,Site_Meta!$C$2:$C$43,Site_Meta!E$2:E$43) -> W | G28: =LOOKUP($D28,Site_Meta!$C$2:$C$43,Site_Meta!F$2:F$43) -> 18.0017 | H28: =LOOKUP($D28,Site_Meta!$C$2:$C$43,Site_Meta!G$2:G$43) -> -67.3299 | I28: =LOOKUP($D28,Site_Meta!$C$2:$C$43,Site_Meta!H$2:H$43) -> 5 | J28: 12 | K28: 3 | L28: 24 | M28: =CONCATENATE(J28,"/",K28,"/",L28) -> 12/3/24 | N28: Espinoza | O28: Manuel O | P28: Victoria | Q28: NA | R28: 0.56111111 | S28: 0.57152778 | T28: 28.91 | U28: 0.72 | V28: 34.56 | W28: 0.82 | X28: 6.16 | Y28: 0.74 | Z28: 8.12 | AA28: 0.69 | AB28: 28.92 | AC28: 2.66 | AD28: 34.57 | AE28: 2.78 | AF28: 6.08 | AG28: 2.76 | AH28: 8.11 | AI28: 2.84 | AJ28: >5 | AK28: >5 | AL28: >5 | AM28: >5 | AN28: 0.5 | AO28: 3 | AP28: 456 | AQ28: 457 | AR28: 458 | AS28: 459 | AT28: 460 | AU28: 461 | AV28: 462 | AW28: 463 | AX28: 464 | AY28: 465 | AZ28: 466
A29: 7 | B29: =LOOKUP($D29,Site_Meta!$C$2:$C$43,Site_Meta!A$2:A$43) -> Resuellos 10m | C29: =LOOKUP($D29,Site_Meta!$C$2:$C$43,Site_Meta!B$2:B$43) -> Cabo Rojo | D29: RESU10 | E29: =LOOKUP($D29,Site_Meta!$C$2:$C$43,Site_Meta!D$2:D$43) -> West | F29: =LOOKUP($D29,Site_Meta!$C$2:$C$43,Site_Meta!E$2:E$43) -> W | G29: =LOOKUP($D29,Site_Meta!$C$2:$C$43,Site_Meta!F$2:F$43) -> 17.99116 | H29: =LOOKUP($D29,Site_Meta!$C$2:$C$43,Site_Meta!G$2:G$43) -> -67.2332 | I29: =LOOKUP($D29,Site_Meta!$C$2:$C$43,Site_Meta!H$2:H$43) -> 10 | J29: 12 | K29: 3 | L29: 24 | M29: =CONCATENATE(J29,"/",K29,"/",L29) -> 12/3/24 | N29: Espinoza | O29: Manuel O | P29: Victoria | Q29: NA | R29: 0.60902778 | S29: 0.62430556 | T29: 28.95 | U29: 0.4 | V29: 34.64 | W29: 0.45 | X29: 6.44 | Y29: 0.44 | Z29: 8.12 | AA29: 0.39 | AB29: 28.97 | AC29: 7.09 | AD29: 34.73 | AE29: 7.48 | AF29: 6.41 | AG29: 7.11 | AH29: 8.11 | AI29: 7.11 | AJ29: 3 | AK29: 3 | AL29: 4 | AM29: =AVERAGE(AJ29,AK29,AL29) -> 3.3333333 | AN29: 0.5 | AO29: 4 | AP29: 391 | AQ29: 392 | AR29: 393 | AS29: 394 | AT29: 395 | AU29: 396 | AV29: 397 | AW29: 398 | AX29: 399 | AY29: 400 | AZ29: 401
A30: 7 | B30: =LOOKUP($D30,Site_Meta!$C$2:$C$43,Site_Meta!A$2:A$43) -> Puerto Botes 15m | C30: =LOOKUP($D30,Site_Meta!$C$2:$C$43,Site_Meta!B$2:B$43) -> Isla Desecheo | D30: BOTE15 | E30: =LOOKUP($D30,Site_Meta!$C$2:$C$43,Site_Meta!D$2:D$43) -> Mona/Desecheo | F30: =LOOKUP($D30,Site_Meta!$C$2:$C$43,Site_Meta!E$2:E$43) -> W | G30: =LOOKUP($D30,Site_Meta!$C$2:$C$43,Site_Meta!F$2:F$43) -> 18.382 | H30: =LOOKUP($D30,Site_Meta!$C$2:$C$43,Site_Meta!G$2:G$43) -> -67.4883 | I30: =LOOKUP($D30,Site_Meta!$C$2:$C$43,Site_Meta!H$2:H$43) -> 15 | J30: 1 | K30: 9 | L30: 25 | M30: =CONCATENATE(J30,"/",K30,"/",L30) -> 1/9/25 | N30: Miguel F | O30: JJ | P30: Victoria | Q30: Aliyah | R30: 0.34513889 | S30: 0.36736111 | T30: 28.03 | U30: 0.69 | V30: 35.42 | W30: 0.71 | X30: 6.49 | Y30: 0.76 | Z30: 8.1 | AA30: 0.79 | AB30: 28.07 | AC30: 15.03 | AD30: 35.68 | AE30: 44.72 | AF30: 6.16 | AG30: 14.88 | AH30: 8.13 | AI30: 14.96 | AJ30: >15 | AK30: >15 | AL30: >15 | AM30: >15 | AN30: 0.5 | AO30: 13 | AP30: 352 | AQ30: 353 | AR30: 354 | AS30: 355 | AT30: 356 | AU30: 357 | AV30: 358 | AW30: 359 | AX30: 360 | AY30: 361 | AZ30: 362
A31: 7 | B31: =LOOKUP($D31,Site_Meta!$C$2:$C$43,Site_Meta!A$2:A$43) -> Puerto Botes 20m | C31: =LOOKUP($D31,Site_Meta!$C$2:$C$43,Site_Meta!B$2:B$43) -> Isla Desecheo | D31: BOTE20 | E31: =LOOKUP($D31,Site_Meta!$C$2:$C$43,Site_Meta!D$2:D$43) -> Mona/Desecheo | F31: =LOOKUP($D31,Site_Meta!$C$2:$C$43,Site_Meta!E$2:E$43) -> W | G31: =LOOKUP($D31,Site_Meta!$C$2:$C$43,Site_Meta!F$2:F$43) -> 18.38158 | H31: =LOOKUP($D31,Site_Meta!$C$2:$C$43,Site_Meta!G$2:G$43) -> -67.4886 | I31: =LOOKUP($D31,Site_Meta!$C$2:$C$43,Site_Meta!H$2:H$43) -> 20 | J31: 1 | K31: 9 | L31: 25 | M31: =CONCATENATE(J31,"/",K31,"/",L31) -> 1/9/25 | N31: Miguel F | O31: JJ | P31: Victoria | Q31: Aliyah | R31: 0.375 | S31: 0.38888889 | T31: 28.03 | U31: 0.59 | V31: 35.52 | W31: 0.51 | X31: 6.53 | Y31: 0.59 | Z31: 8.15 | AA31: 0.62 | AB31: 28.09 | AC31: 15.32 | AD31: 35.68 | AE31: 15.33 | AF31: 6.4 | AG31: 15.22 | AH31: 8.16 | AI31: 15.14 | AJ31: >15 | AK31: >15 | AL31: >15 | AM31: >15 | AN31: 0.5 | AO31: 18 | AP31: 534 | AQ31: 535 | AR31: 536 | AS31: 537 | AT31: 538 | AU31: 539 | AV31: 540 | AW31: 541 | AX31: 542 | AY31: 543 | AZ31: 544
A32: 7 | B32: =LOOKUP($D32,Site_Meta!$C$2:$C$43,Site_Meta!A$2:A$43) -> Puerto Canoas 30m | C32: =LOOKUP($D32,Site_Meta!$C$2:$C$43,Site_Meta!B$2:B$43) -> Isla Desecheo | D32: CANO30 | E32: =LOOKUP($D32,Site_Meta!$C$2:$C$43,Site_Meta!D$2:D$43) -> Mona/Desecheo | F32: =LOOKUP($D32,Site_Meta!$C$2:$C$43,Site_Meta!E$2:E$43) -> W | G32: =LOOKUP($D32,Site_Meta!$C$2:$C$43,Site_Meta!F$2:F$43) -> 18.37747 | H32: =LOOKUP($D32,Site_Meta!$C$2:$C$43,Site_Meta!G$2:G$43) -> -67.484 | I32: =LOOKUP($D32,Site_Meta!$C$2:$C$43,Site_Meta!H$2:H$43) -> 30 | J32: 1 | K32: 9 | L32: 25 | M32: =CONCATENATE(J32,"/",K32,"/",L32) -> 1/9/25 | N32: Miguel F | O32: JJ | P32: Victoria | Q32: Aliyah | R32: 0.39166667 | S32: 0.40416667 | T32: 28.07 | U32: 0.64 | V32: 35.68 | W32: 0.58 | X32: 6.43 | Y32: 0.66 | Z32: 8.16 | AA32: 0.66 | AB32: 28.09 | AC32: 26.56 | AD32: 35.6 | AE32: 25.5 | AF32: 6.37 | AG32: 26.99 | AH32: 8.16 | AI32: 26.99 | AJ32: >25 | AK32: >25 | AL32: >25 | AM32: >25 | AN32: 0.5 | AO32: 28 | AP32: 443 | AQ32: 444 | AR32: 445 | AS32: 446 | AT32: 447 | AU32: 448 | AV32: 449 | AW32: 450 | AX32: 451 | AY32: 452 | AZ32: 453
A33: 7 | B33: =LOOKUP($D33,Site_Meta!$C$2:$C$43,Site_Meta!A$2:A$43) -> Tres Palmas 20m | C33: =LOOKUP($D33,Site_Meta!$C$2:$C$43,Site_Meta!B$2:B$43) -> Rincon | D33: TRES20 | E33: =LOOKUP($D33,Site_Meta!$C$2:$C$43,Site_Meta!D$2:D$43) -> West | F33: =LOOKUP($D33,Site_Meta!$C$2:$C$43,Site_Meta!E$2:E$43) -> W | G33: =LOOKUP($D33,Site_Meta!$C$2:$C$43,Site_Meta!F$2:F$43) -> 18.34652 | H33: =LOOKUP($D33,Site_Meta!$C$2:$C$43,Site_Meta!G$2:G$43) -> -67.2712 | I33: =LOOKUP($D33,Site_Meta!$C$2:$C$43,Site_Meta!H$2:H$43) -> 20 | J33: 1 | K33: 9 | L33: 25 | M33: =CONCATENATE(J33,"/",K33,"/",L33) -> 1/9/25 | N33: Miguel F | O33: JJ | P33: Victoria | Q33: Aliyah | R33: 0.42986111 | S33: 0.44652778 | T33: 27.99 | U33: 0.59 | V33: 35.66 | W33: 0.55 | X33: 6.56 | Y33: 0.53 | Z33: 8.17 | AA33: 0.56 | AB33: 27.94 | AC33: 17.48 | AD33: 35.66 | AE33: 17.42 | AF33: 6.16 | AG33: 17.32 | AH33: 8.15 | AI33: 17.38 | AJ33: >16 | AK33: >16 | AL33: >16 | AM33: >16 | AN33: 0.5 | AO33: 18 | AP33: 521 | AQ33: 522 | AR33: 523 | AS33: 524 | AT33: 525 | AU33: 526 | AV33: 527 | AW33: 528 | AX33: 529 | AY33: 530 | AZ33: 531
A34: 7 | B34: =LOOKUP($D34,Site_Meta!$C$2:$C$43,Site_Meta!A$2:A$43) -> Tres Palmas 10m | C34: =LOOKUP($D34,Site_Meta!$C$2:$C$43,Site_Meta!B$2:B$43) -> Rincon | D34: TRES10 | E34: =LOOKUP($D34,Site_Meta!$C$2:$C$43,Site_Meta!D$2:D$43) -> West | F34: =LOOKUP($D34,Site_Meta!$C$2:$C$43,Site_Meta!E$2:E$43) -> W | G34: =LOOKUP($D34,Site_Meta!$C$2:$C$43,Site_Meta!F$2:F$43) -> 18.34732 | H34: =LOOKUP($D34,Site_Meta!$C$2:$C$43,Site_Meta!G$2:G$43) -> -67.27 | I34: =LOOKUP($D34,Site_Meta!$C$2:$C$43,Site_Meta!H$2:H$43) -> 10 | J34: 1 | K34: 9 | L34: 25 | M34: =CONCATENATE(J34,"/",K34,"/",L34) -> 1/9/25 | N34: Miguel F | O34: JJ | P34: Victoria | Q34: Aliyah | R34: 0.44722222 | S34: 0.45972222 | T34: 28 | U34: 0.54 | V34: 35.7 | W34: 0.55 | X34: 6.48 | Y34: 0.5 | Z34: 8.16 | AA34: 0.55 | AB34: 27.95 | AC34: 7.13 | AD34: 35.71 | AE34: 7 | AF34: 6.3 | AG34: 6.91 | AH34: 8.16 | AI34: 7.05 | AJ34: >7 | AK34: >7 | AL34: >7 | AM34: >7 | AN34: 0.5 | AO34: 5 | AP34: 365 | AQ34: 366 | AR34: 367 | AS34: 368 | AT34: 369 | AU34: 370 | AV34: 371 | AW34: 372 | AX34: 373 | AY34: 374 | AZ34: 375
A35: 7 | B35: =LOOKUP($D35,Site_Meta!$C$2:$C$43,Site_Meta!A$2:A$43) -> Tres Palmas 20m | C35: =LOOKUP($D35,Site_Meta!$C$2:$C$43,Site_Meta!B$2:B$43) -> Rincon | D35: TRES5 | E35: =LOOKUP($D35,Site_Meta!$C$2:$C$43,Site_Meta!D$2:D$43) -> West | F35: =LOOKUP($D35,Site_Meta!$C$2:$C$43,Site_Meta!E$2:E$43) -> W | G35: =LOOKUP($D35,Site_Meta!$C$2:$C$43,Site_Meta!F$2:F$43) -> 18.34652 | H35: =LOOKUP($D35,Site_Meta!$C$2:$C$43,Site_Meta!G$2:G$43) -> -67.2712 | I35: =LOOKUP($D35,Site_Meta!$C$2:$C$43,Site_Meta!H$2:H$43) -> 20 | J35: 1 | K35: 9 | L35: 25 | M35: =CONCATENATE(J35,"/",K35,"/",L35) -> 1/9/25 | N35: Miguel F | O35: JJ | P35: Victoria | Q35: Aliyah | R35: 0.45972222 | S35: 0.47083333 | T35: 27.94 | U35: 0.74 | V35: 35.7 | W35: 0.67 | X35: 6.6 | Y35: 0.46 | Z35: 8.13 | AA35: 0.47 | AB35: 27.94 | AC35: 3.26 | AD35: 35.75 | AE35: 3.13 | AF35: 6.6 | AG35: 3.12 | AH35: 8.13 | AI35: 3.06 | AJ35: >3 | AK35: >3 | AL35: >3 | AM35: >3 | AN35: 0.5 | AO35: 18 | AP35: 417 | AQ35: 418 | AR35: 419 | AS35: 420 | AT35: 421 | AU35: 422 | AV35: 423 | AW35: 424 | AX35: 425 | AY35: 426 | AZ35: 427
A36: 7 | B36: =LOOKUP($D36,Site_Meta!$C$2:$C$43,Site_Meta!A$2:A$43) -> Manchas Exteriores 20m | C36: =LOOKUP($D36,Site_Meta!$C$2:$C$43,Site_Meta!B$2:B$43) -> Mayaguez | D36: MEXT20 | E36: =LOOKUP($D36,Site_Meta!$C$2:$C$43,Site_Meta!D$2:D$43) -> West | F36: =LOOKUP($D36,Site_Meta!$C$2:$C$43,Site_Meta!E$2:E$43) -> W | G36: =LOOKUP($D36,Site_Meta!$C$2:$C$43,Site_Meta!F$2:F$43) -> 18.2335 | H36: =LOOKUP($D36,Site_Meta!$C$2:$C$43,Site_Meta!G$2:G$43) -> -67.2009 | I36: =LOOKUP($D36,Site_Meta!$C$2:$C$43,Site_Meta!H$2:H$43) -> 20 | J36: 1 | K36: 9 | L36: 25 | M36: =CONCATENATE(J36,"/",K36,"/",L36) -> 1/9/25 | N36: Miguel F | O36: JJ | P36: Victoria | Q36: Aliyah | R36: 0.48819444 | S36: 0.5 | T36: 28.07 | U36: 0.62 | V36: 35.61 | W36: 0.6 | X36: 6.29 | Y36: 0.61 | Z36: 8.16 | AA36: 0.6 | AB36: 27.88 | AC36: 14.29 | AD36: 35.64 | AE36: 14.08 | AF36: 6.2 | AG36: 13.66 | AH36: 8.15 | AI36: 13.76 | AJ36: 8.5 | AK36: 7 | AL36: 7 | AM36: =AVERAGE(AJ36,AK36,AL36) -> 7.5 | AN36: 0.5 | AO36: 18 | AP36: 482 | AQ36: 483 | AR36: 484 | AS36: 485 | AT36: 486 | AU36: 487 | AV36: 488 | AW36: 489 | AX36: 490 | AY36: 491 | AZ36: 492
A37: 7 | B37: =LOOKUP($D37,Site_Meta!$C$2:$C$43,Site_Meta!A$2:A$43) -> Manchas Exteriores 10m | C37: =LOOKUP($D37,Site_Meta!$C$2:$C$43,Site_Meta!B$2:B$43) -> Mayaguez | D37: MEXT10 | E37: =LOOKUP($D37,Site_Meta!$C$2:$C$43,Site_Meta!D$2:D$43) -> West | F37: =LOOKUP($D37,Site_Meta!$C$2:$C$43,Site_Meta!E$2:E$43) -> W | G37: =LOOKUP($D37,Site_Meta!$C$2:$C$43,Site_Meta!F$2:F$43) -> 18.23353 | H37: =LOOKUP($D37,Site_Meta!$C$2:$C$43,Site_Meta!G$2:G$43) -> -67.2006 | I37: =LOOKUP($D37,Site_Meta!$C$2:$C$43,Site_Meta!H$2:H$43) -> 10 | J37: 1 | K37: 9 | L37: 25 | M37: =CONCATENATE(J37,"/",K37,"/",L37) -> 1/9/25 | N37: Miguel F | O37: JJ | P37: Victoria | Q37: Aliyah | R37: 0.50208333 | S37: 0.51736111 | T37: 28.05 | U37: 0.52 | V37: 35.69 | W37: 0.53 | X37: 6.23 | Y37: 0.57 | Z37: 8.15 | AA37: 0.55 | AB37: 27.9 | AC37: 7.12 | AD37: 35.66 | AE37: 7.14 | AF37: 6.07 | AG37: 7.11 | AH37: 8.15 | AI37: 7.14 | AJ37: 7 | AK37: 6.6 | AL37: 6 | AM37: =AVERAGE(AJ37,AK37,AL37) -> 6.5333333 | AN37: 0.5 | AO37: 8 | AP37: 339 | AQ37: 340 | AR37: 341 | AS37: 342 | AT37: 343 | AU37: 344 | AV37: 345 | AW37: 346 | AX37: 347 | AY37: 348 | AZ37: 349
A38: 7 | B38: =LOOKUP($D38,Site_Meta!$C$2:$C$43,Site_Meta!A$2:A$43) -> Cayo Caribes 10m | C38: =LOOKUP($D38,Site_Meta!$C$2:$C$43,Site_Meta!B$2:B$43) -> Salinas | D38: CARI10 | E38: =LOOKUP($D38,Site_Meta!$C$2:$C$43,Site_Meta!D$2:D$43) -> Southeast | F38: =LOOKUP($D38,Site_Meta!$C$2:$C$43,Site_Meta!E$2:E$43) -> S | G38: =LOOKUP($D38,Site_Meta!$C$2:$C$43,Site_Meta!F$2:F$43) -> 17.91533 | H38: =LOOKUP($D38,Site_Meta!$C$2:$C$43,Site_Meta!G$2:G$43) -> -66.2141 | I38: =LOOKUP($D38,Site_Meta!$C$2:$C$43,Site_Meta!H$2:H$43) -> 10 | J38: 1 | K38: 16 | L38: 25 | M38: =CONCATENATE(J38,"/",K38,"/",L38) -> 1/16/25 | N38: Hector R | O38: Manuel O | P38: Victoria | Q38: Aliyah | R38: 0.34305556 | S38: 0.35555556 | T38: 27.06 | U38: 0.53 | V38: 35.43 | W38: 0.59 | X38: 6.16 | Y38: 0.53 | Z38: 8.04 | AA38: 0.53 | AB38: 26.98 | AC38: 8.01 | AD38: 35.35 | AE38: 7.97 | AF38: 5.8 | AG38: 8.11 | AH38: 8.07 | AI38: 7.89 | AJ38: 6 | AK38: 6.2 | AL38: 6 | AM38: =AVERAGE(AJ38,AK38,AL38) -> 6.0666667 | AN38: 0.5 | AO38: 8 | AP38: 664 | AQ38: 665 | AR38: 666 | AS38: 667 | AT38: 668 | AU38: 669 | AV38: 670 | AW38: 671 | AX38: 672 | AY38: 673 | AZ38: 674
A39: 7 | B39: =LOOKUP($D39,Site_Meta!$C$2:$C$43,Site_Meta!A$2:A$43) -> Cayo Caribes 10m | C39: =LOOKUP($D39,Site_Meta!$C$2:$C$43,Site_Meta!B$2:B$43) -> Salinas | D39: CARI10-R | E39: =LOOKUP($D39,Site_Meta!$C$2:$C$43,Site_Meta!D$2:D$43) -> Southeast | F39: =LOOKUP($D39,Site_Meta!$C$2:$C$43,Site_Meta!E$2:E$43) -> S | G39: =LOOKUP($D39,Site_Meta!$C$2:$C$43,Site_Meta!F$2:F$43) -> 17.91533 | H39: =LOOKUP($D39,Site_Meta!$C$2:$C$43,Site_Meta!G$2:G$43) -> -66.2141 | I39: =LOOKUP($D39,Site_Meta!$C$2:$C$43,Site_Meta!H$2:H$43) -> 10 | J39: 1 | K39: 16 | L39: 25 | M39: =CONCATENATE(J39,"/",K39,"/",L39) -> 1/16/25 | N39: Hector R | O39: Manuel O | P39: Victoria | Q39: Aliyah | R39: 0.35694444 | S39: 0.36527778 | T39: 26.96 | U39: 0.51 | V39: 35.42 | W39: 0.54 | X39: 6.19 | Y39: 0.6 | Z39: 8.08 | AA39: 0.6 | AB39: 27.03 | AC39: 8.44 | AD39: 35.48 | AE39: 8.2 | AF39: 6.06 | AG39: 8.37 | AH39: 8.12 | AI39: 8.35 | AJ39: 7 | AK39: 7.4 | AL39: 7.2 | AM39: =AVERAGE(AJ39,AK39,AL39) -> 7.2 | AN39: 0.5 | AO39: 8 | AP39: 599 | AQ39: 600 | AR39: 601 | AS39: 602 | AT39: 603 | AU39: 604 | AV39: 605 | AW39: 606 | AX39: 607 | AY39: 608 | AZ39: 609
A40: 7 | B40: =LOOKUP($D40,Site_Meta!$C$2:$C$43,Site_Meta!A$2:A$43) -> Cayo Ratones 5m | C40: =LOOKUP($D40,Site_Meta!$C$2:$C$43,Site_Meta!B$2:B$43) -> Salinas | D40: RATO05 | E40: =LOOKUP($D40,Site_Meta!$C$2:$C$43,Site_Meta!D$2:D$43) -> Southeast | F40: =LOOKUP($D40,Site_Meta!$C$2:$C$43,Site_Meta!E$2:E$43) -> S | G40: =LOOKUP($D40,Site_Meta!$C$2:$C$43,Site_Meta!F$2:F$43) -> 17.9346 | H40: =LOOKUP($D40,Site_Meta!$C$2:$C$43,Site_Meta!G$2:G$43) -> -66.3025 | I40: =LOOKUP($D40,Site_Meta!$C$2:$C$43,Site_Meta!H$2:H$43) -> 5 | J40: 1 | K40: 16 | L40: 25 | M40: =CONCATENATE(J40,"/",K40,"/",L40) -> 1/16/25 | N40: Hector R | O40: Manuel O | P40: Victoria | Q40: Aliyah | R40: 0.38611111 | S40: 0.39027778 | T40: 27.15 | U40: 0.57 | V40: 35.45 | W40: 0.49 | X40: 6.43 | Y40: 0.52 | Z40: 8.12 | AA40: 0.5 | AB40: 27.16 | AC40: 3.01 | AD40: 35.47 | AE40: 2.95 | AF40: 6.29 | AG40: 2.93 | AH40: 8.12 | AI40: 3 | AJ40: 3 | AK40: 3 | AL40: 3 | AM40: 3 | AN40: 0.5 | AO40: 3 | AP40: 613 | AQ40: 612 | AR40: 615 | AS40: 614 | AT40: 616 | AU40: 617 | AV40: 618 | AW40: 619 | AX40: 620 | AY40: 621 | AZ40: 622
...

Sheet Site_Meta
A1: Site_Name | B1: Location | C1: Site_Code | D1: Region | E1: Zone | F1: Latitude | G1: Longitude | H1: Depth
A2: Cayo Aurora 5m | B2: Guanica | C2: AURO05 | D2: Southwest | E2: SW | F2: 17.9369 | G2: -66.8738 | H2: 5 | K2: Sampled
A3: Puerto Botes 15m | B3: Isla Desecheo | C3: BOTE15 | D3: Mona/Desecheo | E3: W | F3: 18.382 | G3: -67.4883 | H3: 15 | K3: Planned
A4: Puerto Botes 20m | B4: Isla Desecheo | C4: BOTE20 | D4: Mona/Desecheo | E4: W | F4: 18.38158 | G4: -67.4886 | H4: 20 | K4: Pending
A5: Boya Vieja 20m | B5: La Parguera | C5: BOYA20 | D5: Southwest | E5: SW | F5: 17.88827 | G5: -66.9978 | H5: 20
A6: Cabezas de San Juan 5m | B6: Fajardo | C6: CABE05 | D6: North/Northeast | E6: E | F6: 18.38544 | G6: -65.6297 | H6: 5
A7: Canjilones 15m | B7: Isla Vieques | C7: CANJ15 | D7: Vieques/Culebra | E7: E | F7: 18.08964 | G7: -65.5901 | H7: 15
A8: Puerto Canoas 30m | B8: Isla Desecheo | C8: CANO30 | D8: Mona/Desecheo | E8: W | F8: 18.37747 | G8: -67.484 | H8: 30
A9: Cayo Caribes 10m | B9: Salinas | C9: CARI10 | D9: Southeast | E9: S | F9: 17.91533 | G9: -66.2141 | H9: 10
A10: West Reef 10m | B10: Ponce | C10: CDMU10 | D10: South | E10: S | F10: 17.89502 | G10: -66.5284 | H10: 10
A11: Cibuco 05m | B11: Vega Baja | C11: CIBU05 | D11: North/Northeast | E11: N | F11: 18.48955 | G11: -66.3736 | H11: 10
A12: Cayo Coral 10m | B12: Guanica | C12: CORA10 | D12: Southwest | E12: SW | F12: 17.9362 | G12: -66.8884 | H12: 10
A13: Carlos Rosario 10m | B13: Isla Culebra | C13: CROS10 | D13: Vieques/Culebra | E13: E | F13: 18.32779 | G13: -65.332 | H13: 10
A14: Dakiti 20m | B14: Isla Culebra | C14: DAKI20 | D14: Vieques/Culebra | E14: E | F14: 18.27587 | G14: -65.2773 | H14: 20
A15: Derrumbadero 20m | B15: Ponce | C15: DERR20 | D15: South | E15: S | F15: 17.904 | G15: -66.6086 | H15: 20
A16: Cayo Diablo 5m | B16: Fajardo | C16: DIAB05 | D16: North/Northeast | E16: E | F16: 18.36033 | G16: -65.5309 | H16: 5
... A43: Tres Palmas 20m | B43: Rincon | C43: TRES20 | D43: West | E43: W | F43: 18.34652 | G43: -67.2712 | H43: 20
