Workbook

Sheet Raw Data
A1: Sampling_Cycle | B1: Site_Name | C1: Location | D1: Site_Code | E1: Region | F1: Zone | G1: Latitude | H1: Longitude | I1: Depth | J1: Month | K1: Day | L1: Year | M1: Date | N1: Captain | O1: Crew_1 | P1: Crew_2 | Q1: Crew_3 | R1: Time_In | S1: Time_Out | T1: Surface_Temp_C | U1: Surface_Temp_Depth_m | V1: Surface_Sal_psu | W1: Surface_Sal_Depth_m | X1: Surface_DO_mg_L | Y1: Surface_DO_Depth_m | Z1: Surface_pH | AA1: Surface_pH_Depth_m | AB1: Bottom_Temp_C | AC1: Bottom_Temp_Depth_m | AD1: Bottom_Sal_psu | AE1: Bottom_Sal._Depth_m | AF1: Bottom_DO_mg_L | AG1: Bottom_DO_Depth_m | AH1: Bottom_pH | AI1: Bottom_pH_Depth_m | AJ1: Secchi_Depth_1_m | AK1: Secchi_Depth_2_m | AL1: Secchi_Depth_3_m | AM1: Secchi_Max_Depth | AN1: Surface_Van_Dorn_Depth_m | AO1: Bottom_Van_Dorn_Depth_m | AP1: Surface_TA_DIC | AQ1: Bottom_TA_DIC | AR1: Surface_BOD | AS1: Bottom_BOD | AT1: Chl_a | AU1: Turbidity | AV1: Settleable_Solids | AW1: Total_Suspended_Solids | AX1: POx_NOx | AY1: TKN | AZ1: Enterococcus
A2: 1 | B2: Boya Vieja 20m | C2: La Parguera | D2: BOYA20 | E2: Southwest | F2: SW | G2: 17.88827 | H2: -66.9978 | I2: 20 | J2: 5 | K2: 12 | L2: 2023 | M2: 5/12/2023 | N2: Anibal | O2: Carla | P2: Manuel | Q2: -999 | R2: 0.37222222 | S2: 0.43194444 | T2: 28.76 | U2: 2.4 | V2: 33.37 | W2: 2.4 | X2: 6.57 | Y2: 2.33 | Z2: 8.12 | AA2: 2.38 | AB2: 28.75 | AC2: 21.69 | AD2: 33.19 | AE2: 21.65 | AF2: 6.58 | AG2: 21.55 | AH2: 8.18 | AI2: 21.55 | AJ2: 12.25 | AK2: 13 | AL2: 13 | AM2: 0 | AN2: 1 | AO2: 21 | AP2: 73 | AQ2: 87 | AR2: 12 | AS2: 7 | AT2: 3 | AU2: 3 | AV2: 5 | AW2: 3 | AX2: 5 | AY2: 6 | AZ2: 1
A3: 1 | B3: Efras Wall 20m | C3: La Parguera | D3: EWAL20 | E3: Southwest | F3: SW | G3: 17.8976 | H3: -66.9599 | I3: 20 | J3: 5 | K3: 18 | L3: 2023 | M3: 5/18/2023 | N3: Anibal | O3: Majo | P3: Irais | Q3: Manuel | R3: 0.32361111 | S3: 0.37222222 | T3: 28.58 | U3: 0.6 | V3: 37.08 | W3: 0.67 | X3: 6.27 | Y3: 0.68 | Z3: 8.12 | AA3: 0.69 | AB3: 28.06 | AC3: 18.5 | AD3: 37.16 | AE3: 18.5 | AF3: 6.1 | AG3: 18.5 | AH3: 8.24 | AI3: 18.5 | AJ3: 20 | AK3: 20 | AL3: 20.25 | AM3: 1 | AN3: 1 | AO3: 18 | AP3: 97 | AQ3: 96 | AR3: 8 | AS3: 5 | AT3: 10 | AU3: 17 | AV3: 6 | AW3: 6 | AX3: PO4_4 | AY3: 1 | AZ3: ET#1
A4: 1 | B4: Media Luna 5m | C4: La Parguera | D4: MLUN05 | E4: Southwest | F4: SW | G4: 17.93937 | H4: -67.0507 | I4: 5 | J4: 5 | K4: 18 | L4: 2023 | M4: 5/18/2023 | N4: Anibal | O4: Majo | P4: Irais | Q4: Manuel | R4: 0.39513889 | S4: 0.42013889 | T4: 29.14 | U4: 0.5 | V4: 37.29 | W4: 0.53 | X4: 6.24 | Y4: 0.54 | Z4: 8.02 | AA4: 0.55 | AB4: 29.17 | AC4: 3.7 | AD4: 37.46 | AE4: 3.74 | AF4: 6.13 | AG4: 3.74 | AH4: 8.15 | AI4: 3.73 | AJ4: 3.7 | AK4: 3.7 | AL4: 3.7 | AM4: 1 | AN4: 1 | AO4: 3 | AP4: 83 | AQ4: 77 | AR4: 4 | AS4: 6 | AT4: 4 | AU4: 5 | AV4: 3 | AW4: 4 | AX4: NO3_5 | AY4: 3 | AZ4: 3
A5: 1 | B5: Media Luna 10m | C5: La Parguera | D5: MLUN10 | E5: Southwest | F5: SW | G5: 17.93472 | H5: -67.0485 | I5: 10 | J5: 5 | K5: 18 | L5: 2023 | M5: 5/18/2023 | N5: Anibal | O5: Majo | P5: Irais | Q5: Manuel | R5: 0.42916667 | S5: 0.44652778 | T5: 29.39 | U5: 0.75 | V5: 36.94 | W5: 0.76 | X5: 6.15 | Y5: 0.76 | Z5: 8.11 | AA5: 0.73 | AB5: 29.2 | AC5: 10.02 | AD5: 37.17 | AE5: 10.02 | AF5: 6.1 | AG5: 9.4 | AH5: 8.13 | AI5: 9.9 | AJ5: 9.25 | AK5: 9.25 | AL5: 9.5 | AM5: 0 | AN5: 1 | AO5: 9.5 | AP5: 85 | AQ5: 84 | AR5: 3 | AS5: 11 | AT5: 11 | AU5: 15 | AV5: 7 | AW5: 5 | AX5: PO4_3 | AY5: 4 | AZ5: 4
A6: 1 | B6: Gallardo 5m | C6: Cabo Rojo | D6: GALL05 | E6: West | F6: W | G6: 18.0017 | H6: -67.3299 | I6: 5 | J6: 5 | K6: 19 | L6: 2023 | M6: 5/19/2023 | N6: Orlando | O6: Irais | P6: Leira | Q6: Manuel | R6: 0.35486111 | S6: 0.38472222 | T6: 29.09 | U6: 0.66 | V6: 37.5 | W6: 0.68 | X6: 5.68 | Y6: 0.68 | Z6: 8.15 | AA6: 0.69 | AB6: 29.12 | AC6: 5.97 | AD6: 37.52 | AE6: 6.05 | AF6: 5.69 | AG6: 6.12 | AH6: 8.18 | AI6: 6.14 | AJ6: 5 | AK6: 5 | AL6: 5 | AM6: 1 | AN6: 1 | AO6: 5.5 | AP6: 100 | AQ6: 95 | AR6: 16 | AS6: 15 | AT6: 5 | AU6: 18 | AV6: 9 | AW6: 9 | AX6: NO3_6 | AY6: 1A | AZ6: 1A
A7: 1 | B7: Resuellos 10m | C7: Cabo Rojo | D7: RESU10 | E7: West | F7: W | G7: 17.99116 | H7: -67.2332 | I7: 10 | J7: 5 | K7: 19 | L7: 2023 | M7: 5/19/2023 | N7: Orlando | O7: Irais | P7: Leira | Q7: Manuel | R7: 0.40138889 | S7: 0.43125 | T7: 29.29 | U7: 0.62 | V7: 37.52 | W7: 0.62 | X7: 6.13 | Y7: 0.61 | Z7: 8.2 | AA7: 0.61 | AB7: 29.39 | AC7: 6.2 | AD7: 37.29 | AE7: 5.85 | AF7: 6.27 | AG7: 5.7 | AH7: 8.23 | AI7: 5.34 | AJ7: 5.5 | AK7: 5.75 | AL7: 5.75 | AM7: 0 | AN7: 1 | AO7: 5.75 | AP7: 99 | AQ7: 86 | AR7: 19 | AS7: 9 | AT7: 7 | AU7: 4 | AV7: 4 | AW7: 7 | AX7: NO3_3 | AY7: 5 | AZ7: 6
A8: 1 | B8: Maria Langa 10m | C8: Guayanilla | D8: MLAN10 | E8: South | F8: S | G8: 17.96093 | H8: -66.7529 | I8: 10 | J8: 5 | K8: 22 | L8: 2023 | M8: 5/22/2023 | N8: Orlando | O8: Irais | P8: Leira | Q8: Manuel | R8: 0.38472222 | S8: 0.40694444 | T8: 28.54 | U8: 0.7 | V8: 36.06 | W8: 0.7 | X8: 5.28 | Y8: 0.7 | Z8: 8.17 | AA8: 0.7 | AB8: 29.16 | AC8: 9.02 | AD8: 37.16 | AE8: 8.74 | AF8: 5.28 | AG8: 9.08 | AH8: 8.24 | AI8: 9.04 | AJ8: 3 | AK8: 2.75 | AL8: 2.25 | AM8: 0 | AN8: 1 | AO8: 9 | AP8: 108 | AQ8: 107 | AR8: 25 | AS8: 26 | AT8: 6 | AU8: 9 | AV8: 8 | AW8: 8 | AX8: 23 | AY8: 24 | AZ8: 5
A9: 1 | B9: Maria Langa 20m | C9: Guayanilla | D9: MLAN20 | E9: South | F9: S | G9: 17.95953 | H9: -66.747 | I9: 20 | J9: 5 | K9: 22 | L9: 2023 | M9: 5/22/2023 | N9: Orlando | O9: Irais | P9: Leira | Q9: Manuel | R9: 0.35277778 | S9: 0.38194444 | T9: 28.07 | U9: 0.84 | V9: 34.78 | W9: 0.83 | X9: 5.42 | Y9: 0.8 | Z9: 8.01 | AA9: 0.8 | AB9: 29.05 | AC9: 16.9 | AD9: 37.05 | AE9: 16.94 | AF9: 5.36 | AG9: 17.06 | AH9: 8.26 | AI9: 16.5 | AJ9: 3 | AK9: 2.75 | AL9: 2.5 | AM9: 0 | AN9: 1 | AO9: 16 | AP9: 106 | AQ9: 105 | AR9: 22 | AS9: 21 | AT9: 8 | AU9: 7 | AV9: 13 | AW9: 13 | AX9: 29 | AY9: 28 | AZ9: MLA20
A10: 1 | B10: Guanajibo 20m | C10: Mayagüez | D10: GUAN20 | E10: West | F10: W | G10: 18.17202 | H10: -67.253 | I10: 20 | J10: 5 | K10: 24 | L10: 2023 | M10: 5/24/2023 | N10: Orlando | O10: Irais | P10: Manuel | Q10: -999 | R10: 0.41666667 | S10: 0.4375 | T10: 28.43 | U10: 0.55 | V10: 37.18 | W10: 0.55 | X10: 5.73 | Y10: 0.53 | Z10: 8.26 | AA10: 0.54 | AB10: 28.29 | AC10: 17.4 | AD10: 37.34 | AE10: 17.13 | AF10: 5.75 | AG10: 16.59 | AH10: 8.34 | AI10: 16.58 | AJ10: 12 | AK10: 12 | AL10: 12 | AM10: 0 | AN10: 0.5 | AO10: 16 | AP10: 93 | AQ10: 94 | AR10: 24 | AS10: 23 | AT10: 13 | AU10: 8 | AV10: 17 | AW10: 12 | AX10: 31 | AY10: 20 | AZ10: 11
A11: 1 | B11: Manchas Exteriores 10m | C11: Mayagüez | D11: MEXT10 | E11: West | F11: W | G11: 18.23353 | H11: -67.2006 | I11: 10 | J11: 5 | K11: 24 | L11: 2023 | M11: 5/24/2023 | N11: Orlando | O11: Irais | P11: Manuel | Q11: -999 | R11: 0.51805556 | S11: 0.53680556 | T11: 28.89 | U11: 0.55 | V11: 36.96 | W11: 0.55 | X11: 5.94 | Y11: 0.54 | Z11: 8.27 | AA11: 0.57 | AB11: 28.51 | AC11: 6.23 | AD11: 37.06 | AE11: 5.8 | AF11: 6.34 | AG11: 6.5 | AH11: 8.35 | AI11: 6.7 | AJ11: 7.25 | AK11: 7.25 | AL11: 7.25 | AM11: 0 | AN11: 0.5 | AO11: 6.5 | AP11: 90 | AQ11: 75 | AR11: 37 | AS11: 38 | AT11: 17 | AU11: 20 | AV11: 20 | AW11: 16 | AX11: 36 | AY11: 42 | AZ11: 14
A12: 1 | B12: Manchas Exteriores 20m | C12: Mayagüez | D12: MEXT20 | E12: West | F12: W | G12: 18.2335 | H12: -67.2009 | I12: 20 | J12: 5 | K12: 24 | L12: 2023 | M12: 5/24/2023 | N12: Orlando | O12: Irais | P12: Manuel | Q12: -999 | R12: 0.49166667 | S12: 0.51458333 | T12: 28.95 | U12: 0.5 | V12: 37.14 | W12: 0.52 | X12: 5.9 | Y12: 0.5 | Z12: 8.28 | AA12: 0.5 | AB12: 28.47 | AC12: 9.46 | AD12: 37.01 | AE12: 9.46 | AF12: 6.04 | AG12: 9.06 | AH12: 8.33 | AI12: 8.6 | AJ12: 10 | AK12: 10 | AL12: 10 | AM12: 0 | AN12: 0.5 | AO12: 11.5 | AP12: 88 | AQ12: 92 | AR12: 41 | AS12: 42 | AT12: 19 | AU12: 11 | AV12: 22 | AW12: 18 | AX12: 35 | AY12: 41 | AZ12: 13
A13: 1 | B13: El Negro 5m | C13: Cabo Rojo | D13: NEGR05 | E13: West | F13: W | G13: 18.14658 | H13: -67.2476 | I13: 5 | J13: 5 | K13: 24 | L13: 2023 | M13: 5/24/2023 | N13: Orlando | O13: Irais | P13: Manuel | Q13: -999 | R13: 0.57916667 | S13: 0.60208333 | T13: 29.02 | U13: 0.49 | V13: 36.93 | W13: 0.5 | X13: 6.1 | Y13: 0.5 | Z13: 8.21 | AA13: 0.49 | AB13: 28.89 | AC13: 2.82 | AD13: 37.35 | AE13: 3.7 | AF13: 6.11 | AG13: 2.8 | AH13: 8.35 | AI13: 2.84 | AJ13: 6 | AK13: 6 | AL13: 6 | AM13: 1 | AN13: 0.5 | AO13: 5 | AP13: 110 | AQ13: 111 | AR13: 40 | AS13: 39 | AT13: 18 | AU13: 12 | AV13: 21 | AW13: 17 | AX13: 34 | AY13: 40 | AZ13: 16
A14: 1 | B14: El Negro 10m | C14: Cabo Rojo | D14: NEGR10 | E14: West | F14: W | G14: 18.14653 | H14: -67.248 | I14: 10 | J14: 5 | K14: 24 | L14: 2023 | M14: 5/24/2023 | N14: Orlando | O14: Irais | P14: Manuel | Q14: -999 | R14: 0.55833333 | S14: 0.58125 | T14: 29.2 | U14: 0.47 | V14: 37.01 | W14: 0.48 | X14: 6.4 | Y14: 0.5 | Z14: 8.2 | AA14: 0.47 | AB14: 28.71 | AC14: 17.43 | AD14: 37.1 | AE14: 17.03 | AF14: 5.96 | AG14: 16.34 | AH14: 8.36 | AI14: 17.35 | AJ14: 8.25 | AK14: 8.75 | AL14: 8.75 | AM14: 0 | AN14: 0.5 | AO14: 16.5 | AP14: 76 | AQ14: 89 | AR14: 35 | AS14: 36 | AT14: 16 | AU14: 13 | AV14: 19 | AW14: 15 | AX14: 33 | AY14: 39 | AZ14: 15
A15: 1 | B15: Cayo Rodriguez 5m | C15: Mayagüez | D15: RODR05 | E15: West | F15: W | G15: 18.1893 | H15: -67.1919 | I15: 5 | J15: 5 | K15: 24 | L15: 2023 | M15: 5/24/2023 | N15: Orlando | O15: Irais | P15: Manuel | Q15: -999 | R15: 0.44930556 | S15: 0.46527778 | T15: 29.7 | U15: 0.5 | V15: 37.06 | W15: 0.5 | X15: 6 | Y15: 0.52 | Z15: 8.29 | AA15: 0.5 | AB15: 29.2 | AC15: 3.67 | AD15: 37.04 | AE15: 3.67 | AF15: 6.15 | AG15: 3.68 | AH15: 8.34 | AI15: 3.66 | AJ15: 5 | AK15: 5 | AL15: 5 | AM15: 1 | AN15: 0.5 | AO15: 3.5 | AP15: 101 | AQ15: 102 | AR15: 20 | AS15: 18 | AT15: 9 | AU15: 6 | AV15: 14 | AW15: 10 | AX15: 27 | AY15: 26 | AZ15: 12
A16: 1 | B16: Tourmaline 10m | C16: Cabo Rojo | D16: TOUR10 | E16: West | F16: W | G16: 18.16304 | H16: -67.2737 | I16: 10 | J16: 5 | K16: 24 | L16: 2023 | M16: 5/24/2023 | N16: Orlando | O16: Irais | P16: Manuel | Q16: -999 | R16: 0.39027778 | S16: 0.40972222 | T16: 28.67 | U16: 0.49 | V16: 37.23 | W16: 0.54 | X16: 5.9 | Y16: 0.53 | Z16: 8.27 | AA16: 0.52 | AB16: 28.59 | AC16: 9.54 | AD16: 37.23 | AE16: 9.3 | AF16: 5.9 | AG16: 9.27 | AH16: 8.34 | AI16: 9.15 | AJ16: 14 | AK16: 14.5 | AL16: 14.75 | AM16: 0 | AN16: 0.5 | AO16: 9.5 | AP16: 98 | AQ16: 81 | AR16: 27 | AS16: 28 | AT16: 12 | AU16: 40 | AV16: 16 | AW16: 11 | AX16: 21 | AY16: 30 | AZ16: 9
A17: 1 | B17: Tourmaline 20m | C17: Cabo Rojo | D17: TOUR20 | E17: West | F17: W | G17: 18.16517 | H17: -67.2752 | I17: 20 | J17: 5 | K17: 24 | L17: 2023 | M17: 5/24/2023 | N17: Orlando | O17: Irais | P17: Manuel | Q17: -999 | R17: 0.35833333 | S17: 0.38472222 | T17: 28.27 | U17: 0.64 | V17: 37.18 | W17: 0.65 | X17: 5.77 | Y17: 0.6 | Z17: 8.26 | AA17: 0.63 | AB17: 28.2 | AC17: 19.3 | AD17: 37.21 | AE17: 19.48 | AF17: 5.77 | AG17: 19.42 | AH17: 8.34 | AI17: 18.92 | AJ17: 15.25 | AK17: 15.25 | AL17: 15.5 | AM17: 0 | AN17: 0.5 | AO17: 19.5 | AP17: 104 | AQ17: 103 | AR17: 14 | AS17: 13 | AT17: 14 | AU17: 16 | AV17: 15 | AW17: 28 | AX17: 25 | AY17: 22 | AZ17: 8
A18: 1 | B18: Tourmaline 30m | C18: Cabo Rojo | D18: TOUR30 | E18: West | F18: W | G18: 18.16637 | H18: -67.2763 | I18: 30 | J18: 5 | K18: 24 | L18: 2023 | M18: 5/24/2023 | N18: Orlando | O18: Irais | P18: Manuel | Q18: -999 | R18: 0.31944444 | S18: 0.35069444 | T18: 28.09 | U18: 0.52 | V18: 37.14 | W18: 0.52 | X18: 5.71 | Y18: 0.52 | Z18: 8.06 | AA18: 0.5 | AB18: 28.15 | AC18: 26.5 | AD18: 37.17 | AE18: 26.01 | AF18: 5.73 | AG18: 25.35 | AH18: 8.34 | AI18: 24.68 | AJ18: 9.25 | AK18: 9.25 | AL18: 9.5 | AM18: 0 | AN18: 0.5 | AO18: 25.5 | AP18: 91 | AQ18: 74 | AR18: 33 | AS18: 34 | AT18: 15 | AU18: 21 | AV18: 18 | AW18: 14 | AX18: 32 | AY18: 38 | AZ18: 7
A19: 1 | B19: Cayo Aurora 5m | C19: Guánica | D19: AURO05 | E19: Southwest | F19: SW | G19: 17.9369 | H19: -66.8738 | I19: 5 | J19: 5 | K19: 25 | L19: 2023 | M19: 5/25/2023 | N19: Orlando | O19: Irais | P19: Leira | Q19: Manuel | R19: 0.40208333 | S19: 0.41875 | T19: 29.38 | U19: 0.55 | V19: 37 | W19: 0.49 | X19: 5.85 | Y19: 0.49 | Z19: 8.4 | AA19: 0.49 | AB19: 29.4 | AC19: 3.58 | AD19: 36.96 | AE19: 3.58 | AF19: 5.95 | AG19: 3.69 | AH19: 8.4 | AI19: 3.79 | AJ19: 3.5 | AK19: 3.5 | AL19: 3.5 | AM19: 1 | AN19: 0.5 | AO19: 2.5 | AP19: 112 | AQ19: 113 | AR19: 44 | AS19: 43 | AT19: 20 | AU19: 19 | AV19: 23 | AW19: 19 | AX19: 37 | AY19: 43 | AZ19: 17
A20: 1 | B20: Cayo Coral 10m | C20: Guánica | D20: CORA10 | E20: Southwest | F20: SW | G20: 17.9362 | H20: -66.8884 | I20: 10 | J20: 5 | K20: 25 | L20: 2023 | M20: 5/25/2023 | N20: Orlando | O20: Irais | P20: Leira | Q20: Manuel | R20: 0.42638889 | S20: 0.44097222 | T20: 29.2 | U20: 0.7 | V20: 37.15 | W20: 0.68 | X20: 5.63 | Y20: 0.69 | Z20: 8.48 | AA20: 0.69 | AB20: 29.02 | AC20: 9.38 | AD20: 36.9 | AE20: 9.43 | AF20: 5.78 | AG20: 9.44 | AH20: 8.39 | AI20: 9.43 | AJ20: 9.5 | AK20: 9.5 | AL20: 9.5 | AM20: 1 | AN20: 0.5 | AO20: 9 | AP20: 114 | AQ20: 115 | AR20: 46 | AS20: 45 | AT20: 21 | AU20: 22 | AV20: 24 | AW20: 20 | AX20: 38 | AY20: 44 | AZ20: 18
A21: 1 | B21: Maria Langa 5m | C21: Guayanilla | D21: MLAN05 | E21: South | F21: S | G21: 17.96488 | H21: -66.7565 | I21: 5 | J21: 5 | K21: 25 | L21: 2023 | M21: 5/25/2023 | N21: Orlando | O21: Irais | P21: Leira | Q21: Manuel | R21: 0.36319444 | S21: 0.38263889 | T21: 29.19 | U21: 0.6 | V21: 37.19 | W21: 0.6 | X21: 4.97 | Y21: 0.57 | Z21: 8.43 | AA21: 0.55 | AB21: 29.22 | AC21: 5.25 | AD21: 37.22 | AE21: 5.38 | AF21: 5.47 | AG21: 5.36 | AH21: 8.38 | AI21: 5.38 | AJ21: 6 | AK21: 6 | AL21: 6 | AM21: 1 | AN21: 0.5 | AO21: 5.5 | AP21: 119 | AQ21: 118 | AR21: 49 | AS21: 50 | AT21: 23 | AU21: 24 | AV21: 26 | AW21: 22 | AX21: 40 | AY21: 46 | AZ21: 10
A22: 1 | B22: Cayo Caribes 10m | C22: Salinas | D22: CARI10 | E22: Southeast | F22: S | G22: 17.91533 | H22: -66.2141 | I22: 10 | J22: 6 | K22: 12 | L22: 2023 | M22: 6/12/2023 | N22: Anibal | O22: Irais | P22: Leira | Q22: Manuel | R22: 0.42083333 | S22: 0.43958333 | T22: 30.06 | U22: 0.7 | V22: 37.31 | W22: 0.65 | X22: 6.24 | Y22: 0.68 | Z22: 8.03 | AA22: 0.7 | AB22: 30.03 | AC22: 9.6 | AD22: 37.18 | AE22: 9.4 | AF22: 6.2 | AG22: 9.14 | AH22: 8.09 | AI22: 8.64 | AJ22: 4.25 | AK22: 4.25 | AL22: 4.25 | AM22: 0 | AN22: 1 | AO22: 9.5 | AP22: 122 | AQ22: 123 | AR22: 56 | AS22: 55 | AT22: 27 | AU22: 29 | AV22: 29 | AW22: 24 | AX22: 42 | AY22: 48 | AZ22: 19
A23: 1 | B23: West Reef 10m | C23: Ponce | D23: CDMU10 | E23: South | F23: S | G23: 17.89502 | H23: -66.5284 | I23: 10 | J23: 6 | K23: 12 | L23: 2023 | M23: 6/12/2023 | N23: Anibal | O23: Irais | P23: Leira | Q23: Manuel | R23: 0.52013889 | S23: 0.53333333 | T23: 29.73 | U23: 0.8 | V23: 37.17 | W23: 0.67 | X23: 6.61 | Y23: 0.68 | Z23: 8.1 | AA23: 0.76 | AB23: 29.66 | AC23: 7.96 | AD23: 37.29 | AE23: 8.18 | AF23: 6.71 | AG23: 7.86 | AH23: 8.13 | AI23: 7.5 | AJ23: 8 | AK23: 8 | AL23: 8 | AM23: 1 | AN23: 1 | AO23: 7.5 | AP23: 128 | AQ23: 129 | AR23: 59 | AS23: 60 | AT23: 31 | AU23: 28 | AV23: 31 | AW23: 26 | AX23: 45 | AY23: 51 | AZ23: 22
A24: 1 | B24: Derrumbadero 20m | C24: Ponce | D24: DERR20 | E24: South | F24: S | G24: 17.904 | H24: -66.6086 | I24: 20 | J24: 6 | K24: 12 | L24: 2023 | M24: 6/12/2023 | N24: Anibal | O24: Irais | P24: Leira | Q24: Manuel | R24: 0.59236111 | S24: 0.60833333 | T24: 29.63 | U24: 0.71 | V24: 37.07 | W24: 0.74 | X24: 6.44 | Y24: 0.73 | Z24: 8.14 | AA24: 0.73 | AB24: 29.54 | AC24: 16.5 | AD24: 37.16 | AE24: 17.1 | AF24: 6.58 | AG24: 16.65 | AH24: 8.14 | AI24: 16.65 | AJ24: 13 | AK24: 13 | AL24: 13 | AM24: 0 | AN24: 1 | AO24: 16.5 | AP24: 120 | AQ24: 121 | AR24: 62 | AS24: 61 | AT24: 32 | AU24: 32 | AV24: 32 | AW24: 29 | AX24: 41 | AY24: 47 | AZ24: 23
A25: 1 | B25: Derrumbadero 20m | C25: Ponce | D25: DERR20-R | E25: South | F25: S | G25: 17.904 | H25: -66.6086 | I25: 20 | J25: 6 | K25: 12 | L25: 2023 | M25: 6/12/2023 | N25: Anibal | O25: Irais | P25: Leira | Q25: Manuel | R25: 0.61041667 | S25: 0.62361111 | T25: 29.64 | U25: 0.53 | V25: 37.13 | W25: 0.58 | X25: 6.52 | Y25: 0.6 | Z25: 8.13 | AA25: 0.59 | AB25: 29.54 | AC25: 16.13 | AD25: 37.12 | AE25: 16.2 | AF25: 6.47 | AG25: 16.3 | AH25: 8.14 | AI25: 16.33 | AJ25: 13 | AK25: 13 | AL25: 13 | AM25: 0 | AN25: 1 | AO25: 16 | AP25: 116 | AQ25: 117 | AR25: 48 | AS25: 47 | AT25: 22 | AU25: 23 | AV25: 25 | AW25: 21 | AX25: 39 | AY25: 45 | AZ25: 24
A26: 1 | B26: Cayo Ratones 5m | C26: Salinas | D26: RATO05 | E26: Southeast | F26: S | G26: 17.9346 | H26: -66.3025 | I26: 5 | J26: 6 | K26: 12 | L26: 2023 | M26: 6/12/2023 | N26: Anibal | O26: Irais | P26: Leira | Q26: Manuel | R26: 0.45486111 | S26: 0.47152778 | T26: 30.41 | U26: 0.82 | V26: 37.12 | W26: 0.8 | X26: 6.41 | Y26: 0.77 | Z26: 8.01 | AA26: 0.79 | AB26: 30.27 | AC26: 4.82 | AD26: 37.17 | AE26: 4.85 | AF26: 6.18 | AG26: 4.84 | AH26: 8.05 | AI26: 4.82 | AJ26: 4 | AK26: 4 | AL26: 4 | AM26: 1 | AN26: 1 | AO26: 4.5 | AP26: 126 | AQ26: 127 | AR26: 52 | AS26: 51 | AT26: 24 | AU26: 25 | AV26: 27 | AW26: 23 | AX26: 44 | AY26: 50 | AZ26: 20
A27: 1 | B27: Cayo Ratones 5m | C27: Salinas | D27: RATO05-R | E27: Southeast | F27: S | G27: 17.9346 | H27: -66.3025 | I27: 5 | J27: 6 | K27: 12 | L27: 2023 | M27: 6/12/2023 | N27: Anibal | O27: Irais | P27: Leira | Q27: Manuel | R27: 0.47222222 | S27: 0.48541667 | T27: -999 | U27: -999 | V27: -999 | W27: -999 | X27: -999 | Y27: -999 | Z27: -999 | AA27: -999 | AB27: -999 | AC27: -999 | AD27: -999 | AE27: -999 | AF27: -999 | AG27: -999 | AH27: -999 | AI27: -999 | AJ27: 4 | AK27: 4 | AL27: 4 | AM27: 1 | AN27: 1 | AO27: 4.5 | AP27: 130 | AQ27: 131 | AR27: 57 | AS27: 58 | AT27: 29 | AU27: 27 | AV27: 30 | AW27: 25 | AX27: 46 | AY27: 52 | AZ27: 21
A28: 1 | B28: Puerto Botes 15m | C28: Isla Desecheo | D28: BOTE15 | E28: Mona/Desecheo | F28: W | G28: 18.382 | H28: -67.4883 | I28: 15 | J28: 6 | K28: 14 | L28: 2023 | M28: 6/14/2023 | N28: Orlando | O28: Irais | P28: Adiana | Q28: Manuel | R28: 0.36111111 | S28: 0.37083333 | T28: 29.03 | U28: 0.65 | V28: 37.42 | W28: 0.6 | X28: 6.48 | Y28: 0.65 | Z28: 7.6 | AA28: 0.66 | AB28: 29.06 | AC28: 12.72 | AD28: 37.08 | AE28: 12.7 | AF28: 6.37 | AG28: 12.68 | AH28: 8.15 | AI28: 12.65 | AJ28: 15 | AK28: 15 | AL28: 15 | AM28: 1 | AN28: 1 | AO28: 12.5 | AP28: 134 | AQ28: 135 | AR28: 66 | AS28: 65 | AT28: 28 | AU28: 31 | AV28: 34 | AW28: 31 | AX28: 47 | AY28: 53 | AZ28: 25
A29: 1 | B29: Puerto Botes 20m | C29: Isla Desecheo | D29: BOTE20 | E29: Mona/Desecheo | F29: W | G29: 18.38158 | H29: -67.4886 | I29: 20 | J29: 6 | K29: 14 | L29: 2023 | M29: 6/14/2023 | N29: Orlando | O29: Irais | P29: Adiana | Q29: Manuel | R29: 0.38055556 | S29: 0.4 | T29: 28.98 | U29: 0.73 | V29: 37.3 | W29: 0.72 | X29: 6.51 | Y29: 0.74 | Z29: 8.1 | AA29: 0.73 | AB29: 29.07 | AC29: 19.5 | AD29: 37.03 | AE29: 19.5 | AF29: 6.31 | AG29: 19.48 | AH29: 8.2 | AI29: 19.4 | AJ29: 23 | AK29: 23 | AL29: 23 | AM29: 1 | AN29: 1 | AO29: 19.5 | AP29: 125 | AQ29: 124 | AR29: 53 | AS29: 54 | AT29: 26 | AU29: 26 | AV29: 28 | AW29: 27 | AX29: 43 | AY29: 49 | AZ29: 29
A30: 1 | B30: Puerto Canoas 30m | C30: Isla Desecheo | D30: CANO30 | E30: Mona/Desecheo | F30: W | G30: 18.37747 | H30: -67.484 | I30: 30 | J30: 6 | K30: 14 | L30: 2023 | M30: 6/14/2023 | N30: Orlando | O30: Irais | P30: Adiana | Q30: Manuel | R30: 0.40625 | S30: 0.43194444 | T30: 29.13 | U30: 0.79 | V30: 36.98 | W30: 0.7 | X30: 6.5 | Y30: 0.78 | Z30: 8.2 | AA30: 0.78 | AB30: 29 | AC30: 25.7 | AD30: 37.06 | AE30: 25.45 | AF30: 6.41 | AG30: 25.51 | AH30: 8.21 | AI30: 25.49 | AJ30: 31 | AK30: 31 | AL30: 31 | AM30: 1 | AN30: 1 | AO30: 25.5 | AP30: 136 | AQ30: 137 | AR30: 68 | AS30: 67 | AT30: 30 | AU30: 33 | AV30: 35 | AW30: 32 | AX30: 49 | AY30: 55 | AZ30: 26
A31: 1 | B31: Tres Palmas 05m | C31: Rincón | D31: TRES05 | E31: West | F31: W | G31: 18.35072 | H31: -67.2669 | I31: 5 | J31: 6 | K31: 20 | L31: 2023 | M31: 6/20/2023 | N31: -999 | O31: Manuel | P31: -999 | Q31: -999 | R31: 0.33888889 | S31: 0.34027778 | T31: 29.08 | U31: 0.99 | V31: 37.19 | W31: 0.99 | X31: 5.89 | Y31: 0.99 | Z31: 7.73 | AA31: 0.99 | AB31: 29.13 | AC31: 2.33 | AD31: 37.11 | AE31: 2.33 | AF31: 5.91 | AG31: 2.33 | AH31: 8.15 | AI31: 2.33 | AJ31: -999 | AK31: -999 | AL31: -999 | AM31: -999 | AN31: -999 | AO31: -999 | AP31: -999 | AQ31: -999 | AR31: -999 | AS31: -999 | AT31: -999 | AU31: -999 | AV31: -999 | AW31: -999 | AX31: -999 | AY31: -999 | AZ31: -999
A32: 1 | B32: Tres Palmas 10m | C32: Rincón | D32: TRES10 | E32: West | F32: W | G32: 18.34732 | H32: -67.27 | I32: 10 | J32: 6 | K32: 20 | L32: 2023 | M32: 6/20/2023 | N32: -999 | O32: Manuel | P32: -999 | Q32: -999 | R32: 0.34861111 | S32: 0.35069444 | T32: 29.07 | U32: 0.94 | V32: 37.42 | W32: 0.94 | X32: 6.17 | Y32: 0.94 | Z32: 8.05 | AA32: 0.94 | AB32: 29.2 | AC32: 13.57 | AD32: 37.25 | AE32: 13.57 | AF32: 6.12 | AG32: 13.57 | AH32: 8.21 | AI32: 13.57 | AJ32: -999 | AK32: -999 | AL32: -999 | AM32: -999 | AN32: -999 | AO32: -999 | AP32: -999 | AQ32: -999 | AR32: -999 | AS32: -999 | AT32: -999 | AU32: -999 | AV32: -999 | AW32: -999 | AX32: -999 | AY32: -999 | AZ32: -999
A33: 1 | B33: Tres Palmas 20m | C33: Rincón | D33: TRES20 | E33: West | F33: W | G33: 18.34652 | H33: -67.2712 | I33: 20 | J33: 6 | K33: 20 | L33: 2023 | M33: 6/20/2023 | N33: -999 | O33: Manuel | P33: -999 | Q33: -999 | R33: 0.35763889 | S33: 0.36319444 | T33: 29.2 | U33: 1.37 | V33: 37.36 | W33: 1.37 | X33: 6.24 | Y33: 1.37 | Z33: 8.1 | AA33: 1.37 | AB33: 29.2 | AC33: 22.89 | AD33: 36.91 | AE33: 22.89 | AF33: 6.21 | AG33: 22.89 | AH33: 8.22 | AI33: 22.89 | AJ33: -999 | AK33: -999 | AL33: -999 | AM33: -999 | AN33: -999 | AO33: -999 | AP33: -999 | AQ33: -999 | AR33: -999 | AS33: -999 | AT33: -999 | AU33: -999 | AV33: -999 | AW33: -999 | AX33: -999 | AY33: -999 | AZ33: -999
A34: 1 | B34: Tres Palmas 05m | C34: Rincón | D34: TRES05 | E34: West | F34: W | G34: 18.35072 | H34: -67.2669 | I34: 5 | J34: 6 | K34: 15 | L34: 2023 | M34: 6/15/2023 | N34: Orlando | O34: Juanita | P34: Adiana | Q34: -999 | R34: 0.42083333 | S34: 0.43472222 | T34: -999 | U34: -999 | V34: -999 | W34: -999 | X34: -999 | Y34: -999 | Z34: -999 | AA34: -999 | AB34: -999 | AC34: -999 | AD34: -999 | AE34: -999 | AF34: -999 | AG34: -999 | AH34: -999 | AI34: -999 | AJ34: 3 | AK34: 3 | AL34: 3 | AM34: 1 | AN34: 1 | AO34: 2.5 | AP34: 143 | AQ34: 142 | AR34: 73 | AS34: 74 | AT34: 35 | AU34: 36 | AV34: 38 | AW34: 35 | AX34: 52 | AY34: 58 | AZ34: 27
A35: 1 | B35: Tres Palmas 10m | C35: Rincón | D35: TRES10 | E35: West | F35: W | G35: 18.34732 | H35: -67.27 | I35: 10 | J35: 6 | K35: 15 | L35: 2023 | M35: 6/15/2023 | N35: Orlando | O35: Juanita | P35: Adiana | Q35: -999 | R35: 0.46944444 | S35: 0.48402778 | T35: -999 | U35: -999 | V35: -999 | W35: -999 | X35: -999 | Y35: -999 | Z35: -999 | AA35: -999 | AB35: -999 | AC35: -999 | AD35: -999 | AE35: -999 | AF35: -999 | AG35: -999 | AH35: -999 | AI35: -999 | AJ35: 9.5 | AK35: 9.5 | AL35: 9.5 | AM35: 1 | AN35: 1 | AO35: 9 | AP35: 138 | AQ35: 139 | AR35: 70 | AS35: 69 | AT35: 33 | AU35: 34 | AV35: 36 | AW35: 33 | AX35: 50 | AY35: 56 | AZ35: 30
A36: 1 | B36: Tres Palmas 20m | C36: Rincón | D36: TRES20 | E36: West | F36: W | G36: 18.34652 | H36: -67.2712 | I36: 20 | J36: 6 | K36: 15 | L36: 2023 | M36: 6/15/2023 | N36: Orlando | O36: Juanita | P36: Adiana | Q36: -999 | R36: 0.44305556 | S36: 0.46111111 | T36: -999 | U36: -999 | V36: -999 | W36: -999 | X36: -999 | Y36: -999 | Z36: -999 | AA36: -999 | AB36: -999 | AC36: -999 | AD36: -999 | AE36: -999 | AF36: -999 | AG36: -999 | AH36: -999 | AI36: -999 | AJ36: 16 | AK36: 16 | AL36: 16 | AM36: 0 | AN36: 1 | AO36: 15.5 | AP36: 141 | AQ36: 140 | AR36: 72 | AS36: 71 | AT36: 34 | AU36: 35 | AV36: 37 | AW36: 34 | AX36: 51 | AY36: 57 | AZ36: 28
A37: 1 | B37: Cabezas de San Juan 5m | C37: Fajardo | D37: CABE05 | E37: North/Northeast | F37: E | G37: 18.38544 | H37: -65.6297 | I37: 5 | J37: 6 | K37: 21 | L37: 2023 | M37: 6/21/2023 | N37: Alonso | O37: Irais | P37: Leira | Q37: Manuel | R37: 0.62847222 | S37: 0.64375 | T37: 29.04 | U37: 0.77 | V37: 37.73 | W37: 0.77 | X37: 6.37 | Y37: 0.77 | Z37: 8.06 | AA37: 0.77 | AB37: 28.64 | AC37: 5.01 | AD37: 37.74 | AE37: 5.28 | AF37: 6.52 | AG37: 5.31 | AH37: 8.23 | AI37: 5.31 | AJ37: 5.5 | AK37: 5.5 | AL37: 5.5 | AM37: 1 | AN37: 1 | AO37: 5 | AP37: 150 | AQ37: 151 | AR37: 81 | AS37: 82 | AT37: 39 | AU37: 41 | AV37: 42 | AW37: 39 | AX37: 56 | AY37: 62 | AZ37: 34
A38: 1 | B38: Cayo Diablo 5m | C38: Fajardo | D38: DIAB05 | E38: North/Northeast | F38: E | G38: 18.36033 | H38: -65.5309 | I38: 5 | J38: 6 | K38: 21 | L38: 2023 | M38: 6/21/2023 | N38: Alonso | O38: Irais | P38: Leira | Q38: Manuel | R38: 0.50833333 | S38: 0.5375 | T38: 29.55 | U38: 1.02 | V38: 37.68 | W38: 1.04 | X38: 8.24 | Y38: 1.05 | Z38: 8.07 | AA38: 1.06 | AB38: 29.31 | AC38: 7.25 | AD38: 37.57 | AE38: 6.71 | AF38: 6.72 | AG38: 6.7 | AH38: 8.24 | AI38: 6.74 | AJ38: 7 | AK38: 7 | AL38: 7 | AM38: 1 | AN38: 1 | AO38: 6.5 | AP38: 132 | AQ38: 133 | AR38: 63 | AS38: 64 | AT38: 25 | AU38: 30 | AV38: 33 | AW38: 30 | AX38: 48 | AY38: 54 | AZ38: 31
A39: 1 | B39: Palominos 20m | C39: Fajardo | D39: PALN20 | E39: North/Northeast | F39: E | G39: 18.35466 | H39: -65.5671 | I39: 20 | J39: 6 | K39: 21 | L39: 2023 | M39: 6/21/2023 | N39: Alonso | O39: Irais | P39: Leira | Q39: Manuel | R39: 0.55555556 | S39: 0.57291667 | T39: 29.42 | U39: 0.74 | V39: 37.61 | W39: 0.75 | X39: 6.3 | Y39: 0.76 | Z39: 8.17 | AA39: 0.71 | AB39: 29.29 | AC39: 12.94 | AD39: 37.52 | AE39: 12.77 | AF39: 6.45 | AG39: 12.75 | AH39: 8.24 | AI39: 12.58 | AJ39: 19 | AK39: 19 | AL39: 19 | AM39: 1 | AN39: 1 | AO39: 13.5 | AP39: 144 | AQ39: 145 | AR39: 75 | AS39: 76 | AT39: 36 | AU39: 37 | AV39: 39 | AW39: 36 | AX39: 53 | AY39: 59 | AZ39: 32
A40: 1 | B40: Palominitos 10m | C40: Fajardo | D40: PALT10 | E40: North/Northeast | F40: E | G40: 18.33537 | H40: -65.5656 | I40: 10 | J40: 6 | K40: 21 | L40: 2023 | M40: 6/21/2023 | N40: Alonso | O40: Irais | P40: Leira | Q40: Manuel | R40: 0.58680556 | S40: 0.60277778 | T40: 30.25 | U40: 0.76 | V40: 37.61 | W40: 0.77 | X40: 7.51 | Y40: 0.76 | Z40: 8.15 | AA40: 0.74 | AB40: 30.34 | AC40: 1.83 | AD40: 37.77 | AE40: 1.84 | AF40: 7.51 | AG40: 1.82 | AH40: 8.26 | AI40: 1.81 | AJ40: 3 | AK40: 3 | AL40: 3 | AM40: 1 | AN40: 1 | AO40: 2.5 | AP40: 146 | AQ40: 147 | AR40: 78 | AS40: 77 | AT40: 37 | AU40: 38 | AV40: 40 | AW40: 37 | AX40: 54 | AY40: 60 | AZ40: 33
...

Sheet Table 2_Sampling_Stats
A1: Site_Name | B1: Site_Code | C1: Date | D1: Data_Points | E1: Percentage
A2: Boya Vieja 20m | B2: BOYA20 | C2: 5/12/2023 | D2: =32-COUNTIF('Raw Data'!T2:AZ2,"-999.00") -> 32 | E2: =D2/32 -> 1
A3: Efras Wall 20m | B3: EWAL20 | C3: 5/18/2023 | D3: =32-COUNTIF('Raw Data'!T3:AZ3,"-999.00") -> 32 | E3: =D3/32 -> 1
A4: Media Luna 5m | B4: MLUN05 | C4: 5/18/2023 | D4: =32-COUNTIF('Raw Data'!T4:AZ4,"-999.00") -> 32 | E4: =D4/32 -> 1
A5: Media Luna 10m | B5: MLUN10 | C5: 5/18/2023 | D5: =32-COUNTIF('Raw Data'!T5:AZ5,"-999.00") -> 32 | E5: =D5/32 -> 1
A6: Gallardo 5m | B6: GALL05 | C6: 5/19/2023 | D6: =32-COUNTIF('Raw Data'!T6:AZ6,"-999.00") -> 32 | E6: =D6/32 -> 1
A7: Resuellos 10m | B7: RESU10 | C7: 5/19/2023 | D7: =32-COUNTIF('Raw Data'!T7:AZ7,"-999.00") -> 32 | E7: =D7/32 -> 1
A8: Maria Langa 10m | B8: MLAN10 | C8: 5/22/2023 | D8: =32-COUNTIF('Raw Data'!T8:AZ8,"-999.00") -> 32 | E8: =D8/32 -> 1
A9: Maria Langa 20m | B9: MLAN20 | C9: 5/22/2023 | D9: =32-COUNTIF('Raw Data'!T9:AZ9,"-999.00") -> 32 | E9: =D9/32 -> 1
A10: Guanajibo 20m | B10: GUAN20 | C10: 5/24/2023 | D10: =32-COUNTIF('Raw Data'!T10:AZ10,"-999.00") -> 32 | E10: =D10/32 -> 1
A11: Manchas Exteriores 10m | B11: MEXT10 | C11: 5/24/2023 | D11: =32-COUNTIF('Raw Data'!T11:AZ11,"-999.00") -> 32 | E11: =D11/32 -> 1
A12: Manchas Exteriores 20m | B12: MEXT20 | C12: 5/24/2023 | D12: =32-COUNTIF('Raw Data'!T12:AZ12,"-999.00") -> 32 | E12: =D12/32 -> 1
A13: El Negro 5m | B13: NEGR05 | C13: 5/24/2023 | D13: =32-COUNTIF('Raw Data'!T13:AZ13,"-999.00") -> 32 | E13: =D13/32 -> 1
... A51: Cibuco 10m | B51: CIBU10-R | C51: 6/29/2023 | D51: =32-COUNTIF('Raw Data'!T51:AZ51,"-999.00") -> 24 | E51: =D51/32 -> 0.75

Sheet Sampling_Stats_Summary
B1: Total | C1: Percentage
A2: Max_Data_Point | B2: =MAX('Table 2_Sampling_Stats'!D2:D51) -> 32 | C2: =B2/32 -> 1
A3: Min_Data_Point | B3: =MIN('Table 2_Sampling_Stats'!D2:D51) -> 15 | C3: =B3/B2 -> 0.46875
A4: Count_of_100% | B4: =COUNTIF('Table 2_Sampling_Stats'!E2:E51,"100.00%") -> 39 | C4: =B4/B16 -> 0.82978723
A5: Average | B5: =AVERAGE('Table 2_Sampling_Stats'!D2:D51) -> 28.74 | C5: =B5/B2 -> 0.898125
A6: Std_Dev | B6: =STDEV('Table 2_Sampling_Stats'!D2:D51) -> 6.3881587
A7: Std_Err | B7: =B6/SQRT(COUNTA('Table 2_Sampling_Stats'!D2:D51)) -> 0.90342207
A8: Unique 1 | B8: =IFERROR(__xludf.DUMMYFUNCTION("UNIQUE('Table 2_Sampling_Stats'!D2:D51)"),"#REF!") -> #REF!
A9: Unique 2
A10: Unique 3
A11: Count of Unique 1+3 | B11: =COUNTIF('Table 2_Sampling_Stats'!$E$2:$E$51,B8)+3 -> 3 | C11: =B11/$B$16 -> 0.063829787
A12: Count of Unique 2-3 | B12: =COUNTIF('Table 2_Sampling_Stats'!$E$2:$E$51,B9)-6 -> -6 | C12: =B12/$B$16 -> -0.12765957
A13: Count of Unique 3 | B13: =COUNTIF('Table 2_Sampling_Stats'!$E$2:$E$51,B10) -> 0 | C13: =B13/$B$16 -> 0
A14: Total | B14: =SUM(B11:B13) -> -3
A15: Duplicates | B15: 3
A16: Total - duplicates | B16: =47 -> 47 | C16: =B16/B16 -> 1

Sheet PRCRMP_dates_vs_CCRI
A1: Station | B1: DNER_date | C1: CCRI_date | D1: Difference _days | E1: Difference_weeks
A2: AURO05 | C2: 45071
A3: BOTE15 | B3: 45092 | C3: 45091 | D3: 1 | E3: 1
A4: BOTE20 | B4: 45092 | C4: 45091 | D4: 1 | E4: 1
A5: BOYA20 | C5: 45058
A6: CABE05 | B6: 45099 | C6: 45098 | D6: 1 | E6: 1
A7: CANJ15 | B7: 45097 | C7: 45103 | D7: 6 | E7: 1
A8: CANO30 | B8: 45091 | C8: 45091 | D8: 0 | E8: 1
A9: CARI10 | C9: 45089
A10: CDMU10 | C10: 45089
A11: CIBU10 | B11: 45083 | C11: 45106 | D11: 23 | E11: 3
A12: CORA10 | C12: 45071
A13: CROS10 | B13: 45098 | C13: 45104 | D13: 6 | E13: 1
A14: DAKI20 | B14: 45098 | C14: 45104 | D14: 6 | E14: 1
A15: DERR20 | C15: 45089
A16: DIAB05 | B16: 45096 | C16: 45098 | D16: 2 | E16: 1
A17: DOMI05 | B17: 45083 | C17: 45105 | D17: 22 | E17: 3
A18: ESPE10 | B18: 45097 | C18: 45103 | D18: 6 | E18: 1
A19: EWAL20 | C19: 45064
A20: GALL05 | C20: 45065
A21: GUAN20 | C21: 45070
A22: LPEN05 | B22: 45098 | C22: 45104 | D22: 6 | E22: 1
A23: MEXT10 | C23: 45070
A24: MEXT20 | C24: 45070
A25: MLAN05 | C25: 45071
A26: MLAN10 | C26: 45068
A27: MLAN20 | C27: 45068
A28: MLUN05 | C28: 45064
A29: MLUN10 | C29: 45064
A30: NEGR05 | C30: 45070
A31: NEGR10 | C31: 45070
A32: PALN20 | B32: 45096 | C32: 45098 | D32: 2 | E32: 1
A33: PALT10 | B33: 45096 | C33: 45098 | D33: 2 | E33: 1
A34: RATO05 | C34: 45089
A35: RESU10 | C35: 45065
A36: RODR05 | C36: 45070
A37: SECO30 | B37: 45097 | C37: 45103 | D37: 6 | E37: 1
A38: TOUR10 | B38: 45008 | C38: 45070 | D38: 62 | E38: 8
A39: TOUR20 | B39: 45008 | C39: 45070 | D39: 62 | E39: 8
A40: TOUR30 | B40: 45007 | C40: 45070 | D40: 63 | E40: 8
...

Sheet PRCRMP_dates_CCRI_stats
B1: Alongside_DNER | C1: %_alongside_DNER | D1: Of_Global_%
A2: 1 week | B2: 16 | C2: 0.7619 | D2: 0.381
A3: 3 weeks | B3: 2 | C3: 0.0952 | D3: 0.0476
A4: >3 weeks | B4: 3 | C4: 0.1429 | D4: 0.0714
A5: Total | B5: 21 | C5: 1 | D5: 0.5

Sheet HydroLab Stats
A1: Data_Type | B1: Calculations | C1: Time_In | D1: Time_Out | E1: Surface_Temp_(C | F1: Surface_Temp_Depth_m | G1: Surface_Temp_Site | H1: Surface_Sal_psu | I1: Surface_Sal_Depth_m | J1: Surface_Sal_Site | K1: Surface_DO_mg_L | L1: Surface_DO_Depth_m | M1: Surface_DO_Site | N1: Surface_pH | O1: Surface_pH_Depth_m | P1: Surface_pH_Site | Q1: Bottom_Temp_C | R1: Bottom_Temp_Depth_m | S1: Bottom_Temp_Site | T1: Bottom_Sal_psu | U1: Bottom_Sal_Depth_m | V1: Bottom_Sal_Site | W1: Bottom_DO_mg_L | X1: Bottom_DO_Depth_m | Y1: Bottom_DO_Sites | Z1: Bottom_pH | AA1: Bottom_pH_Depth_m | AB1: Bottom_pH_Sites | AC1: Secchi_Depth_1_m | AD1: Secchi_Depth_2_m | AE1: Secchi_Depth_3_m | AF1: Surface_Van_Dorn_Depth_m | AG1: Bottom_Van_Dorn_Depth_m | AH1: Secchi_1_Site | AI1: Secchi_2_Site | AJ1: Secchi_3_Site
A2: Global | B2: Max Total | C2: 0.62847222 | D2: 0.64375 | E2: 30.41 | F2: 0.82 | G2: RATO05 | H2: 38.03 | I2: 1.05 | J2: LPEN05 | K2: 8.24 | L2: 1.05 | M2: LPEN05 | N2: 8.48 | O2: 0.69 | P2: CORA10 | Q2: 30.34 | R2: 1.83 | S2: PALT10 | T2: 38.03 | U2: 4.49 | V2: LPEN05 | W2: 7.51 | X2: 1.82 | Y2: PALT10 | Z2: 8.4 | AA2: 3.79 | AB2: AURO05 | AC2: 31 | AD2: 31 | AE2: 31 | AF2: 1 | AG2: 29.5 | AH2: SECO30 | AI2: SECO30 | AJ2: SECO30
A3: Global | B3: Min Total | C3: 0.29166667 | D3: 0.32013889 | E3: 27.71 | F3: 1 | G3: DIAB05 | H3: 33.37 | I3: 2.4 | J3: BOYA20 | K3: 4.97 | L3: 0.57 | M3: MLAN05 | N3: 6.42 | O3: 1.08 | P3: DOMI05 | Q3: 27.02 | R3: 3 | S3: CIBU10 | T3: 33.19 | U3: 21.65 | V3: BOYA20 | W3: 4 | X3: 3 | Y3: CIBU10 | Z3: 7.88 | AA3: 3.87 | AB3: DOMI05 | AC3: 3 | AD3: 2.75 | AE3: 2.25 | AF3: 0.5 | AG3: 2.5 | AH3: PALT10 | AI3: MLAN20 | AJ3: MLAN10
A4: Global | B4: Average | C4: 0.42882683 | D4: 0.45067967 | E4: 29.139318 | H4: 37.132381 | K4: 6.1652273 | N4: 8.0916667 | Q4: 29.057273 | T4: 37.202857 | W4: 6.0822727 | Z4: 8.225 | AC4: 9.8211111 | AD4: 9.8488889 | AE4: 9.8655556 | AF4: 0.87234043 | AG4: 10.643617
A5: Global | B5: Std Dev | C5: 0.087045306 | D5: 0.08403757 | E5: 0.55110206 | H5: 0.78847741 | K5: 0.53146786 | N5: 0.30893931 | Q5: 0.5859096 | T5: 0.69828461 | W5: 0.54146598 | Z5: 0.11043705 | AC5: 6.5852149 | AD5: 6.5942252 | AE5: 6.6417055 | AF5: 0.22037727 | AG5: 7.0508141
A6: Global | B6: Std Err | C6: 0.012696863 | D6: 0.012258139 | E6: 0.083081761 | H6: 0.12166471 | K6: 0.080121795 | N6: 0.04767037 | Q6: 0.088329196 | T6: 0.10774765 | W6: 0.081629068 | Z6: 0.017040806 | AC6: 0.98166588 | AD6: 0.98300905 | AE6: 0.99008701 | AF6: 0.032145329 | AG6: 1.0284669
A7: Cleaned | B7: Max | C7: 0.62847222 | D7: 0.64375 | E7: 30.41 | F7: 0.82 | G7: RATO05 | H7: 38.03 | I7: 1.05 | J7: LPEN05 | K7: 8.24 | L7: 1.05 | M7: DIAB05 | N7: 8.48 | O7: 0.69 | P7: CORA10 | Q7: 30.34 | R7: 1.83 | S7: PALT10 | T7: 38.03 | U7: 4.49 | V7: LPEN05 | W7: 7.51 | X7: 1.82 | Y7: PALT10 | Z7: 8.4 | AA7: 3.79 | AB7: AURO05 | AC7: 31 | AD7: 31 | AE7: 31 | AF7: 1 | AG7: 29.5 | AH7: SECO30 | AI7: SECO30 | AJ7: SECO30
A8: Cleaned | B8: Min | C8: 0.30902778 | D8: 0.33402778 | E8: 28.07 | F8: 0.84 | G8: MLAN20 | H8: 34.78 | I8: 0.83 | J8: MLAN20 | K8: 4.97 | L8: 0.57 | M8: MLAN05 | N8: 6.42 | O8: 1.08 | P8: DOMI05 | Q8: 28.06 | R8: 18.5 | S8: EWAL20 | T8: 36.9 | U8: 9.43 | V8: CORA10 | W8: 5.28 | X8: 9.08 | Y8: MLAN10 | Z8: 7.88 | AA8: 3.87 | AB8: DOMI05 | AC8: 3 | AD8: 2.75 | AE8: 2.5 | AF8: 0.5 | AG8: 2.5 | AH8: PALT10 | AI8: MLAN20 | AJ8: MLAN20
A9: Cleaned | B9: Average | C9: 0.43557449 | D9: 0.45658144 | E9: 29.199512 | H9: 37.224146 | K9: 6.1495122 | N9: 8.0909756 | Q9: 29.12439 | T9: 37.300732 | W9: 6.0953659 | Z9: 8.2260976 | AC9: 9.9761364 | AD9: 10.010227 | AE9: 10.038636 | AF9: 0.86363636 | AG9: 10.721591
A10: Cleaned | B10: Std Dev | C10: 0.085437326 | D10: 0.082652729 | E10: 0.50718809 | H10: 0.52413727 | K10: 0.54242489 | N10: 0.31274434 | Q10: 0.50413316 | T10: 0.29562975 | W10: 0.4158912 | Z10: 0.11157684 | AC10: 6.5777593 | AD10: 6.5800048 | AE10: 6.6150363 | AF10: 0.22525532 | AG10: 7.196821
A11: Cleaned | B11: Std Err | C11: 0.012880162 | D11: 0.012460368 | E11: 0.079209472 | H11: 0.081856489 | K11: 0.084712535 | N11: 0.048842461 | Q11: 0.078732372 | T11: 0.046169611 | W11: 0.064951293 | Z11: 0.017425374 | AC11: 0.99163452 | AD11: 0.99197304 | AE11: 0.99725424 | AF11: 0.033958517 | AG11: 1.0849616
A15: Cleaned = No BOYA20, CIBU10 or CIBU10-R

Sheet Transposed HL Stats
A1: Cleaned_=_No_BOYA20,_CIBU10_or_CIBU10-R
A3: Data_Type | B3: Global | C3: Global | D3: Global | E3: Global | F3: Global | G3: Global | H3: Global | I3: Cleaned | J3: Cleaned | K3: Cleaned | L3: Cleaned | M3: Cleaned | N3: Cleaned | O3: Cleaned
A4: Calculations | B4: Min_Total | C4: Site_Code | D4: Max_Total | E4: Site_Code | F4: Average | G4: Std_Dev | H4: Std_Err | I4: Min | J4: Site_Code | K4: Max | L4: Site_Code | M4: Average | N4: Std_Dev | O4: Std_Err
A5: Time_In | B5: 0.29166667 | D5: 0.62847222 | F5: 0.42882683 | G5: 0.087045306 | H5: 0.012696863 | I5: 0.30902778 | K5: 0.62847222 | M5: 0.43557449 | N5: 0.085437326 | O5: 0.012880162
A6: Time_Out | B6: 0.32013889 | D6: 0.64375 | F6: 0.45067967 | G6: 0.08403757 | H6: 0.012258139 | I6: 0.33402778 | K6: 0.64375 | M6: 0.45658144 | N6: 0.082652729 | O6: 0.012460368
A7: Surface_Temp_C | B7: 27.71 | C7: DIAB05 | D7: 30.41 | E7: RATO05 | F7: 29.139318 | G7: 0.55110206 | H7: 0.083081761 | I7: 28.07 | J7: MLAN20 | K7: 30.41 | L7: RATO05 | M7: 29.199512 | N7: 0.50718809 | O7: 0.079209472
A8: Surface_Temp_Depth_m | B8: 1 | D8: 0.82 | I8: 0.84 | K8: 0.82
A9: Surface_Sal_psu | B9: 33.37 | C9: BOYA20 | D9: 38.03 | E9: LPEN05 | F9: 37.132381 | G9: 0.78847741 | H9: 0.12166471 | I9: 34.78 | J9: MLAN20 | K9: 38.03 | L9: LPEN05 | M9: 37.224146 | N9: 0.52413727 | O9: 0.081856489
A10: Surface_Sal_Depth_m | B10: 2.4 | D10: 1.05 | I10: 0.83 | K10: 1.05
A11: Surface_DO_mg_L | B11: 4.97 | C11: MLAN05 | D11: 8.24 | E11: LPEN05 | F11: 6.1652273 | G11: 0.53146786 | H11: 0.080121795 | I11: 4.97 | J11: MLAN05 | K11: 8.24 | L11: DIAB05 | M11: 6.1495122 | N11: 0.54242489 | O11: 0.084712535
A12: Surface_DO_Depth_m | B12: 0.57 | D12: 1.05 | I12: 0.57 | K12: 1.05
A13: Surface_pH_pH | B13: 6.42 | C13: DOMI05 | D13: 8.48 | E13: CORA10 | F13: 8.0916667 | G13: 0.30893931 | H13: 0.04767037 | I13: 6.42 | J13: DOMI05 | K13: 8.48 | L13: CORA10 | M13: 8.0909756 | N13: 0.31274434 | O13: 0.048842461
A14: Surface_pH_Depth_m | B14: 1.08 | D14: 0.69 | I14: 1.08 | K14: 0.69
A15: Bottom_Temp_C | B15: 27.02 | C15: CIBU10 | D15: 30.34 | E15: PALT10 | F15: 29.057273 | G15: 0.5859096 | H15: 0.088329196 | I15: 28.06 | J15: EWAL20 | K15: 30.34 | L15: PALT10 | M15: 29.12439 | N15: 0.50413316 | O15: 0.078732372
A16: Bottom_Temp_Depth_m | B16: 3 | D16: 1.83 | I16: 18.5 | K16: 1.83
A17: Bottom_Sal_psu | B17: 33.19 | C17: BOYA20 | D17: 38.03 | E17: LPEN05 | F17: 37.202857 | G17: 0.69828461 | H17: 0.10774765 | I17: 36.9 | J17: CORA10 | K17: 38.03 | L17: LPEN05 | M17: 37.300732 | N17: 0.29562975 | O17: 0.046169611
A18: Bottom_Sal_Depth_m | B18: 21.65 | D18: 4.49 | I18: 9.43 | K18: 4.49
A19: Bottom_DO_mg_L | B19: 4 | C19: CIBU10 | D19: 7.51 | E19: PALT10 | F19: 6.0822727 | G19: 0.54146598 | H19: 0.081629068 | I19: 5.28 | J19: MLAN10 | K19: 7.51 | L19: PALT10 | M19: 6.0953659 | N19: 0.4158912 | O19: 0.064951293
A20: Bottom_DO_Depth_m | B20: 3 | D20: 1.82 | I20: 9.08 | K20: 1.82
A21: Bottom_pH_pH | B21: 7.88 | D21: 8.4 | F21: 8.225 | G21: 0.11043705 | H21: 0.017040806 | I21: 7.88 | K21: 8.4 | M21: 8.2260976 | N21: 0.11157684 | O21: 0.017425374
A22: Bottom_pH_Depth_m | B22: 3.87 | C22: DOMI05 | D22: 3.79 | E22: AURO05 | I22: 3.87 | J22: DOMI05 | K22: 3.79 | L22: AURO05
A23: Secchi_Depth_1_m | B23: 3 | C23: PALT10 | D23: 31 | E23: SECO30 | F23: 9.8211111 | G23: 6.5852149 | H23: 0.98166588 | I23: 3 | J23: PALT10 | K23: 31 | L23: SECO30 | M23: 9.9761364 | N23: 6.5777593 | O23: 0.99163452
A24: Secchi_Depth_2_m | B24: 2.75 | C24: MLAN20 | D24: 31 | E24: SECO30 | F24: 9.8488889 | G24: 6.5942252 | H24: 0.98300905 | I24: 2.75 | J24: MLAN20 | K24: 31 | L24: SECO30 | M24: 10.010227 | N24: 6.5800048 | O24: 0.99197304
A25: Secchi_Depth_3_m | B25: 2.25 | C25: MLAN10 | D25: 31 | E25: SECO30 | F25: 9.8655556 | G25: 6.6417055 | H25: 0.99008701 | I25: 2.5 | J25: MLAN20 | K25: 31 | L25: SECO30 | M25: 10.038636 | N25: 6.6150363 | O25: 0.99725424
A26: Surface_Van_Dorn_Depth_m | B26: 0.5 | D26: 1 | F26: 0.87234043 | G26: 0.22037727 | H26: 0.032145329 | I26: 0.5 | K26: 1 | M26: 0.86363636 | N26: 0.22525532 | O26: 0.033958517
A27: Bottom_Van_Dorn_Depth_m | B27: 2.5 | D27: 29.5 | F27: 10.643617 | G27: 7.0508141 | H27: 1.0284669 | I27: 2.5 | K27: 29.5 | M27: 10.721591 | N27: 7.196821 | O27: 1.0849616

Sheet QAQC
A1: Site_Code | B1: DERR20 | C1: DERR20-R | D1: QA/QC | E1: Accept | F1: RATO05 | G1: RATO05-R | H1: QA/QC | I1: Accept | J1: CANJ15 | K1: CANJ15-R | L1: QA/QC | M1: Accept | N1: DOMI05 | O1: DOMI05-R | P1: QA/QC | Q1: Accept | R1: CIBU10 | S1: CIBU10-R | T1: QA/QC | U1: Accept
A2: Date | B2: 45089 | C2: 45089 | F2: 45089 | G2: 45089 | J2: 45103 | K2: 45103 | N2: 45105 | O2: 45105 | R2: 45106 | S2: 45106
A3: Surface_Temp_C | B3: 29.63 | C3: 29.64 | D3: =ABS(C3-B3) -> 0.01 | E3: =IF(D3>0.1,"No", "Yes") -> Yes | F3: 30.41 | H3: =ABS(G3-F3) -> 30.41 | I3: =IF(H3>0.1,"No", "Yes") -> No | J3: 29.51 | L3: =ABS(K3-J3) -> 29.51 | M3: =IF(L3>0.1,"No", "Yes") -> No | N3: 29.56 | P3: =ABS(O3-N3) -> 29.56 | Q3: =IF(P3>0.1,"No", "Yes") -> No | R3: 27.71 | S3: 28.48 | T3: =ABS(S3-R3) -> 0.77 | U3: =IF(T3>0.1,"No", "Yes") -> No
A4: Surface_Temp_Depth_m | B4: 0.71 | C4: 0.53 | D4: =ABS(C4-B4) -> 0.18 | F4: 0.82 | H4: =ABS(G4-F4) -> 0.82 | J4: 1.21 | L4: =ABS(K4-J4) -> 1.21 | N4: 1.08 | P4: =ABS(O4-N4) -> 1.08 | R4: 1 | S4: 1 | T4: =ABS(S4-R4) -> 0
A5: Surface_Sal_psu | B5: 37.07 | C5: 37.13 | D5: =ABS(C5-B5) -> 0.06 | E5: =IF(D5>0.5,"No", "Yes") -> Yes | F5: 37.12 | H5: =ABS(G5-F5) -> 37.12 | I5: =IF(H5>0.5,"No", "Yes") -> No | J5: 37.25 | L5: =ABS(K5-J5) -> 37.25 | M5: =IF(L5>0.5,"No", "Yes") -> No | N5: 37.87 | P5: =ABS(O5-N5) -> 37.87 | Q5: =IF(P5>0.5,"No", "Yes") -> No | T5: =ABS(S5-R5) -> 0 | U5: =IF(T5>0.5,"No", "Yes") -> Yes
A6: Surface_Sal_Depth_m | B6: 0.74 | C6: 0.58 | D6: =ABS(C6-B6) -> 0.16 | F6: 0.8 | H6: =ABS(G6-F6) -> 0.8 | J6: 1.21 | L6: =ABS(K6-J6) -> 1.21 | N6: 1.08 | P6: =ABS(O6-N6) -> 1.08 | T6: =ABS(S6-R6) -> 0
A7: Surface_DO_mg_L | B7: 6.44 | C7: 6.52 | D7: =ABS(C7-B7) -> 0.08 | E7: =IF(D7>0.2,"No", "Yes") -> Yes | F7: 6.41 | H7: =ABS(G7-F7) -> 6.41 | I7: =IF(H7>0.2,"No", "Yes") -> No | J7: 6.31 | L7: =ABS(K7-J7) -> 6.31 | M7: =IF(L7>0.2,"No", "Yes") -> No | N7: 5.69 | P7: =ABS(O7-N7) -> 5.69 | Q7: =IF(P7>0.2,"No", "Yes") -> No | R7: 6.58 | S7: 5.99 | T7: =ABS(S7-R7) -> 0.59 | U7: =IF(T7>0.2,"No", "Yes") -> No
A8: Surface_DO_Depth_m | B8: 0.73 | C8: 0.6 | D8: =ABS(C8-B8) -> 0.13 | F8: 0.77 | H8: =ABS(G8-F8) -> 0.77 | J8: 1.2 | L8: =ABS(K8-J8) -> 1.2 | N8: 1.08 | P8: =ABS(O8-N8) -> 1.08 | R8: 1 | S8: 1 | T8: =ABS(S8-R8) -> 0
A9: Surface_pH | B9: 8.14 | C9: 8.13 | D9: =ABS(C9-B9) -> 0.01 | E9: =IF(D9>0.1,"No", "Yes") -> Yes | F9: 8.01 | H9: =ABS(G9-F9) -> 8.01 | I9: =IF(H9>0.1,"No", "Yes") -> No | J9: 8.24 | L9: =ABS(K9-J9) -> 8.24 | M9: =IF(L9>0.1,"No", "Yes") -> No | N9: 6.42 | P9: =ABS(O9-N9) -> 6.42 | Q9: =IF(P9>0.1,"No", "Yes") -> No | T9: =ABS(S9-R9) -> 0 | U9: =IF(T9>0.1,"No", "Yes") -> Yes
A10: Surface_pH_Depth_m | B10: 0.73 | C10: 0.59 | D10: =ABS(C10-B10) -> 0.14 | F10: 0.79 | H10: =ABS(G10-F10) -> 0.79 | J10: 1.21 | L10: =ABS(K10-J10) -> 1.21 | N10: 1.08 | P10: =ABS(O10-N10) -> 1.08 | T10: =ABS(S10-R10) -> 0
A11: Bottom_Temp_C | B11: 29.54 | C11: 29.54 | D11: =ABS(C11-B11) -> 0 | E11: =IF(D11>0.1,"No", "Yes") -> Yes | F11: 30.27 | H11: =ABS(G11-F11) -> 30.27 | I11: =IF(H11>0.1,"No", "Yes") -> No | J11: 29.45 | L11: =ABS(K11-J11) -> 29.45 | M11: =IF(L11>0.1,"No", "Yes") -> No | N11: 29.52 | P11: =ABS(O11-N11) -> 29.52 | Q11: =IF(P11>0.1,"No", "Yes") -> No | R11: 27.02 | S11: 28.65 | T11: =ABS(S11-R11) -> 1.63 | U11: =IF(T11>0.1,"No", "Yes") -> No
A12: Bottom_Temp_Depth_m | B12: 16.5 | C12: 16.13 | D12: =ABS(C12-B12) -> 0.37 | F12: 4.82 | H12: =ABS(G12-F12) -> 4.82 | J12: 15.26 | L12: =ABS(K12-J12) -> 15.26 | N12: 3.87 | P12: =ABS(O12-N12) -> 3.87 | R12: 3 | S12: 3 | T12: =ABS(S12-R12) -> 0
A13: Bottom_Sal_psu | B13: 37.16 | C13: 37.12 | D13: =ABS(C13-B13) -> 0.04 | E13: =IF(D13>0.5,"No", "Yes") -> Yes | F13: 37.17 | H13: =ABS(G13-F13) -> 37.17 | I13: =IF(H13>0.5,"No", "Yes") -> No | J13: 37.46 | L13: =ABS(K13-J13) -> 37.46 | M13: =IF(L13>0.5,"No", "Yes") -> No | N13: 37.84 | P13: =ABS(O13-N13) -> 37.84 | Q13: =IF(P13>0.5,"No", "Yes") -> No | T13: =ABS(S13-R13) -> 0 | U13: =IF(T13>0.5,"No", "Yes") -> Yes
A14: Bottom_Sal_Depth_m | B14: 17.1 | C14: 16.2 | D14: =ABS(C14-B14) -> 0.9 | F14: 4.85 | H14: =ABS(G14-F14) -> 4.85 | J14: 15.27 | L14: =ABS(K14-J14) -> 15.27 | N14: 3.87 | P14: =ABS(O14-N14) -> 3.87 | T14: =ABS(S14-R14) -> 0
A15: Bottom_DO_mg_L | B15: 6.58 | C15: 6.47 | D15: =ABS(C15-B15) -> 0.11 | E15: =IF(D15>0.2,"No", "Yes") -> Yes | F15: 6.18 | H15: =ABS(G15-F15) -> 6.18 | I15: =IF(H15>0.2,"No", "Yes") -> No | J15: 5.8 | L15: =ABS(K15-J15) -> 5.8 | M15: =IF(L15>0.2,"No", "Yes") -> No | N15: 5.47 | P15: =ABS(O15-N15) -> 5.47 | Q15: =IF(P15>0.2,"No", "Yes") -> No | R15: 7.13 | S15: 4 | T15: =ABS(S15-R15) -> 3.13 | U15: =IF(T15>0.2,"No", "Yes") -> No
A16: Bottom_DO_Depth_m | B16: 16.65 | C16: 16.3 | D16: =ABS(C16-B16) -> 0.35 | F16: 4.84 | H16: =ABS(G16-F16) -> 4.84 | J16: 15.24 | L16: =ABS(K16-J16) -> 15.24 | N16: 3.87 | P16: =ABS(O16-N16) -> 3.87 | R16: 3 | S16: 3 | T16: =ABS(S16-R16) -> 0
A17: Bottom_pH_pH | B17: 8.14 | C17: 8.14 | D17: =ABS(C17-B17) -> 0 | E17: =IF(D17>0.1,"No", "Yes") -> Yes | F17: 8.05 | H17: =ABS(G17-F17) -> 8.05 | I17: =IF(H17>0.1,"No", "Yes") -> No | J17: 8.26 | L17: =ABS(K17-J17) -> 8.26 | M17: =IF(L17>0.1,"No", "Yes") -> No | N17: 7.88 | P17: =ABS(O17-N17) -> 7.88 | Q17: =IF(P17>0.1,"No", "Yes") -> No | T17: =ABS(S17-R17) -> 0 | U17: =IF(T17>0.1,"No", "Yes") -> Yes
A18: Bottom_pH_Depth_m | B18: 16.65 | C18: 16.33 | D18: =ABS(C18-B18) -> 0.32 | F18: 4.82 | H18: =ABS(G18-F18) -> 4.82 | J18: 15.23 | L18: =ABS(K18-J18) -> 15.23 | N18: 3.87 | P18: =ABS(O18-N18) -> 3.87 | T18: =ABS(S18-R18) -> 0
A19: Secchi_Depth_1_m | B19: 13 | C19: 13 | D19: =ABS(C19-B19) -> 0 | E19: =IF(D19>0.2,"No", "Yes") -> Yes | F19: 4 | G19: 4 | H19: =ABS(G19-F19) -> 0 | I19: =IF(H19>0.2,"No", "Yes") -> Yes | J19: 17 | K19: 17 | L19: =ABS(K19-J19) -> 0 | M19: =IF(L19>0.2,"No", "Yes") -> Yes | N19: 3.5 | O19: 3.5 | P19: =ABS(O19-N19) -> 0 | Q19: =IF(P19>0.2,"No", "Yes") -> Yes | R19: 3.5 | S19: 3.5 | T19: =ABS(S19-R19) -> 0 | U19: =IF(T19>0.2,"No", "Yes") -> Yes
A20: Secchi_Depth_2_m | B20: 13 | C20: 13 | D20: =ABS(C20-B20) -> 0 | E20: =IF(D20>0.2,"No", "Yes") -> Yes | F20: 4 | G20: 4 | H20: =ABS(G20-F20) -> 0 | I20: =IF(H20>0.2,"No", "Yes") -> Yes | J20: 17 | K20: 17 | L20: =ABS(K20-J20) -> 0 | M20: =IF(L20>0.2,"No", "Yes") -> Yes | N20: 3.5 | O20: 3.5 | P20: =ABS(O20-N20) -> 0 | Q20: =IF(P20>0.2,"No", "Yes") -> Yes | R20: 3.5 | S20: 3.5 | T20: =ABS(S20-R20) -> 0 | U20: =IF(T20>0.2,"No", "Yes") -> Yes
A21: Secchi_Depth_3_m | B21: 13 | C21: 13 | D21: =ABS(C21-B21) -> 0 | E21: =IF(D21>0.2,"No", "Yes") -> Yes | F21: 4 | G21: 4 | H21: =ABS(G21-F21) -> 0 | I21: =IF(H21>0.2,"No", "Yes") -> Yes | J21: 17 | K21: 17 | L21: =ABS(K21-J21) -> 0 | M21: =IF(L21>0.2,"No", "Yes") -> Yes | N21: 3.5 | O21: 3.5 | P21: =ABS(O21-N21) -> 0 | Q21: =IF(P21>0.2,"No", "Yes") -> Yes | R21: 3.5 | S21: 3.5 | T21: =ABS(S21-R21) -> 0 | U21: =IF(T21>0.2,"No", "Yes") -> Yes
A27: Site_Code | B27: Date | C27: Surface_Temp_C | D27: QA/QC | E27: Surface_Sal_psu | F27: QA/QC | G27: Surface_DO_mg_L | H27: QA/QC | I27: Surface_pH | J27: QA/QC | K27: Bottom_Temp_C | L27: QA/QC | M27: Bottom_Sal_psu | N27: QA/QC | O27: Bottom_DO_mg_L | P27: QA/QC | Q27: Bottom_pH_pH | R27: QA/QC | S27: Secchi_Depth_1_m | T27: QA/QC | U27: Secchi_Depth_2_m | V27: QA/QC | W27: Secchi_Depth_3_m | X27: QA/QC
A28: DERR20 | B28: 45089 | C28: 29.63 | D28: 0.1 | E28: 37.07 | F28: 0.5 | G28: 6.44 | H28: 0.2 | I28: 8.14 | J28: 0.1 | K28: 29.54 | L28: 0.1 | M28: 37.16 | N28: 0.5 | O28: 6.58 | P28: 0.2 | Q28: 8.14 | R28: 0.1 | S28: 13 | T28: 0.2 | U28: 13 | V28: 0.2 | W28: 13 | X28: 0.2
A29: DERR20-R | B29: 45089 | C29: 29.64 | D29: =IF(or(ABS(C28-C29)>D$28,C28=0,C29=0),"no","yes") -> yes | E29: 37.13 | F29: =IF(or(ABS(E28-E29)>F$28,E28=0,E29=0),"no","yes") -> yes | G29: 6.52 | H29: =IF(or(ABS(G28-G29)>H$28,G28=0,G29=0),"no","yes") -> yes | I29: 8.13 | J29: =IF(or(ABS(I28-I29)>J$28,I28=0,I29=0),"no","yes") -> yes | K29: 29.54 | L29: =IF(or(ABS(K28-K29)>L$28,K28=0,K29=0),"no","yes") -> yes | M29: 37.12 | N29: =IF(or(ABS(M28-M29)>N$28,M28=0,M29=0),"no","yes") -> yes | O29: 6.47 | P29: =IF(or(ABS(O28-O29)>P$28,O28=0,O29=0),"no","yes") -> yes | Q29: 8.14 | R29: =IF(or(ABS(Q28-Q29)>R$28,Q28=0,Q29=0),"no","yes") -> yes | S29: 13 | T29: =IF(or(ABS(S28-S29)>T$28,S28=0,S29=0),"no","yes") -> yes | U29: 13 | V29: =IF(or(ABS(U28-U29)>V$28,U28=0,U29=0),"no","yes") -> yes | W29: 13 | X29: =IF(or(ABS(W28-W29)>X$28,W28=0,W29=0),"no","yes") -> yes
A30: RATO05 | B30: 45089 | C30: 30.41 | E30: 37.12 | G30: 6.41 | I30: 8.01 | K30: 30.27 | M30: 37.17 | O30: 6.18 | Q30: 8.05 | S30: 4 | U30: 4 | W30: 4
A31: RATO05-R | B31: 45089 | D31: =IF(or(ABS(C30-C31)>D$28,C30=0,C31=0),"no","yes") -> no | F31: =IF(or(ABS(E30-E31)>F$28,E30=0,E31=0),"no","yes") -> no | H31: =IF(or(ABS(G30-G31)>H$28,G30=0,G31=0),"no","yes") -> no | J31: =IF(or(ABS(I30-I31)>J$28,I30=0,I31=0),"no","yes") -> no | L31: =IF(or(ABS(K30-K31)>L$28,K30=0,K31=0),"no","yes") -> no | N31: =IF(or(ABS(M30-M31)>N$28,M30=0,M31=0),"no","yes") -> no | P31: =IF(or(ABS(O30-O31)>P$28,O30=0,O31=0),"no","yes") -> no | R31: =IF(or(ABS(Q30-Q31)>R$28,Q30=0,Q31=0),"no","yes") -> no | S31: 4 | T31: =IF(or(ABS(S30-S31)>T$28,S30=0,S31=0),"no","yes") -> yes | U31: 4 | V31: =IF(or(ABS(U30-U31)>V$28,U30=0,U31=0),"no","yes") -> yes | W31: 4 | X31: =IF(or(ABS(W30-W31)>X$28,W30=0,W31=0),"no","yes") -> yes
A32: CANJ15 | B32: 45103 | C32: 29.51 | E32: 37.25 | G32: 6.31 | I32: 8.24 | K32: 29.45 | M32: 37.46 | O32: 5.8 | Q32: 8.26 | S32: 17 | U32: 17 | W32: 17
A33: CANJ15-R | B33: 45103 | D33: =IF(or(ABS(C32-C33)>D$28,C32=0,C33=0),"no","yes") -> no | F33: =IF(or(ABS(E32-E33)>F$28,E32=0,E33=0),"no","yes") -> no | H33: =IF(or(ABS(G32-G33)>H$28,G32=0,G33=0),"no","yes") -> no | J33: =IF(or(ABS(I32-I33)>J$28,I32=0,I33=0),"no","yes") -> no | L33: =IF(or(ABS(K32-K33)>L$28,K32=0,K33=0),"no","yes") -> no | N33: =IF(or(ABS(M32-M33)>N$28,M32=0,M33=0),"no","yes") -> no | P33: =IF(or(ABS(O32-O33)>P$28,O32=0,O33=0),"no","yes") -> no | R33: =IF(or(ABS(Q32-Q33)>R$28,Q32=0,Q33=0),"no","yes") -> no | S33: 17 | T33: =IF(or(ABS(S32-S33)>T$28,S32=0,S33=0),"no","yes") -> yes | U33: 17 | V33: =IF(or(ABS(U32-U33)>V$28,U32=0,U33=0),"no","yes") -> yes | W33: 17 | X33: =IF(or(ABS(W32-W33)>X$28,W32=0,W33=0),"no","yes") -> yes
A34: DOMI05 | B34: 45105 | C34: 29.56 | E34: 37.87 | G34: 5.69 | I34: 6.42 | K34: 29.52 | M34: 37.84 | O34: 5.47 | Q34: 7.88 | S34: 3.5 | U34: 3.5 | W34: 3.5
A35: DOMI05-R | B35: 45105 | D35: =IF(or(ABS(C34-C35)>D$28,C34=0,C35=0),"no","yes") -> no | F35: =IF(or(ABS(E34-E35)>F$28,E34=0,E35=0),"no","yes") -> no | H35: =IF(or(ABS(G34-G35)>H$28,G34=0,G35=0),"no","yes") -> no | J35: =IF(or(ABS(I34-I35)>J$28,I34=0,I35=0),"no","yes") -> no | L35: =IF(or(ABS(K34-K35)>L$28,K34=0,K35=0),"no","yes") -> no | N35: =IF(or(ABS(M34-M35)>N$28,M34=0,M35=0),"no","yes") -> no | P35: =IF(or(ABS(O34-O35)>P$28,O34=0,O35=0),"no","yes") -> no | R35: =IF(or(ABS(Q34-Q35)>R$28,Q34=0,Q35=0),"no","yes") -> no | S35: 3.5 | T35: =IF(or(ABS(S34-S35)>T$28,S34=0,S35=0),"no","yes") -> yes | U35: 3.5 | V35: =IF(or(ABS(U34-U35)>V$28,U34=0,U35=0),"no","yes") -> yes | W35: 3.5 | X35: =IF(or(ABS(W34-W35)>X$28,W34=0,W35=0),"no","yes") -> yes
A36: CIBU10 | B36: 45106 | C36: 27.71 | G36: 6.58 | K36: 27.02 | O36: 7.13 | S36: 3.5 | U36: 3.5 | W36: 3.5
A37: CIBU10-R | B37: 45106 | C37: 28.48 | D37: =IF(or(ABS(C36-C37)>D$28,C36=0,C37=0),"no","yes") -> no | F37: =IF(or(ABS(E36-E37)>F$28,E36=0,E37=0),"no","yes") -> no | G37: 5.99 | H37: =IF(or(ABS(G36-G37)>H$28,G36=0,G37=0),"no","yes") -> no | J37: =IF(or(ABS(I36-I37)>J$28,I36=0,I37=0),"no","yes") -> no | K37: 28.65 | L37: =IF(or(ABS(K36-K37)>L$28,K36=0,K37=0),"no","yes") -> no | N37: =IF(or(ABS(M36-M37)>N$28,M36=0,M37=0),"no","yes") -> no | O37: 4 | P37: =IF(or(ABS(O36-O37)>P$28,O36=0,O37=0),"no","yes") -> no | R37: =IF(or(ABS(Q36-Q37)>R$28,Q36=0,Q37=0),"no","yes") -> no | S37: 3.5 | T37: =IF(or(ABS(S36-S37)>T$28,S36=0,S37=0),"no","yes") -> yes | U37: 3.5 | V37: =IF(or(ABS(U36-U37)>V$28,U36=0,U37=0),"no","yes") -> yes | W37: 3.5 | X37: =IF(or(ABS(W36-W37)>X$28,W36=0,W37=0),"no","yes") -> yes
B40: Site_Code | C40: DERR20 | D40: DERR20-R | E40: RATO05 | F40: RATO05-R | G40: CANJ15 | H40: CANJ15-R | I40: DOMI05 | J40: DOMI05-R | K40: CIBU10 | L40: CIBU10-R
B41: Date | C41: 45089 | D41: 45089 | E41: 45089 | F41: 45089 | G41: 45103 | H41: 45103 | I41: 45105 | J41: 45105 | K41: 45106 | L41: 45106
B42: Surface_Temp_C | C42: 29.63 | D42: 29.64 | E42: 30.41 | G42: 29.51 | I42: 29.56 | K42: 27.71 | L42: 28.48
B43: (<0.20) | D43: =IF(or(ABS(C42-D42)>0.2,C42=0,D42=0),"no","yes") -> yes | F43: =IF(or(ABS(E42-F42)>0.2,E42=0,F42=0),"no","yes") -> no | H43: =IF(or(ABS(G42-H42)>0.2,G42=0,H42=0),"no","yes") -> no | J43: =IF(or(ABS(I42-J42)>0.2,I42=0,J42=0),"no","yes") -> no | L43: =IF(or(ABS(K42-L42)>0.2,K42=0,L42=0),"no","yes") -> no
B44: Surface_Sal_psu | C44: 37.07 | D44: 37.13 | E44: 37.12 | G44: 37.25 | I44: 37.87
B45: (<0.20) | D45: =IF(or(ABS(C44-D44)>0.2,C44=0,D44=0),"no","yes") -> yes | F45: =IF(or(ABS(E44-F44)>0.2,E44=0,F44=0),"no","yes") -> no | H45: =IF(or(ABS(G44-H44)>0.2,G44=0,H44=0),"no","yes") -> no | J45: =IF(or(ABS(I44-J44)>0.2,I44=0,J44=0),"no","yes") -> no | L45: =IF(or(ABS(K44-L44)>0.2,K44=0,L44=0),"no","yes") -> no
B46: Surface_DO_mg_L | C46: 6.44 | D46: 6.52 | E46: 6.41 | G46: 6.31 | I46: 5.69 | K46: 6.58 | L46: 5.99
B47: (<0.20) | D47: =IF(or(ABS(C46-D46)>0.2,C46=0,D46=0),"no","yes") -> yes | F47: =IF(or(ABS(E46-F46)>0.2,E46=0,F46=0),"no","yes") -> no | H47: =IF(or(ABS(G46-H46)>0.2,G46=0,H46=0),"no","yes") -> no | J47: =IF(or(ABS(I46-J46)>0.2,I46=0,J46=0),"no","yes") -> no | L47: =IF(or(ABS(K46-L46)>0.2,K46=0,L46=0),"no","yes") -> no
...
