Workbook

Sheet Raw Data
A1: Sampling_Cycle | B1: Site_Name | C1: Location | D1: Site_Code | E1: Region | F1: Zone | G1: Latitude | H1: Longitude | I1: Depth | J1: Month | K1: Day | L1: Year | M1: Date | N1: Captain | O1: Crew_1 | P1: Crew_2 | Q1: Crew_3 | R1: Time_In | S1: Time_Out | T1: Surface_Temp_C | U1: Surface_Temp_Depth_m | V1: Surface_Sal_psu | W1: Surface_Sal_Depth_m | X1: Surface_DO_mg_L | Y1: Surface_DO_Depth_m | Z1: Surface_pH | AA1: Surface_pH_Depth_m | AB1: Bottom_Temp_C | AC1: Bottom_Temp_Depth_m | AD1: Bottom_Sal_psu | AE1: Bottom_Sal_Depth_m | AF1: Bottom_DO_mg_L | AG1: Bottom_DO_Depth_m | AH1: Bottom_pH | AI1: Bottom_pH_Depth_m | AJ1: Secchi_Depth_1_m | AK1: Secchi_Depth_2_m | AL1: Secchi_Depth_3_m | AM1: Secchi_Avg_Depth | AN1: Surface_Van_Dorn_Depth_m | AO1: Bottom_Van_Dorn_Depth_m | AP1: Surface_TA_DIC | AQ1: Bottom_TA_DIC | AR1: Surface_BOD | AS1: Bottom_BOD | AT1: Chl_a | AU1: Turbidity_NTU | AV1: Settleable_Solids | AW1: Total_Suspended_Solids | AX1: POx_NOx | AY1: TKN | AZ1: Enterococcus | BA1: TA/DIC_Surf_R | BB1: TA/DIC_Bttm_R | BC1: Note
A2: 3 | B2: =LOOKUP($D2,Site_Meta!$C$2:$C$43,Site_Meta!A$2:A$43) -> Cayo Aurora 5m | C2: =LOOKUP($D2,Site_Meta!$C$2:$C$43,Site_Meta!B$2:B$43) -> Guanica | D2: AURO05 | E2: =LOOKUP($D2,Site_Meta!$C$2:$C$43,Site_Meta!D$2:D$43) -> Southwest | F2: =LOOKUP($D2,Site_Meta!$C$2:$C$43,Site_Meta!E$2:E$43) -> SW | G2: =LOOKUP($D2,Site_Meta!$C$2:$C$43,Site_Meta!F$2:F$43) -> 17.9369 | H2: =LOOKUP($D2,Site_Meta!$C$2:$C$43,Site_Meta!G$2:G$43) -> -66.8738 | I2: =LOOKUP($D2,Site_Meta!$C$2:$C$43,Site_Meta!H$2:H$43) -> 5 | J2: 1 | K2: 22 | L2: 24 | M2: =CONCATENATE(J2,"/",K2,"/",L2) -> 1/22/24 | N2: Orlando | O2: Manuel | P2: Ana | R2: 0.40625 | S2: 0.44652778 | T2: 27.6 | U2: 0.58 | V2: 35.99 | W2: 0.52 | X2: 6.31 | Y2: 0.48 | Z2: 8.15 | AA2: 0.4 | AB2: 27.61 | AC2: 4.36 | AD2: 36.04 | AE2: 4 | AF2: 6.2 | AG2: 4.12 | AH2: 8.18 | AI2: 4.16 | AJ2: > 4.5 | AK2: > 4.5 | AL2: > 4.5 | AM2: > 4.5 | AN2: 0.5 | AO2: 4 | AP2: 24 | AQ2: 23 | AR2: 25 | AS2: 26 | AT2: 27 | AU2: 28 | AV2: 29 | AW2: 30 | AX2: 31 | AY2: 32 | AZ2: 11 | BA2: 104 | BB2: 105
A3: 3 | B3: =LOOKUP($D3,Site_Meta!$C$2:$C$43,Site_Meta!A$2:A$43) -> Cayo Coral 10m | C3: =LOOKUP($D3,Site_Meta!$C$2:$C$43,Site_Meta!B$2:B$43) -> Guanica | D3: CORA10 | E3: =LOOKUP($D3,Site_Meta!$C$2:$C$43,Site_Meta!D$2:D$43) -> Southwest | F3: =LOOKUP($D3,Site_Meta!$C$2:$C$43,Site_Meta!E$2:E$43) -> SW | G3: =LOOKUP($D3,Site_Meta!$C$2:$C$43,Site_Meta!F$2:F$43) -> 17.9362 | H3: =LOOKUP($D3,Site_Meta!$C$2:$C$43,Site_Meta!G$2:G$43) -> -66.8884 | I3: =LOOKUP($D3,Site_Meta!$C$2:$C$43,Site_Meta!H$2:H$43) -> 10 | J3: 1 | K3: 22 | L3: 24 | M3: =CONCATENATE(J3,"/",K3,"/",L3) -> 1/22/24 | N3: Orlando | O3: Manuel | P3: Ana | R3: 0.45138889 | S3: 0.48194444 | T3: 27.64 | U3: 0.44 | V3: 35.99 | W3: 0.56 | X3: 6.32 | Y3: 0.51 | Z3: 8.16 | AA3: 0.49 | AB3: 27.64 | AC3: 8.52 | AD3: 35.99 | AE3: 8.64 | AF3: 6.25 | AG3: 8.69 | AH3: 8.2 | AI3: 8.72 | AJ3: > 8.5 | AK3: > 8.5 | AL3: > 8.5 | AM3: > 8.5 | AN3: 0.5 | AO3: 8 | AP3: 34 | AQ3: 35 | AR3: 36 | AS3: 37 | AT3: 38 | AU3: 39 | AV3: 40 | AW3: 41 | AX3: 42 | AY3: 43 | AZ3: 33 | BA3: 106 | BB3: 107
A4: 3 | B4: =LOOKUP($D4,Site_Meta!$C$2:$C$43,Site_Meta!A$2:A$43) -> Tourmaline 30m | C4: =LOOKUP($D4,Site_Meta!$C$2:$C$43,Site_Meta!B$2:B$43) -> Cabo Rojo | D4: TOUR30 | E4: =LOOKUP($D4,Site_Meta!$C$2:$C$43,Site_Meta!D$2:D$43) -> West | F4: =LOOKUP($D4,Site_Meta!$C$2:$C$43,Site_Meta!E$2:E$43) -> W | G4: =LOOKUP($D4,Site_Meta!$C$2:$C$43,Site_Meta!F$2:F$43) -> 18.16637 | H4: =LOOKUP($D4,Site_Meta!$C$2:$C$43,Site_Meta!G$2:G$43) -> -67.2763 | I4: =LOOKUP($D4,Site_Meta!$C$2:$C$43,Site_Meta!H$2:H$43) -> 30 | J4: 1 | K4: 23 | L4: 24 | M4: =CONCATENATE(J4,"/",K4,"/",L4) -> 1/23/24 | N4: Orlando | O4: Manuel | P4: Catherine | R4: 0.33472222 | S4: 0.36111111 | T4: 27.65 | U4: 0.5 | V4: 36.26 | W4: 0.52 | X4: 6.44 | Y4: 0.43 | Z4: 8.17 | AA4: 0.52 | AB4: 27.31 | AC4: 23.12 | AD4: 36.58 | AE4: 23.27 | AF4: 6.25 | AG4: 23.46 | AH4: 8.2 | AI4: 23.48 | AJ4: 16.5 | AK4: 17 | AL4: 16.75 | AM4: =AVERAGE(AJ4:AL4) -> 16.75 | AN4: 0.5 | AO4: 23.5 | AP4: 67 | AQ4: 68 | AR4: 69 | AS4: 70 | AT4: 71 | AU4: 72 | AV4: 73 | AW4: 74 | AX4: 75 | AY4: 76 | AZ4: 44 | BA4: 112 | BB4: 113
A5: 3 | B5: =LOOKUP($D5,Site_Meta!$C$2:$C$43,Site_Meta!A$2:A$43) -> Tourmaline 20m | C5: =LOOKUP($D5,Site_Meta!$C$2:$C$43,Site_Meta!B$2:B$43) -> Cabo Rojo | D5: TOUR20 | E5: =LOOKUP($D5,Site_Meta!$C$2:$C$43,Site_Meta!D$2:D$43) -> West | F5: =LOOKUP($D5,Site_Meta!$C$2:$C$43,Site_Meta!E$2:E$43) -> W | G5: =LOOKUP($D5,Site_Meta!$C$2:$C$43,Site_Meta!F$2:F$43) -> 18.16517 | H5: =LOOKUP($D5,Site_Meta!$C$2:$C$43,Site_Meta!G$2:G$43) -> -67.2752 | I5: =LOOKUP($D5,Site_Meta!$C$2:$C$43,Site_Meta!H$2:H$43) -> 20 | J5: 1 | K5: 23 | L5: 24 | M5: =CONCATENATE(J5,"/",K5,"/",L5) -> 1/23/24 | N5: Orlando | O5: Manuel | P5: Catherine | R5: 0.37777778 | S5: 0.4 | T5: 27.67 | U5: 0.5 | V5: 36.32 | W5: 0.47 | X5: 6.37 | Y5: 0.51 | Z5: 8.21 | AA5: 0.56 | AB5: 27.58 | AC5: 14.22 | AD5: 36.43 | AE5: 14.18 | AF5: 6.29 | AG5: 14.23 | AH5: 8.22 | AI5: 14 | AJ5: > 14.5 | AK5: > 14.5 | AL5: > 14.5 | AM5: > 14.5 | AN5: 0.5 | AO5: 14.5 | AP5: 56 | AQ5: 57 | AR5: 58 | AS5: 59 | AT5: 60 | AU5: 61 | AV5: 62 | AW5: 63 | AX5: 64 | AY5: 65 | AZ5: 55 | BA5: 110 | BB5: 111
A6: 3 | B6: =LOOKUP($D6,Site_Meta!$C$2:$C$43,Site_Meta!A$2:A$43) -> Tourmaline 10m | C6: =LOOKUP($D6,Site_Meta!$C$2:$C$43,Site_Meta!B$2:B$43) -> Cabo Rojo | D6: TOUR10 | E6: =LOOKUP($D6,Site_Meta!$C$2:$C$43,Site_Meta!D$2:D$43) -> West | F6: =LOOKUP($D6,Site_Meta!$C$2:$C$43,Site_Meta!E$2:E$43) -> W | G6: =LOOKUP($D6,Site_Meta!$C$2:$C$43,Site_Meta!F$2:F$43) -> 18.16304 | H6: =LOOKUP($D6,Site_Meta!$C$2:$C$43,Site_Meta!G$2:G$43) -> -67.2737 | I6: =LOOKUP($D6,Site_Meta!$C$2:$C$43,Site_Meta!H$2:H$43) -> 10 | J6: 1 | K6: 23 | L6: 24 | M6: =CONCATENATE(J6,"/",K6,"/",L6) -> 1/23/24 | N6: Orlando | O6: Manuel | P6: Catherine | R6: 0.40902778 | S6: 0.43055556 | T6: 27.72 | U6: 0.48 | V6: 36.23 | W6: 0.54 | X6: 6.37 | Y6: 0.42 | Z6: 8.21 | AA6: 0.46 | AB6: 27.65 | AC6: 9.54 | AD6: 36.32 | AE6: 9.48 | AF6: 6.3 | AG6: 9.55 | AH6: 8.22 | AI6: 9.62 | AJ6: 11.75 | AK6: 11.75 | AL6: 12 | AM6: =AVERAGE(AJ6:AL6) -> 11.833333 | AN6: 0.5 | AO6: 9.5 | AP6: 12 | AQ6: 13 | AR6: 14 | AS6: 15 | AT6: 16 | AU6: 17 | AV6: 18 | AW6: 19 | AX6: 20 | AY6: 21 | AZ6: 66 | BA6: 102 | BB6: 103
A7: 3 | B7: =LOOKUP($D7,Site_Meta!$C$2:$C$43,Site_Meta!A$2:A$43) -> El Negro 10m | C7: =LOOKUP($D7,Site_Meta!$C$2:$C$43,Site_Meta!B$2:B$43) -> Cabo Rojo | D7: NEGR10 | E7: =LOOKUP($D7,Site_Meta!$C$2:$C$43,Site_Meta!D$2:D$43) -> West | F7: =LOOKUP($D7,Site_Meta!$C$2:$C$43,Site_Meta!E$2:E$43) -> W | G7: =LOOKUP($D7,Site_Meta!$C$2:$C$43,Site_Meta!F$2:F$43) -> 18.14653 | H7: =LOOKUP($D7,Site_Meta!$C$2:$C$43,Site_Meta!G$2:G$43) -> -67.248 | I7: =LOOKUP($D7,Site_Meta!$C$2:$C$43,Site_Meta!H$2:H$43) -> 10 | J7: 1 | K7: 23 | L7: 24 | M7: =CONCATENATE(J7,"/",K7,"/",L7) -> 1/23/24 | N7: Orlando | O7: Manuel | P7: Catherine | R7: 0.44722222 | S7: 0.47291667 | T7: 27.66 | U7: 0.52 | V7: 36.17 | W7: 0.48 | X7: 6.3 | Y7: 0.48 | Z7: 8.21 | AA7: 0.47 | AB7: 27.62 | AC7: 15.99 | AD7: 36.24 | AE7: 16.14 | AF7: 6.1 | AG7: 16.04 | AH7: 8.21 | AI7: 16 | AJ7: 8.25 | AK7: 8.25 | AL7: 8.25 | AM7: =AVERAGE(AJ7:AL7) -> 8.25 | AN7: 0.5 | AO7: 16 | AP7: 1 | AQ7: 2 | AR7: 3 | AS7: 4 | AT7: 5 | AU7: 6 | AV7: 7 | AW7: 8 | AX7: 9 | AY7: 10 | AZ7: 77 | BA7: 100 | BB7: 101
A8: 3 | B8: =LOOKUP($D8,Site_Meta!$C$2:$C$43,Site_Meta!A$2:A$43) -> El Negro 5m | C8: =LOOKUP($D8,Site_Meta!$C$2:$C$43,Site_Meta!B$2:B$43) -> Cabo Rojo | D8: NEGR05 | E8: =LOOKUP($D8,Site_Meta!$C$2:$C$43,Site_Meta!D$2:D$43) -> West | F8: =LOOKUP($D8,Site_Meta!$C$2:$C$43,Site_Meta!E$2:E$43) -> W | G8: =LOOKUP($D8,Site_Meta!$C$2:$C$43,Site_Meta!F$2:F$43) -> 18.14658 | H8: =LOOKUP($D8,Site_Meta!$C$2:$C$43,Site_Meta!G$2:G$43) -> -67.2476 | I8: =LOOKUP($D8,Site_Meta!$C$2:$C$43,Site_Meta!H$2:H$43) -> 5 | J8: 1 | K8: 23 | L8: 24 | M8: =CONCATENATE(J8,"/",K8,"/",L8) -> 1/23/24 | N8: Orlando | O8: Manuel | P8: Catherine | R8: 0.47291667 | S8: 0.48680556 | T8: 27.68 | U8: 0.5 | V8: 36.19 | W8: 0.51 | X8: 6.2 | Y8: 0.49 | Z8: 8.21 | AA8: 0.52 | AB8: 27.67 | AC8: 3.1 | AD8: 36.27 | AE8: 3.05 | AF8: 6.18 | AG8: 3.08 | AH8: 8.21 | AI8: 3.11 | AJ8: > 3.0 | AK8: > 3.0 | AL8: > 3.0 | AM8: > 3.0 | AN8: 0.5 | AO8: 3 | AP8: 45 | AQ8: 46 | AR8: 47 | AS8: 48 | AT8: 49 | AU8: 50 | AV8: 51 | AW8: 52 | AX8: 53 | AY8: 54 | AZ8: 88 | BA8: 108 | BB8: 109
A9: 3 | B9: =LOOKUP($D9,Site_Meta!$C$2:$C$43,Site_Meta!A$2:A$43) -> Maria Langa 20m | C9: =LOOKUP($D9,Site_Meta!$C$2:$C$43,Site_Meta!B$2:B$43) -> Guayanilla | D9: MLAN20 | E9: =LOOKUP($D9,Site_Meta!$C$2:$C$43,Site_Meta!D$2:D$43) -> South | F9: =LOOKUP($D9,Site_Meta!$C$2:$C$43,Site_Meta!E$2:E$43) -> S | G9: =LOOKUP($D9,Site_Meta!$C$2:$C$43,Site_Meta!F$2:F$43) -> 17.95953 | H9: =LOOKUP($D9,Site_Meta!$C$2:$C$43,Site_Meta!G$2:G$43) -> -66.747 | I9: =LOOKUP($D9,Site_Meta!$C$2:$C$43,Site_Meta!H$2:H$43) -> 20 | J9: 1 | K9: 25 | L9: 24 | M9: =CONCATENATE(J9,"/",K9,"/",L9) -> 1/25/24 | N9: Anibal | O9: Manuel | P9: Idalmis | R9: 0.33333333 | S9: 0.35208333 | T9: 27.29 | U9: 0.5 | V9: 36.2 | W9: 0.47 | X9: 6.43 | Y9: 0.49 | Z9: 8.18 | AA9: 0.57 | AB9: 27.34 | AC9: 14.92 | AD9: 36.26 | AE9: 15 | AF9: 6.21 | AG9: 15.07 | AH9: 8.19 | AI9: 15.13 | AJ9: 5.25 | AK9: 5.25 | AL9: 5.25 | AM9: =AVERAGE(AJ9:AL9) -> 5.25 | AN9: 0.5 | AO9: 15 | AP9: 144 | AQ9: 145 | AR9: 146 | AS9: 147 | AT9: 148 | AU9: 149 | AV9: 150 | AW9: 151 | AX9: 152 | AY9: 153 | AZ9: 167 | BA9: 155 | BB9: 156
A10: 3 | B10: =LOOKUP($D10,Site_Meta!$C$2:$C$43,Site_Meta!A$2:A$43) -> Maria Langa 10m | C10: =LOOKUP($D10,Site_Meta!$C$2:$C$43,Site_Meta!B$2:B$43) -> Guayanilla | D10: MLAN10 | E10: =LOOKUP($D10,Site_Meta!$C$2:$C$43,Site_Meta!D$2:D$43) -> South | F10: =LOOKUP($D10,Site_Meta!$C$2:$C$43,Site_Meta!E$2:E$43) -> S | G10: =LOOKUP($D10,Site_Meta!$C$2:$C$43,Site_Meta!F$2:F$43) -> 17.96093 | H10: =LOOKUP($D10,Site_Meta!$C$2:$C$43,Site_Meta!G$2:G$43) -> -66.7529 | I10: =LOOKUP($D10,Site_Meta!$C$2:$C$43,Site_Meta!H$2:H$43) -> 10 | J10: 1 | K10: 25 | L10: 24 | M10: =CONCATENATE(J10,"/",K10,"/",L10) -> 1/25/24 | N10: Anibal | O10: Manuel | P10: Idalmis | R10: 0.35833333 | S10: 0.37708333 | T10: 27.31 | U10: 0.45 | V10: 36.24 | W10: 0.53 | X10: 6.46 | Y10: 0.51 | Z10: 8.21 | AA10: 0.5 | AB10: 27.32 | AC10: 9 | AD10: 36.16 | AE10: 8.6 | AF10: 6.19 | AG10: 8.84 | AH10: 8.2 | AI10: 9 | AJ10: 5.5 | AK10: 5.5 | AL10: 5.5 | AM10: =AVERAGE(AJ10:AL10) -> 5.5 | AN10: 0.5 | AO10: 9 | AP10: 89 | AQ10: 90 | AR10: 91 | AS10: 92 | AT10: 93 | AU10: 94 | AV10: 95 | AW10: 96 | AX10: 97 | AY10: 98 | AZ10: 180 | BA10: 116 | BB10: 117
A11: 3 | B11: =LOOKUP($D11,Site_Meta!$C$2:$C$43,Site_Meta!A$2:A$43) -> Maria Langa 10m | C11: =LOOKUP($D11,Site_Meta!$C$2:$C$43,Site_Meta!B$2:B$43) -> Guayanilla | D11: MLAN10-R | E11: =LOOKUP($D11,Site_Meta!$C$2:$C$43,Site_Meta!D$2:D$43) -> South | F11: =LOOKUP($D11,Site_Meta!$C$2:$C$43,Site_Meta!E$2:E$43) -> S | G11: =LOOKUP($D11,Site_Meta!$C$2:$C$43,Site_Meta!F$2:F$43) -> 17.96093 | H11: =LOOKUP($D11,Site_Meta!$C$2:$C$43,Site_Meta!G$2:G$43) -> -66.7529 | I11: =LOOKUP($D11,Site_Meta!$C$2:$C$43,Site_Meta!H$2:H$43) -> 10 | J11: 1 | K11: 25 | L11: 24 | M11: =CONCATENATE(J11,"/",K11,"/",L11) -> 1/25/24 | N11: Anibal | O11: Manuel | P11: Idalmis | R11: 0.38194444 | S11: 0.4 | T11: 27.32 | U11: 0.45 | V11: 36.18 | W11: 0.32 | X11: 6.48 | Y11: 0.58 | Z11: 8.22 | AA11: 0.41 | AB11: 27.33 | AC11: 8.94 | AD11: 36.26 | AE11: 8.99 | AF11: 6.26 | AG11: 8.89 | AH11: 8.21 | AI11: 8.6 | AJ11: 5.25 | AK11: 5.25 | AL11: 5.25 | AM11: =AVERAGE(AJ11:AL11) -> 5.25 | AN11: 0.5 | AO11: 9 | AP11: 78 | AQ11: 79 | AR11: 80 | AS11: 81 | AT11: 82 | AU11: 83 | AV11: 84 | AW11: 85 | AX11: 86 | AY11: 87 | AZ11: 193 | BA11: 114 | BB11: 115
A12: 3 | B12: =LOOKUP($D12,Site_Meta!$C$2:$C$43,Site_Meta!A$2:A$43) -> Maria Langa 5m | C12: =LOOKUP($D12,Site_Meta!$C$2:$C$43,Site_Meta!B$2:B$43) -> Guayanilla | D12: MLAN05 | E12: =LOOKUP($D12,Site_Meta!$C$2:$C$43,Site_Meta!D$2:D$43) -> South | F12: =LOOKUP($D12,Site_Meta!$C$2:$C$43,Site_Meta!E$2:E$43) -> S | G12: =LOOKUP($D12,Site_Meta!$C$2:$C$43,Site_Meta!F$2:F$43) -> 17.96488 | H12: =LOOKUP($D12,Site_Meta!$C$2:$C$43,Site_Meta!G$2:G$43) -> -66.7565 | I12: =LOOKUP($D12,Site_Meta!$C$2:$C$43,Site_Meta!H$2:H$43) -> 5 | J12: 1 | K12: 25 | L12: 24 | M12: =CONCATENATE(J12,"/",K12,"/",L12) -> 1/25/24 | N12: Anibal | O12: Manuel | P12: Idalmis | R12: 0.40625 | S12: 0.42222222 | T12: 27.34 | U12: 0.57 | V12: 36.12 | W12: 0.47 | X12: 6.43 | Y12: 0.62 | Z12: 8.22 | AA12: 0.58 | AB12: 27.33 | AC12: 4.43 | AD12: 36.27 | AE12: 4.88 | AF12: 6.38 | AG12: 4.56 | AH12: 8.22 | AI12: 4.32 | AJ12: 5.25 | AK12: 5.25 | AL12: 5.25 | AM12: =AVERAGE(AJ12:AL12) -> 5.25 | AN12: 0.5 | AO12: 4.5 | AP12: 118 | AQ12: 119 | AR12: 120 | AS12: 121 | AT12: 122 | AU12: 123 | AV12: 124 | AW12: 125 | AX12: 126 | AY12: 127 | AZ12: 206 | BA12: 129 | BB12: 130
A13: 3 | B13: =LOOKUP($D13,Site_Meta!$C$2:$C$43,Site_Meta!A$2:A$43) -> Efras Wall 20m | C13: =LOOKUP($D13,Site_Meta!$C$2:$C$43,Site_Meta!B$2:B$43) -> La Parguera | D13: EWAL20 | E13: =LOOKUP($D13,Site_Meta!$C$2:$C$43,Site_Meta!D$2:D$43) -> Southwest | F13: =LOOKUP($D13,Site_Meta!$C$2:$C$43,Site_Meta!E$2:E$43) -> SW | G13: =LOOKUP($D13,Site_Meta!$C$2:$C$43,Site_Meta!F$2:F$43) -> 17.8976 | H13: =LOOKUP($D13,Site_Meta!$C$2:$C$43,Site_Meta!G$2:G$43) -> -66.9599 | I13: =LOOKUP($D13,Site_Meta!$C$2:$C$43,Site_Meta!H$2:H$43) -> 20 | J13: 1 | K13: 29 | L13: 24 | M13: =CONCATENATE(J13,"/",K13,"/",L13) -> 1/29/24 | N13: Frank | O13: Manuel | P13: Ana | R13: 0.31597222 | S13: 0.34236111 | T13: 27.36 | U13: 0.59 | V13: 36.31 | W13: 0.56 | X13: 6.61 | Y13: 0.45 | Z13: 8.19 | AA13: 0.57 | AB13: 27.35 | AC13: 18.14 | AD13: 36.34 | AE13: 18.36 | AF13: 6.27 | AG13: 18.08 | AH13: 8.21 | AI13: 18.3 | AJ13: > 18 | AK13: > 18 | AL13: > 18 | AM13: > 18 | AN13: 0.5 | AO13: 18 | AP13: 326 | AQ13: 327 | AR13: 328 | AS13: 329 | AT13: 330 | AU13: 331 | AV13: 332 | AW13: 333 | AX13: 334 | AY13: 335 | AZ13: 3880 | BA13: 337 | BB13: 338
A14: 3 | B14: =LOOKUP($D14,Site_Meta!$C$2:$C$43,Site_Meta!A$2:A$43) -> Boya Vieja 20m | C14: =LOOKUP($D14,Site_Meta!$C$2:$C$43,Site_Meta!B$2:B$43) -> La Parguera | D14: BOYA20 | E14: =LOOKUP($D14,Site_Meta!$C$2:$C$43,Site_Meta!D$2:D$43) -> Southwest | F14: =LOOKUP($D14,Site_Meta!$C$2:$C$43,Site_Meta!E$2:E$43) -> SW | G14: =LOOKUP($D14,Site_Meta!$C$2:$C$43,Site_Meta!F$2:F$43) -> 17.88827 | H14: =LOOKUP($D14,Site_Meta!$C$2:$C$43,Site_Meta!G$2:G$43) -> -66.9978 | I14: =LOOKUP($D14,Site_Meta!$C$2:$C$43,Site_Meta!H$2:H$43) -> 20 | J14: 1 | K14: 29 | L14: 24 | M14: =CONCATENATE(J14,"/",K14,"/",L14) -> 1/29/24 | N14: Frank | O14: Manuel | P14: Ana | R14: 0.35486111 | S14: 0.375 | T14: 27.35 | U14: 0.49 | V14: 36.26 | W14: 0.54 | X14: 6.55 | Y14: 0.53 | Z14: 8.23 | AA14: 0.51 | AB14: 27.37 | AC14: 18.13 | AD14: 36.35 | AE14: 17.79 | AF14: 6.12 | AG14: 18 | AH14: 8.22 | AI14: 18.12 | AJ14: > 18 | AK14: > 18 | AL14: > 18 | AM14: > 18 | AN14: 0.5 | AO14: 18 | AP14: 235 | AQ14: 236 | AR14: 237 | AS14: 238 | AT14: 239 | AU14: 240 | AV14: 241 | AW14: 242 | AX14: 243 | AY14: 244 | AZ14: 3750 | BA14: 246 | BB14: 247
A15: 3 | B15: =LOOKUP($D15,Site_Meta!$C$2:$C$43,Site_Meta!A$2:A$43) -> Media Luna 10m | C15: =LOOKUP($D15,Site_Meta!$C$2:$C$43,Site_Meta!B$2:B$43) -> La Parguera | D15: MLUN10 | E15: =LOOKUP($D15,Site_Meta!$C$2:$C$43,Site_Meta!D$2:D$43) -> Southwest | F15: =LOOKUP($D15,Site_Meta!$C$2:$C$43,Site_Meta!E$2:E$43) -> SW | G15: =LOOKUP($D15,Site_Meta!$C$2:$C$43,Site_Meta!F$2:F$43) -> 17.93472 | H15: =LOOKUP($D15,Site_Meta!$C$2:$C$43,Site_Meta!G$2:G$43) -> -67.0485 | I15: =LOOKUP($D15,Site_Meta!$C$2:$C$43,Site_Meta!H$2:H$43) -> 10 | J15: 1 | K15: 29 | L15: 24 | M15: =CONCATENATE(J15,"/",K15,"/",L15) -> 1/29/24 | N15: Frank | O15: Manuel | P15: Ana | R15: 0.39375 | S15: 0.40972222 | T15: 26.92 | U15: 0.48 | V15: 36.26 | W15: 0.42 | X15: 6.51 | Y15: 0.56 | Z15: 8.2 | AA15: 0.51 | AB15: 26.9 | AC15: 5.01 | AD15: 36.36 | AE15: 4.98 | AF15: 6.31 | AG15: 5.24 | AH15: 8.2 | AI15: 5.03 | AJ15: > 5 | AK15: > 5 | AL15: > 5 | AM15: > 5 | AN15: 0.5 | AO15: 18 | AP15: 131 | AQ15: 132 | AR15: 133 | AS15: 134 | AT15: 135 | AU15: 136 | AV15: 137 | AW15: 138 | AX15: 139 | AY15: 140 | AZ15: 3620 | BA15: 142 | BB15: 143
A16: 3 | B16: =LOOKUP($D16,Site_Meta!$C$2:$C$43,Site_Meta!A$2:A$43) -> Media Luna 5m | C16: =LOOKUP($D16,Site_Meta!$C$2:$C$43,Site_Meta!B$2:B$43) -> La Parguera | D16: MLUN05 | E16: =LOOKUP($D16,Site_Meta!$C$2:$C$43,Site_Meta!D$2:D$43) -> Southwest | F16: =LOOKUP($D16,Site_Meta!$C$2:$C$43,Site_Meta!E$2:E$43) -> SW | G16: =LOOKUP($D16,Site_Meta!$C$2:$C$43,Site_Meta!F$2:F$43) -> 17.93937 | H16: =LOOKUP($D16,Site_Meta!$C$2:$C$43,Site_Meta!G$2:G$43) -> -67.0507 | I16: =LOOKUP($D16,Site_Meta!$C$2:$C$43,Site_Meta!H$2:H$43) -> 5 | J16: 1 | K16: 29 | L16: 24 | M16: =CONCATENATE(J16,"/",K16,"/",L16) -> 1/29/24 | N16: Frank | O16: Manuel | P16: Ana | R16: 0.42013889 | S16: 0.4375 | T16: 26.85 | U16: 0.45 | V16: 36.35 | W16: 0.44 | X16: 6.65 | Y16: 0.49 | Z16: 8.21 | AA16: 0.49 | AB16: 26.78 | AC16: 3.03 | AD16: 36.36 | AE16: 3.09 | AF16: 6.47 | AG16: 3.07 | AH16: 8.19 | AI16: 3.14 | AJ16: > 3 | AK16: > 3 | AL16: > 3 | AM16: > 3 | AN16: 0.5 | AO16: 3 | AP16: 209 | AQ16: 210 | AR16: 211 | AS16: 212 | AT16: 213 | AU16: 214 | AV16: 215 | AW16: 216 | AX16: 217 | AY16: 218 | AZ16: 219 | BA16: 220 | BB16: 221
A17: 3 | B17: =LOOKUP($D17,Site_Meta!$C$2:$C$43,Site_Meta!A$2:A$43) -> El Seco 30m | C17: =LOOKUP($D17,Site_Meta!$C$2:$C$43,Site_Meta!B$2:B$43) -> Isla Vieques | D17: SECO30 | E17: =LOOKUP($D17,Site_Meta!$C$2:$C$43,Site_Meta!D$2:D$43) -> Vieques/Culebra | F17: =LOOKUP($D17,Site_Meta!$C$2:$C$43,Site_Meta!E$2:E$43) -> E | G17: =LOOKUP($D17,Site_Meta!$C$2:$C$43,Site_Meta!F$2:F$43) -> 18.13869 | H17: =LOOKUP($D17,Site_Meta!$C$2:$C$43,Site_Meta!G$2:G$43) -> -65.1971 | I17: =LOOKUP($D17,Site_Meta!$C$2:$C$43,Site_Meta!H$2:H$43) -> 30 | J17: 1 | K17: 30 | L17: 24 | M17: =CONCATENATE(J17,"/",K17,"/",L17) -> 1/30/24 | N17: Tyrone | O17: Manuel | P17: Catherine | R17: 0.32152778 | S17: 0.35277778 | T17: 26.34 | U17: 0.45 | V17: 36.8 | W17: 0.46 | X17: 6.29 | Y17: 0.46 | Z17: 8.17 | AA17: 0.57 | AB17: 26.35 | AC17: 29.73 | AD17: 36.91 | AE17: 29.71 | AF17: 6.11 | AG17: 29.18 | AH17: 8.19 | AI17: 29.37 | AJ17: 23 | AK17: 23 | AL17: 23 | AM17: =AVERAGE(AJ17:AL17) -> 23 | AN17: 0.5 | AO17: 29.5 | AP17: 183 | AQ17: 184 | AR17: 185 | AS17: 186 | AT17: 187 | AU17: 188 | AV17: 189 | AW17: 190 | AX17: 191 | AY17: 192 | AZ17: 232 | BA17: 194 | BB17: 195
A18: 3 | B18: =LOOKUP($D18,Site_Meta!$C$2:$C$43,Site_Meta!A$2:A$43) -> Esperanza 10m | C18: =LOOKUP($D18,Site_Meta!$C$2:$C$43,Site_Meta!B$2:B$43) -> Isla Vieques | D18: ESPE10 | E18: =LOOKUP($D18,Site_Meta!$C$2:$C$43,Site_Meta!D$2:D$43) -> Vieques/Culebra | F18: =LOOKUP($D18,Site_Meta!$C$2:$C$43,Site_Meta!E$2:E$43) -> E | G18: =LOOKUP($D18,Site_Meta!$C$2:$C$43,Site_Meta!F$2:F$43) -> 18.08057 | H18: =LOOKUP($D18,Site_Meta!$C$2:$C$43,Site_Meta!G$2:G$43) -> -65.4879 | I18: =LOOKUP($D18,Site_Meta!$C$2:$C$43,Site_Meta!H$2:H$43) -> 10 | J18: 1 | K18: 30 | L18: 24 | M18: =CONCATENATE(J18,"/",K18,"/",L18) -> 1/30/24 | N18: Tyrone | O18: Manuel | P18: Catherine | R18: 0.39444444 | S18: 0.41180556 | T18: 27.06 | U18: 0.53 | V18: 36.61 | W18: 0.45 | X18: 6.45 | Y18: 0.52 | Z18: 8.23 | AA18: 0.48 | AB18: 27.08 | AC18: 9.54 | AD18: 36.78 | AE18: 9.48 | AF18: 5.91 | AG18: 9.43 | AH18: 8.2 | AI18: 9.61 | AJ18: > 9.5 | AK18: > 9.5 | AL18: > 9.5 | AM18: > 9.5 | AN18: 0.5 | AO18: 9.5 | AP18: 248 | AQ18: 249 | AR18: 250 | AS18: 251 | AT18: 252 | AU18: 253 | AV18: 254 | AW18: 255 | AX18: 256 | AY18: 257 | AZ18: 245 | BA18: 259 | BB18: 260
A19: 3 | B19: =LOOKUP($D19,Site_Meta!$C$2:$C$43,Site_Meta!A$2:A$43) -> Esperanza 10m | C19: =LOOKUP($D19,Site_Meta!$C$2:$C$43,Site_Meta!B$2:B$43) -> Isla Vieques | D19: ESPE10-R | E19: =LOOKUP($D19,Site_Meta!$C$2:$C$43,Site_Meta!D$2:D$43) -> Vieques/Culebra | F19: =LOOKUP($D19,Site_Meta!$C$2:$C$43,Site_Meta!E$2:E$43) -> E | G19: =LOOKUP($D19,Site_Meta!$C$2:$C$43,Site_Meta!F$2:F$43) -> 18.08057 | H19: =LOOKUP($D19,Site_Meta!$C$2:$C$43,Site_Meta!G$2:G$43) -> -65.4879 | I19: =LOOKUP($D19,Site_Meta!$C$2:$C$43,Site_Meta!H$2:H$43) -> 10 | J19: 1 | K19: 30 | L19: 24 | M19: =CONCATENATE(J19,"/",K19,"/",L19) -> 1/30/24 | N19: Tyrone | O19: Manuel | P19: Catherine | R19: 0.41388889 | S19: 0.43055556 | T19: 27.08 | U19: 0.48 | V19: 36.66 | W19: 0.46 | X19: 6.4 | Y19: 0.5 | Z19: 8.23 | AA19: 0.55 | AB19: 27.07 | AC19: 9.05 | AD19: 36.78 | AE19: 9.21 | AF19: 6.08 | AG19: 9.07 | AH19: 8.21 | AI19: 9.05 | AJ19: > 9.5 | AK19: > 9.5 | AL19: > 9.5 | AM19: > 9.5 | AN19: 0.5 | AO19: 9 | AP19: 196 | AQ19: 197 | AR19: 198 | AS19: 199 | AT19: 200 | AU19: 201 | AV19: 202 | AW19: 203 | AX19: 204 | AY19: 205 | AZ19: 258 | BA19: 207 | BB19: 208
A20: 3 | B20: =LOOKUP($D20,Site_Meta!$C$2:$C$43,Site_Meta!A$2:A$43) -> Canjilones 15m | C20: =LOOKUP($D20,Site_Meta!$C$2:$C$43,Site_Meta!B$2:B$43) -> Isla Vieques | D20: CANJ15 | E20: =LOOKUP($D20,Site_Meta!$C$2:$C$43,Site_Meta!D$2:D$43) -> Vieques/Culebra | F20: =LOOKUP($D20,Site_Meta!$C$2:$C$43,Site_Meta!E$2:E$43) -> E | G20: =LOOKUP($D20,Site_Meta!$C$2:$C$43,Site_Meta!F$2:F$43) -> 18.08964 | H20: =LOOKUP($D20,Site_Meta!$C$2:$C$43,Site_Meta!G$2:G$43) -> -65.5901 | I20: =LOOKUP($D20,Site_Meta!$C$2:$C$43,Site_Meta!H$2:H$43) -> 15 | J20: 1 | K20: 30 | L20: 24 | M20: =CONCATENATE(J20,"/",K20,"/",L20) -> 1/30/24 | N20: Tyrone | O20: Manuel | P20: Catherine | R20: 0.45208333 | S20: 0.46875 | T20: 27.22 | U20: 0.53 | V20: 36.58 | W20: 0.59 | X20: 6.31 | Y20: 0.53 | Z20: 8.23 | AA20: 0.56 | AB20: 27.01 | AC20: 14.42 | AD20: 36.63 | AE20: 14.6 | AF20: 6.3 | AG20: 14.55 | AH20: 8.24 | AI20: 14.54 | AJ20: > 14.5 | AK20: > 14.5 | AL20: > 14.5 | AM20: > 14.5 | AN20: 0.5 | AO20: 14.5 | AP20: 274 | AQ20: 275 | AR20: 276 | AS20: 277 | AT20: 278 | AU20: 279 | AV20: 280 | AW20: 281 | AX20: 282 | AY20: 283 | AZ20: 271 | BA20: 285 | BB20: 286
A21: 3 | B21: =LOOKUP($D21,Site_Meta!$C$2:$C$43,Site_Meta!A$2:A$43) -> Cayo Diablo 5m | C21: =LOOKUP($D21,Site_Meta!$C$2:$C$43,Site_Meta!B$2:B$43) -> Fajardo | D21: DIAB05 | E21: =LOOKUP($D21,Site_Meta!$C$2:$C$43,Site_Meta!D$2:D$43) -> North/Northeast | F21: =LOOKUP($D21,Site_Meta!$C$2:$C$43,Site_Meta!E$2:E$43) -> E | G21: =LOOKUP($D21,Site_Meta!$C$2:$C$43,Site_Meta!F$2:F$43) -> 18.36033 | H21: =LOOKUP($D21,Site_Meta!$C$2:$C$43,Site_Meta!G$2:G$43) -> -65.5309 | I21: =LOOKUP($D21,Site_Meta!$C$2:$C$43,Site_Meta!H$2:H$43) -> 5 | J21: 1 | K21: 31 | L21: 24 | M21: =CONCATENATE(J21,"/",K21,"/",L21) -> 1/31/24 | N21: Tyrone | O21: Manuel | P21: Catherine | R21: 0.29513889 | S21: 0.31736111 | T21: 26.84 | U21: 0.51 | V21: 36.83 | W21: 0.53 | X21: 6.27 | Y21: 0.55 | Z21: 8.19 | AA21: 0.54 | AB21: 26.87 | AC21: 8.48 | AD21: 36.91 | AE21: 8.33 | AF21: 6.07 | AG21: 8.5 | AH21: 8.19 | AI21: 8.46 | AJ21: > 8.5 | AK21: > 8.5 | AL21: > 8.5 | AM21: > 8.5 | AN21: 0.5 | AO21: 8 | AP21: 261 | AQ21: 262 | AR21: 263 | AS21: 264 | AT21: 265 | AU21: 266 | AV21: 267 | AW21: 268 | AX21: 269 | AY21: 270 | AZ21: 284 | BA21: 272 | BB21: 273
A22: 3 | B22: =LOOKUP($D22,Site_Meta!$C$2:$C$43,Site_Meta!A$2:A$43) -> Palominitos 10m | C22: =LOOKUP($D22,Site_Meta!$C$2:$C$43,Site_Meta!B$2:B$43) -> Fajardo | D22: PALT10 | E22: =LOOKUP($D22,Site_Meta!$C$2:$C$43,Site_Meta!D$2:D$43) -> North/Northeast | F22: =LOOKUP($D22,Site_Meta!$C$2:$C$43,Site_Meta!E$2:E$43) -> E | G22: =LOOKUP($D22,Site_Meta!$C$2:$C$43,Site_Meta!F$2:F$43) -> 18.33537 | H22: =LOOKUP($D22,Site_Meta!$C$2:$C$43,Site_Meta!G$2:G$43) -> -65.5656 | I22: =LOOKUP($D22,Site_Meta!$C$2:$C$43,Site_Meta!H$2:H$43) -> 10 | J22: 1 | K22: 31 | L22: 24 | M22: =CONCATENATE(J22,"/",K22,"/",L22) -> 1/31/24 | N22: Tyrone | O22: Manuel | P22: Catherine | R22: 0.34305556 | S22: 0.36111111 | T22: 26.71 | U22: 0.37 | V22: 36.75 | W22: 0.52 | X22: 6.66 | Y22: 0.56 | Z22: 8.22 | AA22: 0.55 | AB22: 26.74 | AC22: 8.69 | AD22: 36.8 | AE22: 8.57 | AF22: 6.51 | AG22: 8.5 | AH22: 8.22 | AI22: 8.47 | AJ22: > 8.5 | AK22: > 8.5 | AL22: > 8.5 | AM22: > 8.5 | AN22: 0.5 | AO22: 8.5 | AP22: 287 | AQ22: 288 | AR22: 289 | AS22: 290 | AT22: 291 | AU22: 292 | AV22: 293 | AW22: 294 | AX22: 295 | AY22: 296 | AZ22: 297 | BA22: 298 | BB22: 299
A23: 3 | B23: =LOOKUP($D23,Site_Meta!$C$2:$C$43,Site_Meta!A$2:A$43) -> Palominos 20m | C23: =LOOKUP($D23,Site_Meta!$C$2:$C$43,Site_Meta!B$2:B$43) -> Fajardo | D23: PALN20 | E23: =LOOKUP($D23,Site_Meta!$C$2:$C$43,Site_Meta!D$2:D$43) -> North/Northeast | F23: =LOOKUP($D23,Site_Meta!$C$2:$C$43,Site_Meta!E$2:E$43) -> E | G23: =LOOKUP($D23,Site_Meta!$C$2:$C$43,Site_Meta!F$2:F$43) -> 18.35466 | H23: =LOOKUP($D23,Site_Meta!$C$2:$C$43,Site_Meta!G$2:G$43) -> -65.5671 | I23: =LOOKUP($D23,Site_Meta!$C$2:$C$43,Site_Meta!H$2:H$43) -> 20 | J23: 1 | K23: 31 | L23: 24 | M23: =CONCATENATE(J23,"/",K23,"/",L23) -> 1/31/24 | N23: Tyrone | O23: Manuel | P23: Catherine | R23: 0.38611111 | S23: 0.40277778 | T23: 26.84 | U23: 0.59 | V23: 36.84 | W23: 0.6 | X23: 6.45 | Y23: 0.57 | Z23: 8.21 | AA23: 0.56 | AB23: 26.81 | AC23: 15.95 | AD23: 36.89 | AE23: 16.3 | AF23: 6.22 | AG23: 16.28 | AH23: 8.21 | AI23: 15.83 | AJ23: 8 | AK23: 8 | AL23: 8 | AM23: =AVERAGE(AJ23:AL23) -> 8 | AN23: 0.5 | AO23: 16 | AP23: 313 | AQ23: 314 | AR23: 315 | AS23: 316 | AT23: 317 | AU23: 318 | AV23: 319 | AW23: 320 | AX23: 321 | AY23: 322 | AZ23: 310 | BA23: 324 | BB23: 325
A24: 3 | B24: =LOOKUP($D24,Site_Meta!$C$2:$C$43,Site_Meta!A$2:A$43) -> Cabezas de San Juan 5m | C24: =LOOKUP($D24,Site_Meta!$C$2:$C$43,Site_Meta!B$2:B$43) -> Fajardo | D24: CABE05 | E24: =LOOKUP($D24,Site_Meta!$C$2:$C$43,Site_Meta!D$2:D$43) -> North/Northeast | F24: =LOOKUP($D24,Site_Meta!$C$2:$C$43,Site_Meta!E$2:E$43) -> E | G24: =LOOKUP($D24,Site_Meta!$C$2:$C$43,Site_Meta!F$2:F$43) -> 18.38544 | H24: =LOOKUP($D24,Site_Meta!$C$2:$C$43,Site_Meta!G$2:G$43) -> -65.6297 | I24: =LOOKUP($D24,Site_Meta!$C$2:$C$43,Site_Meta!H$2:H$43) -> 5 | J24: 1 | K24: 31 | L24: 24 | M24: =CONCATENATE(J24,"/",K24,"/",L24) -> 1/31/24 | N24: Tyrone | O24: Manuel | P24: Catherine | R24: 0.425 | S24: 0.43263889 | T24: 26.86 | U24: 0.34 | V24: 36.4 | W24: 0.44 | X24: 6.67 | Y24: 0.54 | Z24: 8.22 | AA24: 0.48 | AB24: 26.9 | AC24: 5.99 | AD24: 36.61 | AE24: 5.96 | AF24: 6.39 | AG24: 6.01 | AH24: 8.22 | AI24: 5.94 | AJ24: > 6 | AK24: > 6 | AL24: > 6 | AM24: > 6 | AN24: 0.5 | AO24: 6 | AP24: 300 | AQ24: 301 | AR24: 302 | AS24: 303 | AT24: 304 | AU24: 305 | AV24: 306 | AW24: 307 | AX24: 308 | AY24: 309 | AZ24: 323 | BA24: 311 | BB24: 312
A25: 3 | B25: =LOOKUP($D25,Site_Meta!$C$2:$C$43,Site_Meta!A$2:A$43) -> Dakiti 20m | C25: =LOOKUP($D25,Site_Meta!$C$2:$C$43,Site_Meta!B$2:B$43) -> Isla Culebra | D25: DAKI20 | E25: =LOOKUP($D25,Site_Meta!$C$2:$C$43,Site_Meta!D$2:D$43) -> Vieques/Culebra | F25: =LOOKUP($D25,Site_Meta!$C$2:$C$43,Site_Meta!E$2:E$43) -> E | G25: =LOOKUP($D25,Site_Meta!$C$2:$C$43,Site_Meta!F$2:F$43) -> 18.27587 | H25: =LOOKUP($D25,Site_Meta!$C$2:$C$43,Site_Meta!G$2:G$43) -> -65.2773 | I25: =LOOKUP($D25,Site_Meta!$C$2:$C$43,Site_Meta!H$2:H$43) -> 20 | J25: 2 | K25: 1 | L25: 24 | M25: =CONCATENATE(J25,"/",K25,"/",L25) -> 2/1/24 | N25: Tyrone | O25: Manuel | P25: Catherine | R25: 0.30763889 | S25: 0.33333333 | T25: 26.88 | U25: 0.53 | V25: 36.8 | W25: 0.53 | X25: 6.58 | Y25: 0.55 | Z25: 8.2 | AA25: 0.53 | AB25: 26.9 | AC25: 22.48 | AD25: 36.91 | AE25: 22.25 | AF25: 6.23 | AG25: 22.23 | AH25: 8.21 | AI25: 22.11 | AJ25: 18.75 | AK25: 18.5 | AL25: 18.75 | AM25: =AVERAGE(AJ25:AL25) -> 18.666667 | AN25: 0.5 | AO25: 22.5 | AP25: 222 | AQ25: 223 | AR25: 224 | AS25: 225 | AT25: 226 | AU25: 227 | AV25: 228 | AW25: 229 | AX25: 230 | AY25: 231 | AZ25: 336 | BA25: 233 | BB25: 234
A26: 3 | B26: =LOOKUP($D26,Site_Meta!$C$2:$C$43,Site_Meta!A$2:A$43) -> Canal Luis Pena 5m | C26: =LOOKUP($D26,Site_Meta!$C$2:$C$43,Site_Meta!B$2:B$43) -> Isla Culebra | D26: LPEN05 | E26: =LOOKUP($D26,Site_Meta!$C$2:$C$43,Site_Meta!D$2:D$43) -> Vieques/Culebra | F26: =LOOKUP($D26,Site_Meta!$C$2:$C$43,Site_Meta!E$2:E$43) -> E | G26: =LOOKUP($D26,Site_Meta!$C$2:$C$43,Site_Meta!F$2:F$43) -> 18.30493 | H26: =LOOKUP($D26,Site_Meta!$C$2:$C$43,Site_Meta!G$2:G$43) -> -65.3277 | I26: =LOOKUP($D26,Site_Meta!$C$2:$C$43,Site_Meta!H$2:H$43) -> 5 | J26: 2 | K26: 1 | L26: 24 | M26: =CONCATENATE(J26,"/",K26,"/",L26) -> 2/1/24 | N26: Tyrone | O26: Manuel | P26: Catherine | R26: 0.35347222 | S26: 0.36805556 | T26: 26.82 | U26: 0.46 | V26: 36.88 | W26: 0.45 | X26: 6.53 | Y26: 0.41 | Z26: 8.22 | AA26: 0.47 | AB26: 26.75 | AC26: 4.47 | AD26: 36.87 | AE26: 4.47 | AF26: 6 | AG26: 4.49 | AH26: 8.19 | AI26: 4.45 | AJ26: > 5 | AK26: > 5 | AL26: > 5 | AM26: > 5 | AN26: 0.5 | AO26: 4.5 | AP26: 352 | AQ26: 353 | AR26: 354 | AS26: 355 | AT26: 356 | AU26: 357 | AV26: 358 | AW26: 359 | AX26: 360 | AY26: 361 | AZ26: 349 | BA26: 363 | BB26: 364
A27: 3 | B27: =LOOKUP($D27,Site_Meta!$C$2:$C$43,Site_Meta!A$2:A$43) -> Carlos Rosario 10m | C27: =LOOKUP($D27,Site_Meta!$C$2:$C$43,Site_Meta!B$2:B$43) -> Isla Culebra | D27: CROS10 | E27: =LOOKUP($D27,Site_Meta!$C$2:$C$43,Site_Meta!D$2:D$43) -> Vieques/Culebra | F27: =LOOKUP($D27,Site_Meta!$C$2:$C$43,Site_Meta!E$2:E$43) -> E | G27: =LOOKUP($D27,Site_Meta!$C$2:$C$43,Site_Meta!F$2:F$43) -> 18.32779 | H27: =LOOKUP($D27,Site_Meta!$C$2:$C$43,Site_Meta!G$2:G$43) -> -65.332 | I27: =LOOKUP($D27,Site_Meta!$C$2:$C$43,Site_Meta!H$2:H$43) -> 10 | J27: 2 | K27: 1 | L27: 24 | M27: =CONCATENATE(J27,"/",K27,"/",L27) -> 2/1/24 | N27: Tyrone | O27: Manuel | P27: Catherine | R27: 0.38402778 | S27: 0.39861111 | T27: 26.81 | U27: 0.54 | V27: 36.82 | W27: 0.55 | X27: 6.58 | Y27: 0.49 | Z27: 8.23 | AA27: 0.51 | AB27: 26.8 | AC27: 10.44 | AD27: 36.91 | AE27: 10.45 | AF27: 6.45 | AG27: 10.42 | AH27: 8.22 | AI27: 10.57 | AJ27: > 10.5 | AK27: > 10.5 | AL27: > 10.5 | AM27: > 10.5 | AN27: 0.5 | AO27: 10.5 | AP27: 157 | AQ27: 158 | AR27: 159 | AS27: 160 | AT27: 161 | AU27: 162 | AV27: 163 | AW27: 164 | AX27: 165 | AY27: 166 | AZ27: 3621 | BA27: 168 | BB27: 169
A28: 3 | B28: =LOOKUP($D28,Site_Meta!$C$2:$C$43,Site_Meta!A$2:A$43) -> Cayo Caribes 10m | C28: =LOOKUP($D28,Site_Meta!$C$2:$C$43,Site_Meta!B$2:B$43) -> Salinas | D28: CARI10 | E28: =LOOKUP($D28,Site_Meta!$C$2:$C$43,Site_Meta!D$2:D$43) -> Southeast | F28: =LOOKUP($D28,Site_Meta!$C$2:$C$43,Site_Meta!E$2:E$43) -> S | G28: =LOOKUP($D28,Site_Meta!$C$2:$C$43,Site_Meta!F$2:F$43) -> 17.91533 | H28: =LOOKUP($D28,Site_Meta!$C$2:$C$43,Site_Meta!G$2:G$43) -> -66.2141 | I28: =LOOKUP($D28,Site_Meta!$C$2:$C$43,Site_Meta!H$2:H$43) -> 10 | J28: 2 | K28: 2 | L28: 24 | M28: =CONCATENATE(J28,"/",K28,"/",L28) -> 2/2/24 | N28: Anibal | O28: Manuel | P28: Ana | R28: 0.37013889 | S28: 0.39027778 | T28: 27.18 | U28: 0.49 | V28: 36.67 | W28: 0.5 | X28: 6.68 | Y28: 0.5 | Z28: 8.21 | AA28: 0.49 | AB28: 27.18 | AC28: 10.03 | AD28: 36.54 | AE28: 10.02 | AF28: 6.44 | AG28: 9.97 | AH28: 8.21 | AI28: 10.06 | AJ28: > 10 | AK28: > 10 | AL28: > 10 | AM28: > 10 | AN28: 0.5 | AO28: 9 | AP28: 378 | AQ28: 379 | AR28: 380 | AS28: 381 | AT28: 382 | AU28: 383 | AV28: 384 | AW28: 385 | AX28: 386 | AY28: 387 | AZ28: 3751 | BA28: 389 | BB28: 390
A29: 3 | B29: =LOOKUP($D29,Site_Meta!$C$2:$C$43,Site_Meta!A$2:A$43) -> Cayo Ratones 5m | C29: =LOOKUP($D29,Site_Meta!$C$2:$C$43,Site_Meta!B$2:B$43) -> Salinas | D29: RATO05 | E29: =LOOKUP($D29,Site_Meta!$C$2:$C$43,Site_Meta!D$2:D$43) -> Southeast | F29: =LOOKUP($D29,Site_Meta!$C$2:$C$43,Site_Meta!E$2:E$43) -> S | G29: =LOOKUP($D29,Site_Meta!$C$2:$C$43,Site_Meta!F$2:F$43) -> 17.9346 | H29: =LOOKUP($D29,Site_Meta!$C$2:$C$43,Site_Meta!G$2:G$43) -> -66.3025 | I29: =LOOKUP($D29,Site_Meta!$C$2:$C$43,Site_Meta!H$2:H$43) -> 5 | J29: 2 | K29: 2 | L29: 24 | M29: =CONCATENATE(J29,"/",K29,"/",L29) -> 2/2/24 | N29: Anibal | O29: Manuel | P29: Ana | R29: 0.40208333 | S29: 0.41597222 | T29: 27.29 | U29: 0.46 | V29: 36.59 | W29: 0.51 | X29: 6.71 | Y29: 0.49 | Z29: 8.21 | AA29: 0.5 | AB29: 27.3 | AC29: 3.53 | AD29: 36.4 | AE29: 3.54 | AF29: 6.76 | AG29: 3.55 | AH29: 8.21 | AI29: 3.51 | AJ29: > 3.5 | AK29: > 3.5 | AL29: > 3.5 | AM29: > 3.5 | AN29: 0.5 | AO29: 3.5 | AP29: 391 | AQ29: 392 | AR29: 393 | AS29: 394 | AT29: 395 | AU29: 396 | AV29: 397 | AW29: 398 | AX29: 399 | AY29: 400 | AZ29: 3881 | BA29: 402 | BB29: 403
A30: 3 | B30: =LOOKUP($D30,Site_Meta!$C$2:$C$43,Site_Meta!A$2:A$43) -> West Reef 10m | C30: =LOOKUP($D30,Site_Meta!$C$2:$C$43,Site_Meta!B$2:B$43) -> Ponce | D30: CDMU10 | E30: =LOOKUP($D30,Site_Meta!$C$2:$C$43,Site_Meta!D$2:D$43) -> South | F30: =LOOKUP($D30,Site_Meta!$C$2:$C$43,Site_Meta!E$2:E$43) -> S | G30: =LOOKUP($D30,Site_Meta!$C$2:$C$43,Site_Meta!F$2:F$43) -> 17.89502 | H30: =LOOKUP($D30,Site_Meta!$C$2:$C$43,Site_Meta!G$2:G$43) -> -66.5284 | I30: =LOOKUP($D30,Site_Meta!$C$2:$C$43,Site_Meta!H$2:H$43) -> 10 | J30: 2 | K30: 2 | L30: 24 | M30: =CONCATENATE(J30,"/",K30,"/",L30) -> 2/2/24 | N30: Anibal | O30: Manuel | P30: Ana | R30: 0.43888889 | S30: 0.45763889 | T30: 27.46 | U30: 0.48 | V30: 36.3 | W30: 0.5 | X30: 6.74 | Y30: 0.51 | Z30: 8.23 | AA30: 0.46 | AB30: 27.34 | AC30: 7.93 | AD30: 36.36 | AE30: 8.06 | AF30: 6.58 | AG30: 7.96 | AH30: 8.24 | AI30: 8.02 | AJ30: > 8 | AK30: > 8 | AL30: > 8 | AM30: > 8 | AN30: 0.5 | AO30: 8 | AP30: 417 | AQ30: 418 | AR30: 419 | AS30: 420 | AT30: 421 | AU30: 422 | AV30: 423 | AW30: 424 | AX30: 425 | AY30: 426 | AZ30: 401 | BA30: 428 | BB30: 429
A31: 3 | B31: =LOOKUP($D31,Site_Meta!$C$2:$C$43,Site_Meta!A$2:A$43) -> Derrumbadero 20m | C31: =LOOKUP($D31,Site_Meta!$C$2:$C$43,Site_Meta!B$2:B$43) -> Ponce | D31: DERR20 | E31: =LOOKUP($D31,Site_Meta!$C$2:$C$43,Site_Meta!D$2:D$43) -> South | F31: =LOOKUP($D31,Site_Meta!$C$2:$C$43,Site_Meta!E$2:E$43) -> S | G31: =LOOKUP($D31,Site_Meta!$C$2:$C$43,Site_Meta!F$2:F$43) -> 17.904 | H31: =LOOKUP($D31,Site_Meta!$C$2:$C$43,Site_Meta!G$2:G$43) -> -66.6086 | I31: =LOOKUP($D31,Site_Meta!$C$2:$C$43,Site_Meta!H$2:H$43) -> 20 | J31: 2 | K31: 2 | L31: 24 | M31: =CONCATENATE(J31,"/",K31,"/",L31) -> 2/2/24 | N31: Anibal | O31: Manuel | P31: Ana | R31: 0.46944444 | S31: 0.48958333 | T31: 27.5 | U31: 0.5 | V31: 36.44 | W31: 0.46 | X31: 6.52 | Y31: 0.48 | Z31: 8.24 | AA31: 0.5 | AB31: 27.31 | AC31: 18.07 | AD31: 36.5 | AE31: 18.17 | AF31: 6.54 | AG31: 18.23 | AH31: 8.25 | AI31: 18.24 | AJ31: > 18 | AK31: > 18 | AL31: > 18 | AM31: > 18 | AN31: 0.5 | AO31: 18 | AP31: 365 | AQ31: 366 | AR31: 367 | AS31: 368 | AT31: 369 | AU31: 370 | AV31: 371 | AW31: 372 | AX31: 373 | AY31: 374 | AZ31: 414 | BA31: 376 | BB31: 377
A32: 3 | B32: =LOOKUP($D32,Site_Meta!$C$2:$C$43,Site_Meta!A$2:A$43) -> Gallardo 5m | C32: =LOOKUP($D32,Site_Meta!$C$2:$C$43,Site_Meta!B$2:B$43) -> Cabo Rojo | D32: GALL05 | E32: =LOOKUP($D32,Site_Meta!$C$2:$C$43,Site_Meta!D$2:D$43) -> West | F32: =LOOKUP($D32,Site_Meta!$C$2:$C$43,Site_Meta!E$2:E$43) -> W | G32: =LOOKUP($D32,Site_Meta!$C$2:$C$43,Site_Meta!F$2:F$43) -> 18.0017 | H32: =LOOKUP($D32,Site_Meta!$C$2:$C$43,Site_Meta!G$2:G$43) -> -67.3299 | I32: =LOOKUP($D32,Site_Meta!$C$2:$C$43,Site_Meta!H$2:H$43) -> 5 | J32: 2 | K32: 14 | L32: 24 | M32: =CONCATENATE(J32,"/",K32,"/",L32) -> 2/14/24 | N32: Orlando | O32: Manuel | P32: Ana | R32: 0.32986111 | S32: 0.35138889 | T32: 27.04 | U32: 0.44 | V32: 36.62 | W32: 0.42 | X32: 6.26 | Y32: 0.45 | Z32: 8.18 | AA32: 0.51 | AB32: 27.04 | AC32: 6.02 | AD32: 36.63 | AE32: 6.11 | AF32: 6.13 | AG32: 6.12 | AH32: 8.18 | AI32: 6.21 | AJ32: > 3 | AK32: > 3 | AL32: > 3 | AM32: > 3 | AN32: 0.5 | AO32: 6 | AP32: 339 | AQ32: 340 | AR32: 341 | AS32: 342 | AT32: 343 | AU32: 344 | AV32: 345 | AW32: 346 | AX32: 347 | AY32: 348 | AZ32: 427 | BA32: 350 | BB32: 351
A33: 3 | B33: =LOOKUP($D33,Site_Meta!$C$2:$C$43,Site_Meta!A$2:A$43) -> Gallardo 5m | C33: =LOOKUP($D33,Site_Meta!$C$2:$C$43,Site_Meta!B$2:B$43) -> Cabo Rojo | D33: GALL05-R | E33: =LOOKUP($D33,Site_Meta!$C$2:$C$43,Site_Meta!D$2:D$43) -> West | F33: =LOOKUP($D33,Site_Meta!$C$2:$C$43,Site_Meta!E$2:E$43) -> W | G33: =LOOKUP($D33,Site_Meta!$C$2:$C$43,Site_Meta!F$2:F$43) -> 18.0017 | H33: =LOOKUP($D33,Site_Meta!$C$2:$C$43,Site_Meta!G$2:G$43) -> -67.3299 | I33: =LOOKUP($D33,Site_Meta!$C$2:$C$43,Site_Meta!H$2:H$43) -> 5 | J33: 2 | K33: 14 | L33: 24 | M33: =CONCATENATE(J33,"/",K33,"/",L33) -> 2/14/24 | N33: Orlando | O33: Manuel | P33: Ana | R33: 0.35138889 | S33: 0.36388889 | T33: 27.04 | U33: 0.53 | V33: 36.54 | W33: 0.54 | X33: 6.57 | Y33: 0.73 | Z33: 8.2 | AA33: 0.55 | AB33: 27.05 | AC33: 6 | AD33: 36.56 | AE33: 5.97 | AF33: 6.19 | AG33: 6.18 | AH33: 8.2 | AI33: 6.23 | AJ33: > 6 | AK33: > 6 | AL33: > 6 | AM33: > 6 | AN33: 0.5 | AO33: 6 | AP33: 482 | AQ33: 483 | AR33: 484 | AS33: 485 | AT33: 486 | AU33: 487 | AV33: 488 | AW33: 489 | AX33: 490 | AY33: 491 | AZ33: 440 | BA33: 493 | BB33: 494
A34: 3 | B34: =LOOKUP($D34,Site_Meta!$C$2:$C$43,Site_Meta!A$2:A$43) -> Cayo Rodriguez 5m | C34: =LOOKUP($D34,Site_Meta!$C$2:$C$43,Site_Meta!B$2:B$43) -> Mayaguez | D34: RODR05 | E34: =LOOKUP($D34,Site_Meta!$C$2:$C$43,Site_Meta!D$2:D$43) -> West | F34: =LOOKUP($D34,Site_Meta!$C$2:$C$43,Site_Meta!E$2:E$43) -> W | G34: =LOOKUP($D34,Site_Meta!$C$2:$C$43,Site_Meta!F$2:F$43) -> 18.1893 | H34: =LOOKUP($D34,Site_Meta!$C$2:$C$43,Site_Meta!G$2:G$43) -> -67.1919 | I34: =LOOKUP($D34,Site_Meta!$C$2:$C$43,Site_Meta!H$2:H$43) -> 5 | J34: 2 | K34: 14 | L34: 24 | M34: =CONCATENATE(J34,"/",K34,"/",L34) -> 2/14/24 | N34: Orlando | O34: Manuel | P34: Ana | R34: 0.40625 | S34: 0.42013889 | T34: 26.76 | U34: 0.48 | V34: 36.62 | W34: 0.52 | X34: 6.68 | Y34: 0.49 | Z34: 8.18 | AA34: 0.48 | AB34: 26.72 | AC34: 4.05 | AD34: 36.73 | AE34: 3.99 | AF34: 6.55 | AG34: 4.08 | AH34: 8.18 | AI34: 4.01 | AJ34: > 4 | AK34: > 4 | AL34: > 4 | AM34: > 4 | AN34: 0.5 | AO34: 4 | AP34: 430 | AQ34: 431 | AR34: 432 | AS34: 433 | AT34: 434 | AU34: 435 | AV34: 436 | AW34: 437 | AX34: 438 | AY34: 439 | AZ34: 453 | BA34: 441 | BB34: 442
A35: 3 | B35: =LOOKUP($D35,Site_Meta!$C$2:$C$43,Site_Meta!A$2:A$43) -> Resuellos 10m | C35: =LOOKUP($D35,Site_Meta!$C$2:$C$43,Site_Meta!B$2:B$43) -> Cabo Rojo | D35: RESU10 | E35: =LOOKUP($D35,Site_Meta!$C$2:$C$43,Site_Meta!D$2:D$43) -> West | F35: =LOOKUP($D35,Site_Meta!$C$2:$C$43,Site_Meta!E$2:E$43) -> W | G35: =LOOKUP($D35,Site_Meta!$C$2:$C$43,Site_Meta!F$2:F$43) -> 17.99116 | H35: =LOOKUP($D35,Site_Meta!$C$2:$C$43,Site_Meta!G$2:G$43) -> -67.2332 | I35: =LOOKUP($D35,Site_Meta!$C$2:$C$43,Site_Meta!H$2:H$43) -> 10 | J35: 2 | K35: 14 | L35: 24 | M35: =CONCATENATE(J35,"/",K35,"/",L35) -> 2/14/24 | N35: Orlando | O35: Manuel | P35: Ana | R35: 0.45486111 | S35: 0.47361111 | T35: 27.13 | U35: 0.6 | V35: 36.45 | W35: 0.61 | X35: 6.59 | Y35: 0.55 | Z35: 8.19 | AA35: 0.57 | AB35: 27.09 | AC35: 6.56 | AD35: 36.58 | AE35: 6.48 | AF35: 6.8 | AG35: 6.58 | AH35: 8.2 | AI35: 6.54 | AJ35: > 6.5 | AK35: > 6.5 | AL35: > 6.5 | AM35: > 6.5 | AN35: 0.5 | AO35: 6.5 | AP35: 170 | AQ35: 171 | AR35: 172 | AS35: 173 | AT35: 174 | AU35: 175 | AV35: 176 | AW35: 177 | AX35: 178 | AY35: 179 | AZ35: 466 | BA35: 181 | BB35: 182
A36: 3 | B36: =LOOKUP($D36,Site_Meta!$C$2:$C$43,Site_Meta!A$2:A$43) -> Cibuco 05m | C36: =LOOKUP($D36,Site_Meta!$C$2:$C$43,Site_Meta!B$2:B$43) -> Vega Baja | D36: CIBU05 | E36: =LOOKUP($D36,Site_Meta!$C$2:$C$43,Site_Meta!D$2:D$43) -> North/Northeast | F36: =LOOKUP($D36,Site_Meta!$C$2:$C$43,Site_Meta!E$2:E$43) -> N | G36: =LOOKUP($D36,Site_Meta!$C$2:$C$43,Site_Meta!F$2:F$43) -> 18.48955 | H36: =LOOKUP($D36,Site_Meta!$C$2:$C$43,Site_Meta!G$2:G$43) -> -66.3736 | I36: =LOOKUP($D36,Site_Meta!$C$2:$C$43,Site_Meta!H$2:H$43) -> 10 | J36: 2 | K36: 15 | L36: 24 | M36: =CONCATENATE(J36,"/",K36,"/",L36) -> 2/15/24 | N36: Rodolfo | O36: Manuel | P36: Idalmis | R36: 0.29305556 | S36: 0.32847222 | T36: 27.05 | U36: 0.53 | V36: 36.71 | W36: 0.52 | X36: 6.39 | Y36: 0.49 | Z36: 8.11 | AA36: 0.45 | AB36: 27.01 | AC36: 3 | AD36: 36.69 | AE36: 2.98 | AF36: 5.85 | AG36: 2.95 | AH36: 8.12 | AI36: 3 | AJ36: > 3 | AK36: > 3 | AL36: > 3 | AM36: > 3 | AN36: 0.5 | AO36: 3 | AP36: 508 | AQ36: 509 | AR36: 510 | AS36: 511 | AT36: 512 | AU36: 513 | AV36: 514 | AW36: 515 | AX36: 516 | AY36: 517 | AZ36: 609 | BA36: 519 | BB36: 520
A37: 3 | B37: =LOOKUP($D37,Site_Meta!$C$2:$C$43,Site_Meta!A$2:A$43) -> Dominos 5m | C37: =LOOKUP($D37,Site_Meta!$C$2:$C$43,Site_Meta!B$2:B$43) -> San Juan | D37: DOMI05 | E37: =LOOKUP($D37,Site_Meta!$C$2:$C$43,Site_Meta!D$2:D$43) -> North/Northeast | F37: =LOOKUP($D37,Site_Meta!$C$2:$C$43,Site_Meta!E$2:E$43) -> N | G37: =LOOKUP($D37,Site_Meta!$C$2:$C$43,Site_Meta!F$2:F$43) -> 18.46222 | H37: =LOOKUP($D37,Site_Meta!$C$2:$C$43,Site_Meta!G$2:G$43) -> -66.0517 | I37: =LOOKUP($D37,Site_Meta!$C$2:$C$43,Site_Meta!H$2:H$43) -> 5 | J37: 2 | K37: 15 | L37: 24 | M37: =CONCATENATE(J37,"/",K37,"/",L37) -> 2/15/24 | N37: Rodolfo | O37: Manuel | P37: Idalmis | R37: 0.39722222 | S37: 0.41111111 | T37: 27.21 | U37: 0.41 | V37: 37.2 | W37: 0.52 | X37: 6.54 | Y37: 0.56 | Z37: 8.17 | AA37: 0.47 | AB37: 27.19 | AC37: 2.09 | AD37: 37.18 | AE37: 1.9 | AF37: 6.57 | AG37: 2.01 | AH37: 8.17 | AI37: 2 | AJ37: > 2 | AK37: > 2 | AL37: > 2 | AM37: > 2 | AN37: 0.5 | AO37: 2 | AP37: 495 | AQ37: 496 | AR37: 497 | AS37: 498 | AT37: 499 | AU37: 500 | AV37: 501 | AW37: 502 | AX37: 503 | AY37: 504 | AZ37: 479 | BA37: 506 | BB37: 507
A38: 3 | B38: =LOOKUP($D38,Site_Meta!$C$2:$C$43,Site_Meta!A$2:A$43) -> Dominos 5m | C38: =LOOKUP($D38,Site_Meta!$C$2:$C$43,Site_Meta!B$2:B$43) -> San Juan | D38: DOMI05-R | E38: =LOOKUP($D38,Site_Meta!$C$2:$C$43,Site_Meta!D$2:D$43) -> North/Northeast | F38: =LOOKUP($D38,Site_Meta!$C$2:$C$43,Site_Meta!E$2:E$43) -> N | G38: =LOOKUP($D38,Site_Meta!$C$2:$C$43,Site_Meta!F$2:F$43) -> 18.46222 | H38: =LOOKUP($D38,Site_Meta!$C$2:$C$43,Site_Meta!G$2:G$43) -> -66.0517 | I38: =LOOKUP($D38,Site_Meta!$C$2:$C$43,Site_Meta!H$2:H$43) -> 5 | J38: 2 | K38: 15 | L38: 24 | M38: =CONCATENATE(J38,"/",K38,"/",L38) -> 2/15/24 | N38: Rodolfo | O38: Manuel | P38: Idalmis | R38: 0.41527778 | S38: 0.42777778 | T38: 27.24 | U38: 0.48 | V38: 37.06 | W38: 0.57 | X38: 6.57 | Y38: 0.61 | Z38: 8.18 | AA38: 0.55 | AB38: 27.21 | AC38: 2.09 | AD38: 37.1 | AE38: 2.09 | AF38: 6.63 | AG38: 2.1 | AH38: 8.18 | AI38: 2.2 | AJ38: > 2 | AK38: > 2 | AL38: > 2 | AM38: > 2 | AN38: 0.5 | AO38: 2 | AP38: 443 | AQ38: 444 | AR38: 445 | AS38: 446 | AT38: 447 | AU38: 448 | AV38: 449 | AW38: 450 | AX38: 451 | AY38: 452 | AZ38: 492 | BA38: 454 | BB38: 455
A39: 3 | B39: =LOOKUP($D39,Site_Meta!$C$2:$C$43,Site_Meta!A$2:A$43) -> Manchas Exteriores 20m | C39: =LOOKUP($D39,Site_Meta!$C$2:$C$43,Site_Meta!B$2:B$43) -> Mayaguez | D39: MEXT20 | E39: =LOOKUP($D39,Site_Meta!$C$2:$C$43,Site_Meta!D$2:D$43) -> West | F39: =LOOKUP($D39,Site_Meta!$C$2:$C$43,Site_Meta!E$2:E$43) -> W | G39: =LOOKUP($D39,Site_Meta!$C$2:$C$43,Site_Meta!F$2:F$43) -> 18.2335 | H39: =LOOKUP($D39,Site_Meta!$C$2:$C$43,Site_Meta!G$2:G$43) -> -67.2009 | I39: =LOOKUP($D39,Site_Meta!$C$2:$C$43,Site_Meta!H$2:H$43) -> 20 | J39: 2 | K39: 16 | L39: 24 | M39: =CONCATENATE(J39,"/",K39,"/",L39) -> 2/16/24 | N39: Orlando | O39: Manuel | P39: Johann | R39: 0.33055556 | S39: 0.35902778 | T39: 26.98 | U39: 0.48 | V39: 36.59 | W39: 0.46 | X39: 6.75 | Y39: 0.46 | Z39: 8.18 | AA39: 0.47 | AB39: 26.94 | AC39: 10.44 | AD39: 36.78 | AE39: 16.54 | AF39: 6.3 | AG39: 16.46 | AH39: 8.2 | AI39: 16.4 | AJ39: 13.25 | AK39: 13 | AL39: 13.5 | AM39: =AVERAGE(AJ39:AL39) -> 13.25 | AN39: 0.5 | AO39: 16.5 | AP39: 469 | AQ39: 470 | AR39: 471 | AS39: 472 | AT39: 473 | AU39: 474 | AV39: 475 | AW39: 476 | AX39: 477 | AY39: 478 | AZ39: 505 | BA39: 480 | BB39: 481
A40: 3 | B40: =LOOKUP($D40,Site_Meta!$C$2:$C$43,Site_Meta!A$2:A$43) -> Manchas Exteriores 10m | C40: =LOOKUP($D40,Site_Meta!$C$2:$C$43,Site_Meta!B$2:B$43) -> Mayaguez | D40: MEXT10 | E40: =LOOKUP($D40,Site_Meta!$C$2:$C$43,Site_Meta!D$2:D$43) -> West | F40: =LOOKUP($D40,Site_Meta!$C$2:$C$43,Site_Meta!E$2:E$43) -> W | G40: =LOOKUP($D40,Site_Meta!$C$2:$C$43,Site_Meta!F$2:F$43) -> 18.23353 | H40: =LOOKUP($D40,Site_Meta!$C$2:$C$43,Site_Meta!G$2:G$43) -> -67.2006 | I40: =LOOKUP($D40,Site_Meta!$C$2:$C$43,Site_Meta!H$2:H$43) -> 10 | J40: 2 | K40: 16 | L40: 24 | M40: =CONCATENATE(J40,"/",K40,"/",L40) -> 2/16/24 | N40: Orlando | O40: Manuel | P40: Johann | R40: 0.36458333 | S40: 0.37847222 | T40: 26.98 | U40: 0.54 | V40: 36.67 | W40: 0.56 | X40: 6.59 | Y40: 0.5 | Z40: 8.22 | AA40: 0.55 | AB40: 26.98 | AC40: 7.57 | AD40: 36.7 | AE40: 7.58 | AF40: 6.38 | AG40: 7.57 | AH40: 8.22 | AI40: 7.53 | AJ40: > 7.5 | AK40: > 7.5 | AL40: > 7.5 | AM40: > 7.5 | AN40: 0.5 | AO40: 7.5 | AP40: 547 | AQ40: 548 | AR40: 549 | AS40: 550 | AT40: 551 | AU40: 552 | AV40: 553 | AW40: 554 | AX40: 555 | AY40: 556 | AZ40: 518 | BA40: 558 | BB40: 559
...

Sheet Table 1
B2: Parameter | C2: Method | D2: Depth of Measurement | E2: Holding Time (hr) | F2: Accuracy | G2: Precision
B3: Temperature (°C) | C3: SM 2550 B | D3: S+B | E3: N/A | F3: ± 0.1 | G3: <20%
B4: Salinity (psu) | C4: SM 2520 B | D4: S+B | E4: N/A | F4: ± 0.50 | G4: <20%
B5: DO (mg/L) | C5: SM 4500-O H | D5: S+B | E5: N/A | F5: ± 0.2 | G5: <20%
B6: pH | C6: EPA 150.2 | D6: S+B | E6: N/A | F6: ± 0.002 | G6: <10%
B7: Secchi Depth (m) | C7: Secchi Disk | D7: NA | E7: N/A | F7: ± 20% | G7: <20%
B8: BOD (mg/L) | C8: SM 5210 B | D8: S+B | E8: 48 | F8: ± 0.2 | G8: <20%
B9: TA (µmol/kg) | C9: Dickson et al., 2007 | D9: S+B | E9: 672 | F9: ± 3 | G9: <20%
B10: DIC (µmol/kg) | C10: Dickson et al., 2007 | D10: S+B | E10: 672 | F10: ± 3 | G10: <20%
B11: Chlorophyll-a (µg/L) | C11: SM 10200 H | D11: B | E11: 24 | F11: N/A | G11: <20%
B12: Enterococcus (MPN) | C12: SM 9230 B/C/D | D12: B | E12: < 8 | F12: N/A | G12: <60%
B13: Turbidity (NTU) | C13: EPA 180.1 | D13: B | E13: 48 | F13: ± 20% | G13: <20%
B14: Settleable Solids (mg/L) | C14: SM 2540-F | D14: B | E14: 48 | F14: ±20% | G14: <20%
B15: TSS (mg/L) | C15: SM 2540-D | D15: B | E15: 48 | F15: ± 5 | G15: <20%
B16: TP (mg/L) | C16: EPA 365.4 | D16: B | E16: 672 | F16: ± 0.05 | G16: <20%
B17: TKN (mg/L) | C17: EPA 351.21 | D17: B | E17: 672 | F17: ± 0.5 | G17: <20%
B18: Nitrate + Nitrite (mg/L) | C18: EPA 353.2 | D18: B | E18: 672 | F18: ± 0.05 | G18: <20%

Sheet Table 2_Sampling_Stats
A1: Site_Name | B1: Site_Code | C1: Latitude | D1: Longitude | E1: Date | F1: Data Points | G1: Sampling % | I1: List | J1: Count | K1: > 91-100% | L1: <91%
A47: Replicates

Sheet Table 3_HydroLab QAQC
A1: Parameter | B1: Accuracy | C1: Precision
A2: Surface Temp (°C) | B2: ± 0.1 | C2: <20%
A3: Surface Sal (psu) | B3: ± 0.50 | C3: <20%
A4: Surface DO (mg/L) | B4: ± 0.2 | C4: <20%
A5: Surface pH | B5: ± 0.10 | C5: <10%
A6: Bottom Temp (°C) | B6: ± 0.1 | C6: <20%
A7: Bottom Sal (psu) | B7: ± 0.50 | C7: <20%
A8: Bottom DO (mg/L)) | B8: ± 0.2 | C8: <20%
A9: Bottom pH | B9: ± 0.10 | C9: <10%
A10: Secchi Depth (m) | B10: ± 20% | C10: <20%
A11: Surface BOD (mg/L) | B11: ± 0.2 | C11: <20%
A12: Bottom BOD (mg/L) | B12: ± 0.2 | C12: <20%
... A24: Nitrate + Nitrite (mg/L) | B24: ± 0.05 | C24: <20%

Sheet Table 4
A1: Parameter | B1: Data Points | C1: % | D1: < limit | E1: % < limit | F1: Min | G1: Max | H1: Average | I1: SD
A2: Surface Temp (°C)
A3: Surface Sal (psu)
A4: Surface DO (mg/L)
A5: Surface pH
A6: Bottom Temp (°C)
A7: Bottom Sal (psu)
A8: Bottom DO (mg/L)
A9: Bottom pH
A10: Secchi Depth (m)
A11: Surface BOD (mg/L)
A12: Bottom BOD (mg/L)
A13: Surface TA (umol/kg)
... A24: TP (mg/L)

Sheet Site_Meta
A1: Site_Name | B1: Location | C1: Site_Code | D1: Region | E1: Zone | F1: Latitude | G1: Longitude | H1: Depth
A2: Cayo Aurora 5m | B2: Guanica | C2: AURO05 | D2: Southwest | E2: SW | F2: 17.9369 | G2: -66.8738 | H2: 5 | K2: Sampled
A3: Puerto Botes 15m | B3: Isla Desecheo | C3: BOTE15 | D3: Mona/Desecheo | E3: W | F3: 18.382 | G3: -67.4883 | H3: 15 | K3: Planned
A4: Puerto Botes 20m | B4: Isla Desecheo | C4: BOTE20 | D4: Mona/Desecheo | E4: W | F4: 18.38158 | G4: -67.4886 | H4: 20 | K4: Pending
A5: Boya Vieja 20m | B5: La Parguera | C5: BOYA20 | D5: Southwest | E5: SW | F5: 17.88827 | G5: -66.9978 | H5: 20
A6: Cabezas de San Juan 5m | B6: Fajardo | C6: CABE05 | D6: North/Northeast | E6: E | F6: 18.38544 | G6: -65.6297 | H6: 5
A7: Canjilones 15m | B7: Isla Vieques | C7: CANJ15 | D7: Vieques/Culebra | E7: E | F7: 18.08964 | G7: -65.5901 | H7: 15
A8: Puerto Canoas 30m | B8: Isla Desecheo | C8: CANO30 | D8: Mona/Desecheo | E8: W | F8: 18.37747 | G8: -67.484 | H8: 30
A9: Cayo Caribes 10m | B9: Salinas | C9: CARI10 | D9: Southeast | E9: S | F9: 17.91533 | G9: -66.2141 | H9: 10
A10: West Reef 10m | B10: Ponce | C10: CDMU10 | D10: South | E10: S | F10: 17.89502 | G10: -66.5284 | H10: 10
A11: Cibuco 05m | B11: Vega Baja | C11: CIBU05 | D11: North/Northeast | E11: N | F11: 18.48955 | G11: -66.3736 | H11: 10
A12: Cayo Coral 10m | B12: Guanica | C12: CORA10 | D12: Southwest | E12: SW | F12: 17.9362 | G12: -66.8884 | H12: 10
A13: Carlos Rosario 10m | B13: Isla Culebra | C13: CROS10 | D13: Vieques/Culebra | E13: E | F13: 18.32779 | G13: -65.332 | H13: 10
A14: Dakiti 20m | B14: Isla Culebra | C14: DAKI20 | D14: Vieques/Culebra | E14: E | F14: 18.27587 | G14: -65.2773 | H14: 20
A15: Derrumbadero 20m | B15: Ponce | C15: DERR20 | D15: South | E15: S | F15: 17.904 | G15: -66.6086 | H15: 20
A16: Cayo Diablo 5m | B16: Fajardo | C16: DIAB05 | D16: North/Northeast | E16: E | F16: 18.36033 | G16: -65.5309 | H16: 5
... A43: Tres Palmas 20m | B43: Rincon | C43: TRES20 | D43: West | E43: W | F43: 18.34652 | G43: -67.2712 | H43: 20
